Traceback (most recent call last):
  File "/Users/linyuchen/Documents/code/Python/qq/qqsdk/qqclient.py", line 765, in run
    msg = self.getMsg()
  File "/Users/linyuchen/Documents/code/Python/qq/qqsdk/qqapi.py", line 90, in getMsg
    data = self.post_json(self.get_msgs_url)
  File "/Users/linyuchen/Documents/code/Python/qq/qqsdk/qqapi.py", line 37, in post_json
    res = requests.get(url, kwargs)
  File "/Library/Frameworks/Python.framework/Versions/2.7/lib/python2.7/site-packages/requests/api.py", line 67, in get
    return request('get', url, params=params, **kwargs)
  File "/Library/Frameworks/Python.framework/Versions/2.7/lib/python2.7/site-packages/requests/api.py", line 53, in request
    return session.request(method=method, url=url, **kwargs)
  File "/Library/Frameworks/Python.framework/Versions/2.7/lib/python2.7/site-packages/requests/sessions.py", line 468, in request
    resp = self.send(prep, **send_kwargs)
  File "/Library/Frameworks/Python.framework/Versions/2.7/lib/python2.7/site-packages/requests/sessions.py", line 576, in send
    r = adapter.send(request, **kwargs)
  File "/Library/Frameworks/Python.framework/Versions/2.7/lib/python2.7/site-packages/requests/adapters.py", line 426, in send
    raise ConnectionError(err, request=request)
ConnectionError: ('Connection aborted.', error(54, 'Connection reset by peer'))
Tue Mar 29 10:52:21 2016
Traceback (most recent call last):
  File "/Users/linyuchen/Documents/code/Python/qq/qqsdk/qqclient.py", line 765, in run
    msg = self.getMsg()
  File "/Users/linyuchen/Documents/code/Python/qq/qqsdk/qqapi.py", line 90, in getMsg
    data = self.post_json(self.get_msgs_url)
  File "/Users/linyuchen/Documents/code/Python/qq/qqsdk/qqapi.py", line 37, in post_json
    res = requests.get(url, kwargs)
  File "/Library/Frameworks/Python.framework/Versions/2.7/lib/python2.7/site-packages/requests/api.py", line 67, in get
    return request('get', url, params=params, **kwargs)
  File "/Library/Frameworks/Python.framework/Versions/2.7/lib/python2.7/site-packages/requests/api.py", line 53, in request
    return session.request(method=method, url=url, **kwargs)
  File "/Library/Frameworks/Python.framework/Versions/2.7/lib/python2.7/site-packages/requests/sessions.py", line 468, in request
    resp = self.send(prep, **send_kwargs)
  File "/Library/Frameworks/Python.framework/Versions/2.7/lib/python2.7/site-packages/requests/sessions.py", line 576, in send
    r = adapter.send(request, **kwargs)
  File "/Library/Frameworks/Python.framework/Versions/2.7/lib/python2.7/site-packages/requests/adapters.py", line 437, in send
    raise ConnectionError(e, request=request)
ConnectionError: HTTPConnectionPool(host='localhost', port=3000): Max retries exceeded with url: /msgs (Caused by NewConnectionError('<requests.packages.urllib3.connection.HTTPConnection object at 0x10542b910>: Failed to establish a new connection: [Errno 61] Connection refused',))
Tue Mar 29 10:52:21 2016
Traceback (most recent call last):
  File "/Users/linyuchen/Documents/code/Python/qq/qqsdk/qqclient.py", line 765, in run
    msg = self.getMsg()
  File "/Users/linyuchen/Documents/code/Python/qq/qqsdk/qqapi.py", line 90, in getMsg
    data = self.post_json(self.get_msgs_url)
  File "/Users/linyuchen/Documents/code/Python/qq/qqsdk/qqapi.py", line 37, in post_json
    res = requests.get(url, kwargs)
  File "/Library/Frameworks/Python.framework/Versions/2.7/lib/python2.7/site-packages/requests/api.py", line 67, in get
    return request('get', url, params=params, **kwargs)
  File "/Library/Frameworks/Python.framework/Versions/2.7/lib/python2.7/site-packages/requests/api.py", line 53, in request
    return session.request(method=method, url=url, **kwargs)
  File "/Library/Frameworks/Python.framework/Versions/2.7/lib/python2.7/site-packages/requests/sessions.py", line 468, in request
    resp = self.send(prep, **send_kwargs)
  File "/Library/Frameworks/Python.framework/Versions/2.7/lib/python2.7/site-packages/requests/sessions.py", line 576, in send
    r = adapter.send(request, **kwargs)
  File "/Library/Frameworks/Python.framework/Versions/2.7/lib/python2.7/site-packages/requests/adapters.py", line 437, in send
    raise ConnectionError(e, request=request)
ConnectionError: HTTPConnectionPool(host='localhost', port=3000): Max retries exceeded with url: /msgs (Caused by NewConnectionError('<requests.packages.urllib3.connection.HTTPConnection object at 0x10542ba50>: Failed to establish a new connection: [Errno 61] Connection refused',))
Tue Mar 29 10:52:21 2016
Traceback (most recent call last):
  File "/Users/linyuchen/Documents/code/Python/qq/qqsdk/qqclient.py", line 765, in run
    msg = self.getMsg()
  File "/Users/linyuchen/Documents/code/Python/qq/qqsdk/qqapi.py", line 90, in getMsg
    data = self.post_json(self.get_msgs_url)
  File "/Users/linyuchen/Documents/code/Python/qq/qqsdk/qqapi.py", line 37, in post_json
    res = requests.get(url, kwargs)
  File "/Library/Frameworks/Python.framework/Versions/2.7/lib/python2.7/site-packages/requests/api.py", line 67, in get
    return request('get', url, params=params, **kwargs)
  File "/Library/Frameworks/Python.framework/Versions/2.7/lib/python2.7/site-packages/requests/api.py", line 53, in request
    return session.request(method=method, url=url, **kwargs)
  File "/Library/Frameworks/Python.framework/Versions/2.7/lib/python2.7/site-packages/requests/sessions.py", line 468, in request
    resp = self.send(prep, **send_kwargs)
  File "/Library/Frameworks/Python.framework/Versions/2.7/lib/python2.7/site-packages/requests/sessions.py", line 576, in send
    r = adapter.send(request, **kwargs)
  File "/Library/Frameworks/Python.framework/Versions/2.7/lib/python2.7/site-packages/requests/adapters.py", line 437, in send
    raise ConnectionError(e, request=request)
ConnectionError: HTTPConnectionPool(host='localhost', port=3000): Max retries exceeded with url: /msgs (Caused by NewConnectionError('<requests.packages.urllib3.connection.HTTPConnection object at 0x10542b1d0>: Failed to establish a new connection: [Errno 61] Connection refused',))
Tue Mar 29 10:52:21 2016
Traceback (most recent call last):
  File "/Users/linyuchen/Documents/code/Python/qq/qqsdk/qqclient.py", line 765, in run
    msg = self.getMsg()
  File "/Users/linyuchen/Documents/code/Python/qq/qqsdk/qqapi.py", line 90, in getMsg
    data = self.post_json(self.get_msgs_url)
  File "/Users/linyuchen/Documents/code/Python/qq/qqsdk/qqapi.py", line 37, in post_json
    res = requests.get(url, kwargs)
  File "/Library/Frameworks/Python.framework/Versions/2.7/lib/python2.7/site-packages/requests/api.py", line 67, in get
    return request('get', url, params=params, **kwargs)
  File "/Library/Frameworks/Python.framework/Versions/2.7/lib/python2.7/site-packages/requests/api.py", line 53, in request
    return session.request(method=method, url=url, **kwargs)
  File "/Library/Frameworks/Python.framework/Versions/2.7/lib/python2.7/site-packages/requests/sessions.py", line 468, in request
    resp = self.send(prep, **send_kwargs)
  File "/Library/Frameworks/Python.framework/Versions/2.7/lib/python2.7/site-packages/requests/sessions.py", line 576, in send
    r = adapter.send(request, **kwargs)
  File "/Library/Frameworks/Python.framework/Versions/2.7/lib/python2.7/site-packages/requests/adapters.py", line 437, in send
    raise ConnectionError(e, request=request)
ConnectionError: HTTPConnectionPool(host='localhost', port=3000): Max retries exceeded with url: /msgs (Caused by NewConnectionError('<requests.packages.urllib3.connection.HTTPConnection object at 0x10542b850>: Failed to establish a new connection: [Errno 61] Connection refused',))
Tue Mar 29 10:52:22 2016
Traceback (most recent call last):
  File "/Users/linyuchen/Documents/code/Python/qq/qqsdk/qqclient.py", line 765, in run
    msg = self.getMsg()
  File "/Users/linyuchen/Documents/code/Python/qq/qqsdk/qqapi.py", line 90, in getMsg
    data = self.post_json(self.get_msgs_url)
  File "/Users/linyuchen/Documents/code/Python/qq/qqsdk/qqapi.py", line 37, in post_json
    res = requests.get(url, kwargs)
  File "/Library/Frameworks/Python.framework/Versions/2.7/lib/python2.7/site-packages/requests/api.py", line 67, in get
    return request('get', url, params=params, **kwargs)
  File "/Library/Frameworks/Python.framework/Versions/2.7/lib/python2.7/site-packages/requests/api.py", line 53, in request
    return session.request(method=method, url=url, **kwargs)
  File "/Library/Frameworks/Python.framework/Versions/2.7/lib/python2.7/site-packages/requests/sessions.py", line 468, in request
    resp = self.send(prep, **send_kwargs)
  File "/Library/Frameworks/Python.framework/Versions/2.7/lib/python2.7/site-packages/requests/sessions.py", line 576, in send
    r = adapter.send(request, **kwargs)
  File "/Library/Frameworks/Python.framework/Versions/2.7/lib/python2.7/site-packages/requests/adapters.py", line 437, in send
    raise ConnectionError(e, request=request)
ConnectionError: HTTPConnectionPool(host='localhost', port=3000): Max retries exceeded with url: /msgs (Caused by NewConnectionError('<requests.packages.urllib3.connection.HTTPConnection object at 0x10542bb90>: Failed to establish a new connection: [Errno 61] Connection refused',))
Tue Mar 29 10:52:22 2016
Traceback (most recent call last):
  File "/Users/linyuchen/Documents/code/Python/qq/qqsdk/qqclient.py", line 765, in run
    msg = self.getMsg()
  File "/Users/linyuchen/Documents/code/Python/qq/qqsdk/qqapi.py", line 90, in getMsg
    data = self.post_json(self.get_msgs_url)
  File "/Users/linyuchen/Documents/code/Python/qq/qqsdk/qqapi.py", line 37, in post_json
    res = requests.get(url, kwargs)
  File "/Library/Frameworks/Python.framework/Versions/2.7/lib/python2.7/site-packages/requests/api.py", line 67, in get
    return request('get', url, params=params, **kwargs)
  File "/Library/Frameworks/Python.framework/Versions/2.7/lib/python2.7/site-packages/requests/api.py", line 53, in request
    return session.request(method=method, url=url, **kwargs)
  File "/Library/Frameworks/Python.framework/Versions/2.7/lib/python2.7/site-packages/requests/sessions.py", line 468, in request
    resp = self.send(prep, **send_kwargs)
  File "/Library/Frameworks/Python.framework/Versions/2.7/lib/python2.7/site-packages/requests/sessions.py", line 576, in send
    r = adapter.send(request, **kwargs)
  File "/Library/Frameworks/Python.framework/Versions/2.7/lib/python2.7/site-packages/requests/adapters.py", line 437, in send
    raise ConnectionError(e, request=request)
ConnectionError: HTTPConnectionPool(host='localhost', port=3000): Max retries exceeded with url: /msgs (Caused by NewConnectionError('<requests.packages.urllib3.connection.HTTPConnection object at 0x10542b650>: Failed to establish a new connection: [Errno 61] Connection refused',))
Tue Mar 29 10:52:22 2016
Traceback (most recent call last):
  File "/Users/linyuchen/Documents/code/Python/qq/qqsdk/qqclient.py", line 765, in run
    msg = self.getMsg()
  File "/Users/linyuchen/Documents/code/Python/qq/qqsdk/qqapi.py", line 90, in getMsg
    data = self.post_json(self.get_msgs_url)
  File "/Users/linyuchen/Documents/code/Python/qq/qqsdk/qqapi.py", line 37, in post_json
    res = requests.get(url, kwargs)
  File "/Library/Frameworks/Python.framework/Versions/2.7/lib/python2.7/site-packages/requests/api.py", line 67, in get
    return request('get', url, params=params, **kwargs)
  File "/Library/Frameworks/Python.framework/Versions/2.7/lib/python2.7/site-packages/requests/api.py", line 53, in request
    return session.request(method=method, url=url, **kwargs)
  File "/Library/Frameworks/Python.framework/Versions/2.7/lib/python2.7/site-packages/requests/sessions.py", line 468, in request
    resp = self.send(prep, **send_kwargs)
  File "/Library/Frameworks/Python.framework/Versions/2.7/lib/python2.7/site-packages/requests/sessions.py", line 576, in send
    r = adapter.send(request, **kwargs)
  File "/Library/Frameworks/Python.framework/Versions/2.7/lib/python2.7/site-packages/requests/adapters.py", line 437, in send
    raise ConnectionError(e, request=request)
ConnectionError: HTTPConnectionPool(host='localhost', port=3000): Max retries exceeded with url: /msgs (Caused by NewConnectionError('<requests.packages.urllib3.connection.HTTPConnection object at 0x10542b890>: Failed to establish a new connection: [Errno 61] Connection refused',))
Tue Mar 29 10:52:22 2016
Traceback (most recent call last):
  File "/Users/linyuchen/Documents/code/Python/qq/qqsdk/qqclient.py", line 765, in run
    msg = self.getMsg()
  File "/Users/linyuchen/Documents/code/Python/qq/qqsdk/qqapi.py", line 90, in getMsg
    data = self.post_json(self.get_msgs_url)
  File "/Users/linyuchen/Documents/code/Python/qq/qqsdk/qqapi.py", line 37, in post_json
    res = requests.get(url, kwargs)
  File "/Library/Frameworks/Python.framework/Versions/2.7/lib/python2.7/site-packages/requests/api.py", line 67, in get
    return request('get', url, params=params, **kwargs)
  File "/Library/Frameworks/Python.framework/Versions/2.7/lib/python2.7/site-packages/requests/api.py", line 53, in request
    return session.request(method=method, url=url, **kwargs)
  File "/Library/Frameworks/Python.framework/Versions/2.7/lib/python2.7/site-packages/requests/sessions.py", line 468, in request
    resp = self.send(prep, **send_kwargs)
  File "/Library/Frameworks/Python.framework/Versions/2.7/lib/python2.7/site-packages/requests/sessions.py", line 576, in send
    r = adapter.send(request, **kwargs)
  File "/Library/Frameworks/Python.framework/Versions/2.7/lib/python2.7/site-packages/requests/adapters.py", line 437, in send
    raise ConnectionError(e, request=request)
ConnectionError: HTTPConnectionPool(host='localhost', port=3000): Max retries exceeded with url: /msgs (Caused by NewConnectionError('<requests.packages.urllib3.connection.HTTPConnection object at 0x10542b250>: Failed to establish a new connection: [Errno 61] Connection refused',))
Tue Mar 29 10:52:22 2016
Traceback (most recent call last):
  File "/Users/linyuchen/Documents/code/Python/qq/qqsdk/qqclient.py", line 765, in run
    msg = self.getMsg()
  File "/Users/linyuchen/Documents/code/Python/qq/qqsdk/qqapi.py", line 90, in getMsg
    data = self.post_json(self.get_msgs_url)
  File "/Users/linyuchen/Documents/code/Python/qq/qqsdk/qqapi.py", line 37, in post_json
    res = requests.get(url, kwargs)
  File "/Library/Frameworks/Python.framework/Versions/2.7/lib/python2.7/site-packages/requests/api.py", line 67, in get
    return request('get', url, params=params, **kwargs)
  File "/Library/Frameworks/Python.framework/Versions/2.7/lib/python2.7/site-packages/requests/api.py", line 53, in request
    return session.request(method=method, url=url, **kwargs)
  File "/Library/Frameworks/Python.framework/Versions/2.7/lib/python2.7/site-packages/requests/sessions.py", line 468, in request
    resp = self.send(prep, **send_kwargs)
  File "/Library/Frameworks/Python.framework/Versions/2.7/lib/python2.7/site-packages/requests/sessions.py", line 576, in send
    r = adapter.send(request, **kwargs)
  File "/Library/Frameworks/Python.framework/Versions/2.7/lib/python2.7/site-packages/requests/adapters.py", line 437, in send
    raise ConnectionError(e, request=request)
ConnectionError: HTTPConnectionPool(host='localhost', port=3000): Max retries exceeded with url: /msgs (Caused by NewConnectionError('<requests.packages.urllib3.connection.HTTPConnection object at 0x10542b050>: Failed to establish a new connection: [Errno 61] Connection refused',))
Tue Mar 29 10:52:22 2016
Traceback (most recent call last):
  File "/Users/linyuchen/Documents/code/Python/qq/qqsdk/qqclient.py", line 765, in run
    msg = self.getMsg()
  File "/Users/linyuchen/Documents/code/Python/qq/qqsdk/qqapi.py", line 90, in getMsg
    data = self.post_json(self.get_msgs_url)
  File "/Users/linyuchen/Documents/code/Python/qq/qqsdk/qqapi.py", line 37, in post_json
    res = requests.get(url, kwargs)
  File "/Library/Frameworks/Python.framework/Versions/2.7/lib/python2.7/site-packages/requests/api.py", line 67, in get
    return request('get', url, params=params, **kwargs)
  File "/Library/Frameworks/Python.framework/Versions/2.7/lib/python2.7/site-packages/requests/api.py", line 53, in request
    return session.request(method=method, url=url, **kwargs)
  File "/Library/Frameworks/Python.framework/Versions/2.7/lib/python2.7/site-packages/requests/sessions.py", line 468, in request
    resp = self.send(prep, **send_kwargs)
  File "/Library/Frameworks/Python.framework/Versions/2.7/lib/python2.7/site-packages/requests/sessions.py", line 576, in send
    r = adapter.send(request, **kwargs)
  File "/Library/Frameworks/Python.framework/Versions/2.7/lib/python2.7/site-packages/requests/adapters.py", line 437, in send
    raise ConnectionError(e, request=request)
ConnectionError: HTTPConnectionPool(host='localhost', port=3000): Max retries exceeded with url: /msgs (Caused by NewConnectionError('<requests.packages.urllib3.connection.HTTPConnection object at 0x10542b810>: Failed to establish a new connection: [Errno 61] Connection refused',))
Tue Mar 29 10:52:22 2016
Traceback (most recent call last):
  File "/Users/linyuchen/Documents/code/Python/qq/qqsdk/qqclient.py", line 765, in run
    msg = self.getMsg()
  File "/Users/linyuchen/Documents/code/Python/qq/qqsdk/qqapi.py", line 90, in getMsg
    data = self.post_json(self.get_msgs_url)
  File "/Users/linyuchen/Documents/code/Python/qq/qqsdk/qqapi.py", line 37, in post_json
    res = requests.get(url, kwargs)
  File "/Library/Frameworks/Python.framework/Versions/2.7/lib/python2.7/site-packages/requests/api.py", line 67, in get
    return request('get', url, params=params, **kwargs)
  File "/Library/Frameworks/Python.framework/Versions/2.7/lib/python2.7/site-packages/requests/api.py", line 53, in request
    return session.request(method=method, url=url, **kwargs)
  File "/Library/Frameworks/Python.framework/Versions/2.7/lib/python2.7/site-packages/requests/sessions.py", line 468, in request
    resp = self.send(prep, **send_kwargs)
  File "/Library/Frameworks/Python.framework/Versions/2.7/lib/python2.7/site-packages/requests/sessions.py", line 576, in send
    r = adapter.send(request, **kwargs)
  File "/Library/Frameworks/Python.framework/Versions/2.7/lib/python2.7/site-packages/requests/adapters.py", line 437, in send
    raise ConnectionError(e, request=request)
ConnectionError: HTTPConnectionPool(host='localhost', port=3000): Max retries exceeded with url: /msgs (Caused by NewConnectionError('<requests.packages.urllib3.connection.HTTPConnection object at 0x10542b350>: Failed to establish a new connection: [Errno 61] Connection refused',))
Tue Mar 29 10:52:22 2016
Traceback (most recent call last):
  File "/Users/linyuchen/Documents/code/Python/qq/qqsdk/qqclient.py", line 765, in run
    msg = self.getMsg()
  File "/Users/linyuchen/Documents/code/Python/qq/qqsdk/qqapi.py", line 90, in getMsg
    data = self.post_json(self.get_msgs_url)
  File "/Users/linyuchen/Documents/code/Python/qq/qqsdk/qqapi.py", line 37, in post_json
    res = requests.get(url, kwargs)
  File "/Library/Frameworks/Python.framework/Versions/2.7/lib/python2.7/site-packages/requests/api.py", line 67, in get
    return request('get', url, params=params, **kwargs)
  File "/Library/Frameworks/Python.framework/Versions/2.7/lib/python2.7/site-packages/requests/api.py", line 53, in request
    return session.request(method=method, url=url, **kwargs)
  File "/Library/Frameworks/Python.framework/Versions/2.7/lib/python2.7/site-packages/requests/sessions.py", line 468, in request
    resp = self.send(prep, **send_kwargs)
  File "/Library/Frameworks/Python.framework/Versions/2.7/lib/python2.7/site-packages/requests/sessions.py", line 576, in send
    r = adapter.send(request, **kwargs)
  File "/Library/Frameworks/Python.framework/Versions/2.7/lib/python2.7/site-packages/requests/adapters.py", line 437, in send
    raise ConnectionError(e, request=request)
ConnectionError: HTTPConnectionPool(host='localhost', port=3000): Max retries exceeded with url: /msgs (Caused by NewConnectionError('<requests.packages.urllib3.connection.HTTPConnection object at 0x10542b210>: Failed to establish a new connection: [Errno 61] Connection refused',))
Tue Mar 29 10:52:22 2016
Traceback (most recent call last):
  File "/Users/linyuchen/Documents/code/Python/qq/qqsdk/qqclient.py", line 765, in run
    msg = self.getMsg()
  File "/Users/linyuchen/Documents/code/Python/qq/qqsdk/qqapi.py", line 90, in getMsg
    data = self.post_json(self.get_msgs_url)
  File "/Users/linyuchen/Documents/code/Python/qq/qqsdk/qqapi.py", line 37, in post_json
    res = requests.get(url, kwargs)
  File "/Library/Frameworks/Python.framework/Versions/2.7/lib/python2.7/site-packages/requests/api.py", line 67, in get
    return request('get', url, params=params, **kwargs)
  File "/Library/Frameworks/Python.framework/Versions/2.7/lib/python2.7/site-packages/requests/api.py", line 53, in request
    return session.request(method=method, url=url, **kwargs)
  File "/Library/Frameworks/Python.framework/Versions/2.7/lib/python2.7/site-packages/requests/sessions.py", line 468, in request
    resp = self.send(prep, **send_kwargs)
  File "/Library/Frameworks/Python.framework/Versions/2.7/lib/python2.7/site-packages/requests/sessions.py", line 576, in send
    r = adapter.send(request, **kwargs)
  File "/Library/Frameworks/Python.framework/Versions/2.7/lib/python2.7/site-packages/requests/adapters.py", line 437, in send
    raise ConnectionError(e, request=request)
ConnectionError: HTTPConnectionPool(host='localhost', port=3000): Max retries exceeded with url: /msgs (Caused by NewConnectionError('<requests.packages.urllib3.connection.HTTPConnection object at 0x10542b3d0>: Failed to establish a new connection: [Errno 61] Connection refused',))
Tue Mar 29 10:52:22 2016
Traceback (most recent call last):
  File "/Users/linyuchen/Documents/code/Python/qq/qqsdk/qqclient.py", line 765, in run
    msg = self.getMsg()
  File "/Users/linyuchen/Documents/code/Python/qq/qqsdk/qqapi.py", line 90, in getMsg
    data = self.post_json(self.get_msgs_url)
  File "/Users/linyuchen/Documents/code/Python/qq/qqsdk/qqapi.py", line 37, in post_json
    res = requests.get(url, kwargs)
  File "/Library/Frameworks/Python.framework/Versions/2.7/lib/python2.7/site-packages/requests/api.py", line 67, in get
    return request('get', url, params=params, **kwargs)
  File "/Library/Frameworks/Python.framework/Versions/2.7/lib/python2.7/site-packages/requests/api.py", line 53, in request
    return session.request(method=method, url=url, **kwargs)
  File "/Library/Frameworks/Python.framework/Versions/2.7/lib/python2.7/site-packages/requests/sessions.py", line 468, in request
    resp = self.send(prep, **send_kwargs)
  File "/Library/Frameworks/Python.framework/Versions/2.7/lib/python2.7/site-packages/requests/sessions.py", line 576, in send
    r = adapter.send(request, **kwargs)
  File "/Library/Frameworks/Python.framework/Versions/2.7/lib/python2.7/site-packages/requests/adapters.py", line 437, in send
    raise ConnectionError(e, request=request)
ConnectionError: HTTPConnectionPool(host='localhost', port=3000): Max retries exceeded with url: /msgs (Caused by NewConnectionError('<requests.packages.urllib3.connection.HTTPConnection object at 0x10542b5d0>: Failed to establish a new connection: [Errno 61] Connection refused',))
Tue Mar 29 10:52:23 2016
Traceback (most recent call last):
  File "/Users/linyuchen/Documents/code/Python/qq/qqsdk/qqclient.py", line 765, in run
    msg = self.getMsg()
  File "/Users/linyuchen/Documents/code/Python/qq/qqsdk/qqapi.py", line 90, in getMsg
    data = self.post_json(self.get_msgs_url)
  File "/Users/linyuchen/Documents/code/Python/qq/qqsdk/qqapi.py", line 37, in post_json
    res = requests.get(url, kwargs)
  File "/Library/Frameworks/Python.framework/Versions/2.7/lib/python2.7/site-packages/requests/api.py", line 67, in get
    return request('get', url, params=params, **kwargs)
  File "/Library/Frameworks/Python.framework/Versions/2.7/lib/python2.7/site-packages/requests/api.py", line 53, in request
    return session.request(method=method, url=url, **kwargs)
  File "/Library/Frameworks/Python.framework/Versions/2.7/lib/python2.7/site-packages/requests/sessions.py", line 468, in request
    resp = self.send(prep, **send_kwargs)
  File "/Library/Frameworks/Python.framework/Versions/2.7/lib/python2.7/site-packages/requests/sessions.py", line 576, in send
    r = adapter.send(request, **kwargs)
  File "/Library/Frameworks/Python.framework/Versions/2.7/lib/python2.7/site-packages/requests/adapters.py", line 437, in send
    raise ConnectionError(e, request=request)
ConnectionError: HTTPConnectionPool(host='localhost', port=3000): Max retries exceeded with url: /msgs (Caused by NewConnectionError('<requests.packages.urllib3.connection.HTTPConnection object at 0x10542b7d0>: Failed to establish a new connection: [Errno 61] Connection refused',))
Tue Mar 29 10:52:23 2016
Traceback (most recent call last):
  File "/Users/linyuchen/Documents/code/Python/qq/qqsdk/qqclient.py", line 765, in run
    msg = self.getMsg()
  File "/Users/linyuchen/Documents/code/Python/qq/qqsdk/qqapi.py", line 90, in getMsg
    data = self.post_json(self.get_msgs_url)
  File "/Users/linyuchen/Documents/code/Python/qq/qqsdk/qqapi.py", line 37, in post_json
    res = requests.get(url, kwargs)
  File "/Library/Frameworks/Python.framework/Versions/2.7/lib/python2.7/site-packages/requests/api.py", line 67, in get
    return request('get', url, params=params, **kwargs)
  File "/Library/Frameworks/Python.framework/Versions/2.7/lib/python2.7/site-packages/requests/api.py", line 53, in request
    return session.request(method=method, url=url, **kwargs)
  File "/Library/Frameworks/Python.framework/Versions/2.7/lib/python2.7/site-packages/requests/sessions.py", line 468, in request
    resp = self.send(prep, **send_kwargs)
  File "/Library/Frameworks/Python.framework/Versions/2.7/lib/python2.7/site-packages/requests/sessions.py", line 576, in send
    r = adapter.send(request, **kwargs)
  File "/Library/Frameworks/Python.framework/Versions/2.7/lib/python2.7/site-packages/requests/adapters.py", line 437, in send
    raise ConnectionError(e, request=request)
ConnectionError: HTTPConnectionPool(host='localhost', port=3000): Max retries exceeded with url: /msgs (Caused by NewConnectionError('<requests.packages.urllib3.connection.HTTPConnection object at 0x10542b9d0>: Failed to establish a new connection: [Errno 61] Connection refused',))
Tue Mar 29 10:52:23 2016
Traceback (most recent call last):
  File "/Users/linyuchen/Documents/code/Python/qq/qqsdk/qqclient.py", line 765, in run
    msg = self.getMsg()
  File "/Users/linyuchen/Documents/code/Python/qq/qqsdk/qqapi.py", line 90, in getMsg
    data = self.post_json(self.get_msgs_url)
  File "/Users/linyuchen/Documents/code/Python/qq/qqsdk/qqapi.py", line 37, in post_json
    res = requests.get(url, kwargs)
  File "/Library/Frameworks/Python.framework/Versions/2.7/lib/python2.7/site-packages/requests/api.py", line 67, in get
    return request('get', url, params=params, **kwargs)
  File "/Library/Frameworks/Python.framework/Versions/2.7/lib/python2.7/site-packages/requests/api.py", line 53, in request
    return session.request(method=method, url=url, **kwargs)
  File "/Library/Frameworks/Python.framework/Versions/2.7/lib/python2.7/site-packages/requests/sessions.py", line 468, in request
    resp = self.send(prep, **send_kwargs)
  File "/Library/Frameworks/Python.framework/Versions/2.7/lib/python2.7/site-packages/requests/sessions.py", line 576, in send
    r = adapter.send(request, **kwargs)
  File "/Library/Frameworks/Python.framework/Versions/2.7/lib/python2.7/site-packages/requests/adapters.py", line 437, in send
    raise ConnectionError(e, request=request)
ConnectionError: HTTPConnectionPool(host='localhost', port=3000): Max retries exceeded with url: /msgs (Caused by NewConnectionError('<requests.packages.urllib3.connection.HTTPConnection object at 0x10542bbd0>: Failed to establish a new connection: [Errno 61] Connection refused',))
Tue Mar 29 10:52:23 2016
Traceback (most recent call last):
  File "/Users/linyuchen/Documents/code/Python/qq/qqsdk/qqclient.py", line 765, in run
    msg = self.getMsg()
  File "/Users/linyuchen/Documents/code/Python/qq/qqsdk/qqapi.py", line 90, in getMsg
    data = self.post_json(self.get_msgs_url)
  File "/Users/linyuchen/Documents/code/Python/qq/qqsdk/qqapi.py", line 37, in post_json
    res = requests.get(url, kwargs)
  File "/Library/Frameworks/Python.framework/Versions/2.7/lib/python2.7/site-packages/requests/api.py", line 67, in get
    return request('get', url, params=params, **kwargs)
  File "/Library/Frameworks/Python.framework/Versions/2.7/lib/python2.7/site-packages/requests/api.py", line 53, in request
    return session.request(method=method, url=url, **kwargs)
  File "/Library/Frameworks/Python.framework/Versions/2.7/lib/python2.7/site-packages/requests/sessions.py", line 468, in request
    resp = self.send(prep, **send_kwargs)
  File "/Library/Frameworks/Python.framework/Versions/2.7/lib/python2.7/site-packages/requests/sessions.py", line 576, in send
    r = adapter.send(request, **kwargs)
  File "/Library/Frameworks/Python.framework/Versions/2.7/lib/python2.7/site-packages/requests/adapters.py", line 437, in send
    raise ConnectionError(e, request=request)
ConnectionError: HTTPConnectionPool(host='localhost', port=3000): Max retries exceeded with url: /msgs (Caused by NewConnectionError('<requests.packages.urllib3.connection.HTTPConnection object at 0x10542ba10>: Failed to establish a new connection: [Errno 61] Connection refused',))
Tue Mar 29 10:52:23 2016
Traceback (most recent call last):
  File "/Users/linyuchen/Documents/code/Python/qq/qqsdk/qqclient.py", line 765, in run
    msg = self.getMsg()
  File "/Users/linyuchen/Documents/code/Python/qq/qqsdk/qqapi.py", line 90, in getMsg
    data = self.post_json(self.get_msgs_url)
  File "/Users/linyuchen/Documents/code/Python/qq/qqsdk/qqapi.py", line 37, in post_json
    res = requests.get(url, kwargs)
  File "/Library/Frameworks/Python.framework/Versions/2.7/lib/python2.7/site-packages/requests/api.py", line 67, in get
    return request('get', url, params=params, **kwargs)
  File "/Library/Frameworks/Python.framework/Versions/2.7/lib/python2.7/site-packages/requests/api.py", line 53, in request
    return session.request(method=method, url=url, **kwargs)
  File "/Library/Frameworks/Python.framework/Versions/2.7/lib/python2.7/site-packages/requests/sessions.py", line 468, in request
    resp = self.send(prep, **send_kwargs)
  File "/Library/Frameworks/Python.framework/Versions/2.7/lib/python2.7/site-packages/requests/sessions.py", line 576, in send
    r = adapter.send(request, **kwargs)
  File "/Library/Frameworks/Python.framework/Versions/2.7/lib/python2.7/site-packages/requests/adapters.py", line 437, in send
    raise ConnectionError(e, request=request)
ConnectionError: HTTPConnectionPool(host='localhost', port=3000): Max retries exceeded with url: /msgs (Caused by NewConnectionError('<requests.packages.urllib3.connection.HTTPConnection object at 0x10542b710>: Failed to establish a new connection: [Errno 61] Connection refused',))
Tue Mar 29 10:52:23 2016
Traceback (most recent call last):
  File "/Users/linyuchen/Documents/code/Python/qq/qqsdk/qqclient.py", line 765, in run
    msg = self.getMsg()
  File "/Users/linyuchen/Documents/code/Python/qq/qqsdk/qqapi.py", line 90, in getMsg
    data = self.post_json(self.get_msgs_url)
  File "/Users/linyuchen/Documents/code/Python/qq/qqsdk/qqapi.py", line 37, in post_json
    res = requests.get(url, kwargs)
  File "/Library/Frameworks/Python.framework/Versions/2.7/lib/python2.7/site-packages/requests/api.py", line 67, in get
    return request('get', url, params=params, **kwargs)
  File "/Library/Frameworks/Python.framework/Versions/2.7/lib/python2.7/site-packages/requests/api.py", line 53, in request
    return session.request(method=method, url=url, **kwargs)
  File "/Library/Frameworks/Python.framework/Versions/2.7/lib/python2.7/site-packages/requests/sessions.py", line 468, in request
    resp = self.send(prep, **send_kwargs)
  File "/Library/Frameworks/Python.framework/Versions/2.7/lib/python2.7/site-packages/requests/sessions.py", line 576, in send
    r = adapter.send(request, **kwargs)
  File "/Library/Frameworks/Python.framework/Versions/2.7/lib/python2.7/site-packages/requests/adapters.py", line 437, in send
    raise ConnectionError(e, request=request)
ConnectionError: HTTPConnectionPool(host='localhost', port=3000): Max retries exceeded with url: /msgs (Caused by NewConnectionError('<requests.packages.urllib3.connection.HTTPConnection object at 0x10542bd50>: Failed to establish a new connection: [Errno 61] Connection refused',))
Tue Mar 29 10:52:23 2016
Traceback (most recent call last):
  File "/Users/linyuchen/Documents/code/Python/qq/qqsdk/qqclient.py", line 765, in run
    msg = self.getMsg()
  File "/Users/linyuchen/Documents/code/Python/qq/qqsdk/qqapi.py", line 90, in getMsg
    data = self.post_json(self.get_msgs_url)
  File "/Users/linyuchen/Documents/code/Python/qq/qqsdk/qqapi.py", line 37, in post_json
    res = requests.get(url, kwargs)
  File "/Library/Frameworks/Python.framework/Versions/2.7/lib/python2.7/site-packages/requests/api.py", line 67, in get
    return request('get', url, params=params, **kwargs)
  File "/Library/Frameworks/Python.framework/Versions/2.7/lib/python2.7/site-packages/requests/api.py", line 53, in request
    return session.request(method=method, url=url, **kwargs)
  File "/Library/Frameworks/Python.framework/Versions/2.7/lib/python2.7/site-packages/requests/sessions.py", line 468, in request
    resp = self.send(prep, **send_kwargs)
  File "/Library/Frameworks/Python.framework/Versions/2.7/lib/python2.7/site-packages/requests/sessions.py", line 576, in send
    r = adapter.send(request, **kwargs)
  File "/Library/Frameworks/Python.framework/Versions/2.7/lib/python2.7/site-packages/requests/adapters.py", line 437, in send
    raise ConnectionError(e, request=request)
ConnectionError: HTTPConnectionPool(host='localhost', port=3000): Max retries exceeded with url: /msgs (Caused by NewConnectionError('<requests.packages.urllib3.connection.HTTPConnection object at 0x10542b0d0>: Failed to establish a new connection: [Errno 61] Connection refused',))
Tue Mar 29 10:52:23 2016
Traceback (most recent call last):
  File "/Users/linyuchen/Documents/code/Python/qq/qqsdk/qqclient.py", line 765, in run
    msg = self.getMsg()
  File "/Users/linyuchen/Documents/code/Python/qq/qqsdk/qqapi.py", line 90, in getMsg
    data = self.post_json(self.get_msgs_url)
  File "/Users/linyuchen/Documents/code/Python/qq/qqsdk/qqapi.py", line 37, in post_json
    res = requests.get(url, kwargs)
  File "/Library/Frameworks/Python.framework/Versions/2.7/lib/python2.7/site-packages/requests/api.py", line 67, in get
    return request('get', url, params=params, **kwargs)
  File "/Library/Frameworks/Python.framework/Versions/2.7/lib/python2.7/site-packages/requests/api.py", line 53, in request
    return session.request(method=method, url=url, **kwargs)
  File "/Library/Frameworks/Python.framework/Versions/2.7/lib/python2.7/site-packages/requests/sessions.py", line 468, in request
    resp = self.send(prep, **send_kwargs)
  File "/Library/Frameworks/Python.framework/Versions/2.7/lib/python2.7/site-packages/requests/sessions.py", line 576, in send
    r = adapter.send(request, **kwargs)
  File "/Library/Frameworks/Python.framework/Versions/2.7/lib/python2.7/site-packages/requests/adapters.py", line 437, in send
    raise ConnectionError(e, request=request)
ConnectionError: HTTPConnectionPool(host='localhost', port=3000): Max retries exceeded with url: /msgs (Caused by NewConnectionError('<requests.packages.urllib3.connection.HTTPConnection object at 0x10542b990>: Failed to establish a new connection: [Errno 61] Connection refused',))
Tue Mar 29 10:52:23 2016
Traceback (most recent call last):
  File "/Users/linyuchen/Documents/code/Python/qq/qqsdk/qqclient.py", line 765, in run
    msg = self.getMsg()
  File "/Users/linyuchen/Documents/code/Python/qq/qqsdk/qqapi.py", line 90, in getMsg
    data = self.post_json(self.get_msgs_url)
  File "/Users/linyuchen/Documents/code/Python/qq/qqsdk/qqapi.py", line 37, in post_json
    res = requests.get(url, kwargs)
  File "/Library/Frameworks/Python.framework/Versions/2.7/lib/python2.7/site-packages/requests/api.py", line 67, in get
    return request('get', url, params=params, **kwargs)
  File "/Library/Frameworks/Python.framework/Versions/2.7/lib/python2.7/site-packages/requests/api.py", line 53, in request
    return session.request(method=method, url=url, **kwargs)
  File "/Library/Frameworks/Python.framework/Versions/2.7/lib/python2.7/site-packages/requests/sessions.py", line 468, in request
    resp = self.send(prep, **send_kwargs)
  File "/Library/Frameworks/Python.framework/Versions/2.7/lib/python2.7/site-packages/requests/sessions.py", line 576, in send
    r = adapter.send(request, **kwargs)
  File "/Library/Frameworks/Python.framework/Versions/2.7/lib/python2.7/site-packages/requests/adapters.py", line 437, in send
    raise ConnectionError(e, request=request)
ConnectionError: HTTPConnectionPool(host='localhost', port=3000): Max retries exceeded with url: /msgs (Caused by NewConnectionError('<requests.packages.urllib3.connection.HTTPConnection object at 0x10542bdd0>: Failed to establish a new connection: [Errno 61] Connection refused',))
Tue Mar 29 10:52:23 2016
Traceback (most recent call last):
  File "/Users/linyuchen/Documents/code/Python/qq/qqsdk/qqclient.py", line 765, in run
    msg = self.getMsg()
  File "/Users/linyuchen/Documents/code/Python/qq/qqsdk/qqapi.py", line 90, in getMsg
    data = self.post_json(self.get_msgs_url)
  File "/Users/linyuchen/Documents/code/Python/qq/qqsdk/qqapi.py", line 37, in post_json
    res = requests.get(url, kwargs)
  File "/Library/Frameworks/Python.framework/Versions/2.7/lib/python2.7/site-packages/requests/api.py", line 67, in get
    return request('get', url, params=params, **kwargs)
  File "/Library/Frameworks/Python.framework/Versions/2.7/lib/python2.7/site-packages/requests/api.py", line 53, in request
    return session.request(method=method, url=url, **kwargs)
  File "/Library/Frameworks/Python.framework/Versions/2.7/lib/python2.7/site-packages/requests/sessions.py", line 468, in request
    resp = self.send(prep, **send_kwargs)
  File "/Library/Frameworks/Python.framework/Versions/2.7/lib/python2.7/site-packages/requests/sessions.py", line 576, in send
    r = adapter.send(request, **kwargs)
  File "/Library/Frameworks/Python.framework/Versions/2.7/lib/python2.7/site-packages/requests/adapters.py", line 437, in send
    raise ConnectionError(e, request=request)
ConnectionError: HTTPConnectionPool(host='localhost', port=3000): Max retries exceeded with url: /msgs (Caused by NewConnectionError('<requests.packages.urllib3.connection.HTTPConnection object at 0x10542b310>: Failed to establish a new connection: [Errno 61] Connection refused',))
Tue Mar 29 10:52:24 2016
Traceback (most recent call last):
  File "/Users/linyuchen/Documents/code/Python/qq/qqsdk/qqclient.py", line 765, in run
    msg = self.getMsg()
  File "/Users/linyuchen/Documents/code/Python/qq/qqsdk/qqapi.py", line 90, in getMsg
    data = self.post_json(self.get_msgs_url)
  File "/Users/linyuchen/Documents/code/Python/qq/qqsdk/qqapi.py", line 37, in post_json
    res = requests.get(url, kwargs)
  File "/Library/Frameworks/Python.framework/Versions/2.7/lib/python2.7/site-packages/requests/api.py", line 67, in get
    return request('get', url, params=params, **kwargs)
  File "/Library/Frameworks/Python.framework/Versions/2.7/lib/python2.7/site-packages/requests/api.py", line 53, in request
    return session.request(method=method, url=url, **kwargs)
  File "/Library/Frameworks/Python.framework/Versions/2.7/lib/python2.7/site-packages/requests/sessions.py", line 468, in request
    resp = self.send(prep, **send_kwargs)
  File "/Library/Frameworks/Python.framework/Versions/2.7/lib/python2.7/site-packages/requests/sessions.py", line 576, in send
    r = adapter.send(request, **kwargs)
  File "/Library/Frameworks/Python.framework/Versions/2.7/lib/python2.7/site-packages/requests/adapters.py", line 437, in send
    raise ConnectionError(e, request=request)
ConnectionError: HTTPConnectionPool(host='localhost', port=3000): Max retries exceeded with url: /msgs (Caused by NewConnectionError('<requests.packages.urllib3.connection.HTTPConnection object at 0x10542bcd0>: Failed to establish a new connection: [Errno 61] Connection refused',))
Tue Mar 29 10:52:24 2016
Traceback (most recent call last):
  File "/Users/linyuchen/Documents/code/Python/qq/qqsdk/qqclient.py", line 765, in run
    msg = self.getMsg()
  File "/Users/linyuchen/Documents/code/Python/qq/qqsdk/qqapi.py", line 90, in getMsg
    data = self.post_json(self.get_msgs_url)
  File "/Users/linyuchen/Documents/code/Python/qq/qqsdk/qqapi.py", line 37, in post_json
    res = requests.get(url, kwargs)
  File "/Library/Frameworks/Python.framework/Versions/2.7/lib/python2.7/site-packages/requests/api.py", line 67, in get
    return request('get', url, params=params, **kwargs)
  File "/Library/Frameworks/Python.framework/Versions/2.7/lib/python2.7/site-packages/requests/api.py", line 53, in request
    return session.request(method=method, url=url, **kwargs)
  File "/Library/Frameworks/Python.framework/Versions/2.7/lib/python2.7/site-packages/requests/sessions.py", line 468, in request
    resp = self.send(prep, **send_kwargs)
  File "/Library/Frameworks/Python.framework/Versions/2.7/lib/python2.7/site-packages/requests/sessions.py", line 576, in send
    r = adapter.send(request, **kwargs)
  File "/Library/Frameworks/Python.framework/Versions/2.7/lib/python2.7/site-packages/requests/adapters.py", line 437, in send
    raise ConnectionError(e, request=request)
ConnectionError: HTTPConnectionPool(host='localhost', port=3000): Max retries exceeded with url: /msgs (Caused by NewConnectionError('<requests.packages.urllib3.connection.HTTPConnection object at 0x10542be90>: Failed to establish a new connection: [Errno 61] Connection refused',))
Tue Mar 29 10:52:24 2016
Traceback (most recent call last):
  File "/Users/linyuchen/Documents/code/Python/qq/qqsdk/qqclient.py", line 765, in run
    msg = self.getMsg()
  File "/Users/linyuchen/Documents/code/Python/qq/qqsdk/qqapi.py", line 90, in getMsg
    data = self.post_json(self.get_msgs_url)
  File "/Users/linyuchen/Documents/code/Python/qq/qqsdk/qqapi.py", line 37, in post_json
    res = requests.get(url, kwargs)
  File "/Library/Frameworks/Python.framework/Versions/2.7/lib/python2.7/site-packages/requests/api.py", line 67, in get
    return request('get', url, params=params, **kwargs)
  File "/Library/Frameworks/Python.framework/Versions/2.7/lib/python2.7/site-packages/requests/api.py", line 53, in request
    return session.request(method=method, url=url, **kwargs)
  File "/Library/Frameworks/Python.framework/Versions/2.7/lib/python2.7/site-packages/requests/sessions.py", line 468, in request
    resp = self.send(prep, **send_kwargs)
  File "/Library/Frameworks/Python.framework/Versions/2.7/lib/python2.7/site-packages/requests/sessions.py", line 576, in send
    r = adapter.send(request, **kwargs)
  File "/Library/Frameworks/Python.framework/Versions/2.7/lib/python2.7/site-packages/requests/adapters.py", line 437, in send
    raise ConnectionError(e, request=request)
ConnectionError: HTTPConnectionPool(host='localhost', port=3000): Max retries exceeded with url: /msgs (Caused by NewConnectionError('<requests.packages.urllib3.connection.HTTPConnection object at 0x10542bf90>: Failed to establish a new connection: [Errno 61] Connection refused',))
Tue Mar 29 10:52:24 2016
Traceback (most recent call last):
  File "/Users/linyuchen/Documents/code/Python/qq/qqsdk/qqclient.py", line 765, in run
    msg = self.getMsg()
  File "/Users/linyuchen/Documents/code/Python/qq/qqsdk/qqapi.py", line 90, in getMsg
    data = self.post_json(self.get_msgs_url)
  File "/Users/linyuchen/Documents/code/Python/qq/qqsdk/qqapi.py", line 37, in post_json
    res = requests.get(url, kwargs)
  File "/Library/Frameworks/Python.framework/Versions/2.7/lib/python2.7/site-packages/requests/api.py", line 67, in get
    return request('get', url, params=params, **kwargs)
  File "/Library/Frameworks/Python.framework/Versions/2.7/lib/python2.7/site-packages/requests/api.py", line 53, in request
    return session.request(method=method, url=url, **kwargs)
  File "/Library/Frameworks/Python.framework/Versions/2.7/lib/python2.7/site-packages/requests/sessions.py", line 468, in request
    resp = self.send(prep, **send_kwargs)
  File "/Library/Frameworks/Python.framework/Versions/2.7/lib/python2.7/site-packages/requests/sessions.py", line 576, in send
    r = adapter.send(request, **kwargs)
  File "/Library/Frameworks/Python.framework/Versions/2.7/lib/python2.7/site-packages/requests/adapters.py", line 437, in send
    raise ConnectionError(e, request=request)
ConnectionError: HTTPConnectionPool(host='localhost', port=3000): Max retries exceeded with url: /msgs (Caused by NewConnectionError('<requests.packages.urllib3.connection.HTTPConnection object at 0x10542be10>: Failed to establish a new connection: [Errno 61] Connection refused',))
Tue Mar 29 10:52:24 2016
Traceback (most recent call last):
  File "/Users/linyuchen/Documents/code/Python/qq/qqsdk/qqclient.py", line 765, in run
    msg = self.getMsg()
  File "/Users/linyuchen/Documents/code/Python/qq/qqsdk/qqapi.py", line 90, in getMsg
    data = self.post_json(self.get_msgs_url)
  File "/Users/linyuchen/Documents/code/Python/qq/qqsdk/qqapi.py", line 37, in post_json
    res = requests.get(url, kwargs)
  File "/Library/Frameworks/Python.framework/Versions/2.7/lib/python2.7/site-packages/requests/api.py", line 67, in get
    return request('get', url, params=params, **kwargs)
  File "/Library/Frameworks/Python.framework/Versions/2.7/lib/python2.7/site-packages/requests/api.py", line 53, in request
    return session.request(method=method, url=url, **kwargs)
  File "/Library/Frameworks/Python.framework/Versions/2.7/lib/python2.7/site-packages/requests/sessions.py", line 468, in request
    resp = self.send(prep, **send_kwargs)
  File "/Library/Frameworks/Python.framework/Versions/2.7/lib/python2.7/site-packages/requests/sessions.py", line 576, in send
    r = adapter.send(request, **kwargs)
  File "/Library/Frameworks/Python.framework/Versions/2.7/lib/python2.7/site-packages/requests/adapters.py", line 437, in send
    raise ConnectionError(e, request=request)
ConnectionError: HTTPConnectionPool(host='localhost', port=3000): Max retries exceeded with url: /msgs (Caused by NewConnectionError('<requests.packages.urllib3.connection.HTTPConnection object at 0x10542b550>: Failed to establish a new connection: [Errno 61] Connection refused',))
Tue Mar 29 10:52:24 2016
Traceback (most recent call last):
  File "/Users/linyuchen/Documents/code/Python/qq/qqsdk/qqclient.py", line 765, in run
    msg = self.getMsg()
  File "/Users/linyuchen/Documents/code/Python/qq/qqsdk/qqapi.py", line 90, in getMsg
    data = self.post_json(self.get_msgs_url)
  File "/Users/linyuchen/Documents/code/Python/qq/qqsdk/qqapi.py", line 37, in post_json
    res = requests.get(url, kwargs)
  File "/Library/Frameworks/Python.framework/Versions/2.7/lib/python2.7/site-packages/requests/api.py", line 67, in get
    return request('get', url, params=params, **kwargs)
  File "/Library/Frameworks/Python.framework/Versions/2.7/lib/python2.7/site-packages/requests/api.py", line 53, in request
    return session.request(method=method, url=url, **kwargs)
  File "/Library/Frameworks/Python.framework/Versions/2.7/lib/python2.7/site-packages/requests/sessions.py", line 468, in request
    resp = self.send(prep, **send_kwargs)
  File "/Library/Frameworks/Python.framework/Versions/2.7/lib/python2.7/site-packages/requests/sessions.py", line 576, in send
    r = adapter.send(request, **kwargs)
  File "/Library/Frameworks/Python.framework/Versions/2.7/lib/python2.7/site-packages/requests/adapters.py", line 437, in send
    raise ConnectionError(e, request=request)
ConnectionError: HTTPConnectionPool(host='localhost', port=3000): Max retries exceeded with url: /msgs (Caused by NewConnectionError('<requests.packages.urllib3.connection.HTTPConnection object at 0x1053c9e50>: Failed to establish a new connection: [Errno 61] Connection refused',))
Tue Mar 29 10:52:24 2016
Traceback (most recent call last):
  File "/Users/linyuchen/Documents/code/Python/qq/qqsdk/qqclient.py", line 765, in run
    msg = self.getMsg()
  File "/Users/linyuchen/Documents/code/Python/qq/qqsdk/qqapi.py", line 90, in getMsg
    data = self.post_json(self.get_msgs_url)
  File "/Users/linyuchen/Documents/code/Python/qq/qqsdk/qqapi.py", line 37, in post_json
    res = requests.get(url, kwargs)
  File "/Library/Frameworks/Python.framework/Versions/2.7/lib/python2.7/site-packages/requests/api.py", line 67, in get
    return request('get', url, params=params, **kwargs)
  File "/Library/Frameworks/Python.framework/Versions/2.7/lib/python2.7/site-packages/requests/api.py", line 53, in request
    return session.request(method=method, url=url, **kwargs)
  File "/Library/Frameworks/Python.framework/Versions/2.7/lib/python2.7/site-packages/requests/sessions.py", line 468, in request
    resp = self.send(prep, **send_kwargs)
  File "/Library/Frameworks/Python.framework/Versions/2.7/lib/python2.7/site-packages/requests/sessions.py", line 576, in send
    r = adapter.send(request, **kwargs)
  File "/Library/Frameworks/Python.framework/Versions/2.7/lib/python2.7/site-packages/requests/adapters.py", line 437, in send
    raise ConnectionError(e, request=request)
ConnectionError: HTTPConnectionPool(host='localhost', port=3000): Max retries exceeded with url: /msgs (Caused by NewConnectionError('<requests.packages.urllib3.connection.HTTPConnection object at 0x1053c9790>: Failed to establish a new connection: [Errno 61] Connection refused',))
Tue Mar 29 10:52:24 2016
Traceback (most recent call last):
  File "/Users/linyuchen/Documents/code/Python/qq/qqsdk/qqclient.py", line 765, in run
    msg = self.getMsg()
  File "/Users/linyuchen/Documents/code/Python/qq/qqsdk/qqapi.py", line 90, in getMsg
    data = self.post_json(self.get_msgs_url)
  File "/Users/linyuchen/Documents/code/Python/qq/qqsdk/qqapi.py", line 37, in post_json
    res = requests.get(url, kwargs)
  File "/Library/Frameworks/Python.framework/Versions/2.7/lib/python2.7/site-packages/requests/api.py", line 67, in get
    return request('get', url, params=params, **kwargs)
  File "/Library/Frameworks/Python.framework/Versions/2.7/lib/python2.7/site-packages/requests/api.py", line 53, in request
    return session.request(method=method, url=url, **kwargs)
  File "/Library/Frameworks/Python.framework/Versions/2.7/lib/python2.7/site-packages/requests/sessions.py", line 468, in request
    resp = self.send(prep, **send_kwargs)
  File "/Library/Frameworks/Python.framework/Versions/2.7/lib/python2.7/site-packages/requests/sessions.py", line 576, in send
    r = adapter.send(request, **kwargs)
  File "/Library/Frameworks/Python.framework/Versions/2.7/lib/python2.7/site-packages/requests/adapters.py", line 437, in send
    raise ConnectionError(e, request=request)
ConnectionError: HTTPConnectionPool(host='localhost', port=3000): Max retries exceeded with url: /msgs (Caused by NewConnectionError('<requests.packages.urllib3.connection.HTTPConnection object at 0x1053c9710>: Failed to establish a new connection: [Errno 61] Connection refused',))
Tue Mar 29 10:52:24 2016
Traceback (most recent call last):
  File "/Users/linyuchen/Documents/code/Python/qq/qqsdk/qqclient.py", line 765, in run
    msg = self.getMsg()
  File "/Users/linyuchen/Documents/code/Python/qq/qqsdk/qqapi.py", line 90, in getMsg
    data = self.post_json(self.get_msgs_url)
  File "/Users/linyuchen/Documents/code/Python/qq/qqsdk/qqapi.py", line 37, in post_json
    res = requests.get(url, kwargs)
  File "/Library/Frameworks/Python.framework/Versions/2.7/lib/python2.7/site-packages/requests/api.py", line 67, in get
    return request('get', url, params=params, **kwargs)
  File "/Library/Frameworks/Python.framework/Versions/2.7/lib/python2.7/site-packages/requests/api.py", line 53, in request
    return session.request(method=method, url=url, **kwargs)
  File "/Library/Frameworks/Python.framework/Versions/2.7/lib/python2.7/site-packages/requests/sessions.py", line 468, in request
    resp = self.send(prep, **send_kwargs)
  File "/Library/Frameworks/Python.framework/Versions/2.7/lib/python2.7/site-packages/requests/sessions.py", line 576, in send
    r = adapter.send(request, **kwargs)
  File "/Library/Frameworks/Python.framework/Versions/2.7/lib/python2.7/site-packages/requests/adapters.py", line 437, in send
    raise ConnectionError(e, request=request)
ConnectionError: HTTPConnectionPool(host='localhost', port=3000): Max retries exceeded with url: /msgs (Caused by NewConnectionError('<requests.packages.urllib3.connection.HTTPConnection object at 0x1053c9490>: Failed to establish a new connection: [Errno 61] Connection refused',))
Tue Mar 29 10:52:25 2016
Traceback (most recent call last):
  File "/Users/linyuchen/Documents/code/Python/qq/qqsdk/qqclient.py", line 765, in run
    msg = self.getMsg()
  File "/Users/linyuchen/Documents/code/Python/qq/qqsdk/qqapi.py", line 90, in getMsg
    data = self.post_json(self.get_msgs_url)
  File "/Users/linyuchen/Documents/code/Python/qq/qqsdk/qqapi.py", line 37, in post_json
    res = requests.get(url, kwargs)
  File "/Library/Frameworks/Python.framework/Versions/2.7/lib/python2.7/site-packages/requests/api.py", line 67, in get
    return request('get', url, params=params, **kwargs)
  File "/Library/Frameworks/Python.framework/Versions/2.7/lib/python2.7/site-packages/requests/api.py", line 53, in request
    return session.request(method=method, url=url, **kwargs)
  File "/Library/Frameworks/Python.framework/Versions/2.7/lib/python2.7/site-packages/requests/sessions.py", line 468, in request
    resp = self.send(prep, **send_kwargs)
  File "/Library/Frameworks/Python.framework/Versions/2.7/lib/python2.7/site-packages/requests/sessions.py", line 576, in send
    r = adapter.send(request, **kwargs)
  File "/Library/Frameworks/Python.framework/Versions/2.7/lib/python2.7/site-packages/requests/adapters.py", line 437, in send
    raise ConnectionError(e, request=request)
ConnectionError: HTTPConnectionPool(host='localhost', port=3000): Max retries exceeded with url: /msgs (Caused by NewConnectionError('<requests.packages.urllib3.connection.HTTPConnection object at 0x1053c9b50>: Failed to establish a new connection: [Errno 61] Connection refused',))
Tue Mar 29 10:52:25 2016
Traceback (most recent call last):
  File "/Users/linyuchen/Documents/code/Python/qq/qqsdk/qqclient.py", line 765, in run
    msg = self.getMsg()
  File "/Users/linyuchen/Documents/code/Python/qq/qqsdk/qqapi.py", line 90, in getMsg
    data = self.post_json(self.get_msgs_url)
  File "/Users/linyuchen/Documents/code/Python/qq/qqsdk/qqapi.py", line 37, in post_json
    res = requests.get(url, kwargs)
  File "/Library/Frameworks/Python.framework/Versions/2.7/lib/python2.7/site-packages/requests/api.py", line 67, in get
    return request('get', url, params=params, **kwargs)
  File "/Library/Frameworks/Python.framework/Versions/2.7/lib/python2.7/site-packages/requests/api.py", line 53, in request
    return session.request(method=method, url=url, **kwargs)
  File "/Library/Frameworks/Python.framework/Versions/2.7/lib/python2.7/site-packages/requests/sessions.py", line 468, in request
    resp = self.send(prep, **send_kwargs)
  File "/Library/Frameworks/Python.framework/Versions/2.7/lib/python2.7/site-packages/requests/sessions.py", line 576, in send
    r = adapter.send(request, **kwargs)
  File "/Library/Frameworks/Python.framework/Versions/2.7/lib/python2.7/site-packages/requests/adapters.py", line 437, in send
    raise ConnectionError(e, request=request)
ConnectionError: HTTPConnectionPool(host='localhost', port=3000): Max retries exceeded with url: /msgs (Caused by NewConnectionError('<requests.packages.urllib3.connection.HTTPConnection object at 0x1053c90d0>: Failed to establish a new connection: [Errno 61] Connection refused',))
Tue Mar 29 10:52:25 2016
Traceback (most recent call last):
  File "/Users/linyuchen/Documents/code/Python/qq/qqsdk/qqclient.py", line 765, in run
    msg = self.getMsg()
  File "/Users/linyuchen/Documents/code/Python/qq/qqsdk/qqapi.py", line 90, in getMsg
    data = self.post_json(self.get_msgs_url)
  File "/Users/linyuchen/Documents/code/Python/qq/qqsdk/qqapi.py", line 37, in post_json
    res = requests.get(url, kwargs)
  File "/Library/Frameworks/Python.framework/Versions/2.7/lib/python2.7/site-packages/requests/api.py", line 67, in get
    return request('get', url, params=params, **kwargs)
  File "/Library/Frameworks/Python.framework/Versions/2.7/lib/python2.7/site-packages/requests/api.py", line 53, in request
    return session.request(method=method, url=url, **kwargs)
  File "/Library/Frameworks/Python.framework/Versions/2.7/lib/python2.7/site-packages/requests/sessions.py", line 468, in request
    resp = self.send(prep, **send_kwargs)
  File "/Library/Frameworks/Python.framework/Versions/2.7/lib/python2.7/site-packages/requests/sessions.py", line 576, in send
    r = adapter.send(request, **kwargs)
  File "/Library/Frameworks/Python.framework/Versions/2.7/lib/python2.7/site-packages/requests/adapters.py", line 437, in send
    raise ConnectionError(e, request=request)
ConnectionError: HTTPConnectionPool(host='localhost', port=3000): Max retries exceeded with url: /msgs (Caused by NewConnectionError('<requests.packages.urllib3.connection.HTTPConnection object at 0x1053c91d0>: Failed to establish a new connection: [Errno 61] Connection refused',))
Tue Mar 29 10:52:25 2016
Traceback (most recent call last):
  File "/Users/linyuchen/Documents/code/Python/qq/qqsdk/qqclient.py", line 765, in run
    msg = self.getMsg()
  File "/Users/linyuchen/Documents/code/Python/qq/qqsdk/qqapi.py", line 90, in getMsg
    data = self.post_json(self.get_msgs_url)
  File "/Users/linyuchen/Documents/code/Python/qq/qqsdk/qqapi.py", line 37, in post_json
    res = requests.get(url, kwargs)
  File "/Library/Frameworks/Python.framework/Versions/2.7/lib/python2.7/site-packages/requests/api.py", line 67, in get
    return request('get', url, params=params, **kwargs)
  File "/Library/Frameworks/Python.framework/Versions/2.7/lib/python2.7/site-packages/requests/api.py", line 53, in request
    return session.request(method=method, url=url, **kwargs)
  File "/Library/Frameworks/Python.framework/Versions/2.7/lib/python2.7/site-packages/requests/sessions.py", line 468, in request
    resp = self.send(prep, **send_kwargs)
  File "/Library/Frameworks/Python.framework/Versions/2.7/lib/python2.7/site-packages/requests/sessions.py", line 576, in send
    r = adapter.send(request, **kwargs)
  File "/Library/Frameworks/Python.framework/Versions/2.7/lib/python2.7/site-packages/requests/adapters.py", line 437, in send
    raise ConnectionError(e, request=request)
ConnectionError: HTTPConnectionPool(host='localhost', port=3000): Max retries exceeded with url: /msgs (Caused by NewConnectionError('<requests.packages.urllib3.connection.HTTPConnection object at 0x1053c92d0>: Failed to establish a new connection: [Errno 61] Connection refused',))
Tue Mar 29 10:52:25 2016
Traceback (most recent call last):
  File "/Users/linyuchen/Documents/code/Python/qq/qqsdk/qqclient.py", line 765, in run
    msg = self.getMsg()
  File "/Users/linyuchen/Documents/code/Python/qq/qqsdk/qqapi.py", line 90, in getMsg
    data = self.post_json(self.get_msgs_url)
  File "/Users/linyuchen/Documents/code/Python/qq/qqsdk/qqapi.py", line 37, in post_json
    res = requests.get(url, kwargs)
  File "/Library/Frameworks/Python.framework/Versions/2.7/lib/python2.7/site-packages/requests/api.py", line 67, in get
    return request('get', url, params=params, **kwargs)
  File "/Library/Frameworks/Python.framework/Versions/2.7/lib/python2.7/site-packages/requests/api.py", line 53, in request
    return session.request(method=method, url=url, **kwargs)
  File "/Library/Frameworks/Python.framework/Versions/2.7/lib/python2.7/site-packages/requests/sessions.py", line 468, in request
    resp = self.send(prep, **send_kwargs)
  File "/Library/Frameworks/Python.framework/Versions/2.7/lib/python2.7/site-packages/requests/sessions.py", line 576, in send
    r = adapter.send(request, **kwargs)
  File "/Library/Frameworks/Python.framework/Versions/2.7/lib/python2.7/site-packages/requests/adapters.py", line 437, in send
    raise ConnectionError(e, request=request)
ConnectionError: HTTPConnectionPool(host='localhost', port=3000): Max retries exceeded with url: /msgs (Caused by NewConnectionError('<requests.packages.urllib3.connection.HTTPConnection object at 0x1053c93d0>: Failed to establish a new connection: [Errno 61] Connection refused',))
Tue Mar 29 10:52:25 2016
Traceback (most recent call last):
  File "/Users/linyuchen/Documents/code/Python/qq/qqsdk/qqclient.py", line 765, in run
    msg = self.getMsg()
  File "/Users/linyuchen/Documents/code/Python/qq/qqsdk/qqapi.py", line 90, in getMsg
    data = self.post_json(self.get_msgs_url)
  File "/Users/linyuchen/Documents/code/Python/qq/qqsdk/qqapi.py", line 37, in post_json
    res = requests.get(url, kwargs)
  File "/Library/Frameworks/Python.framework/Versions/2.7/lib/python2.7/site-packages/requests/api.py", line 67, in get
    return request('get', url, params=params, **kwargs)
  File "/Library/Frameworks/Python.framework/Versions/2.7/lib/python2.7/site-packages/requests/api.py", line 53, in request
    return session.request(method=method, url=url, **kwargs)
  File "/Library/Frameworks/Python.framework/Versions/2.7/lib/python2.7/site-packages/requests/sessions.py", line 468, in request
    resp = self.send(prep, **send_kwargs)
  File "/Library/Frameworks/Python.framework/Versions/2.7/lib/python2.7/site-packages/requests/sessions.py", line 576, in send
    r = adapter.send(request, **kwargs)
  File "/Library/Frameworks/Python.framework/Versions/2.7/lib/python2.7/site-packages/requests/adapters.py", line 437, in send
    raise ConnectionError(e, request=request)
ConnectionError: HTTPConnectionPool(host='localhost', port=3000): Max retries exceeded with url: /msgs (Caused by NewConnectionError('<requests.packages.urllib3.connection.HTTPConnection object at 0x1053c94d0>: Failed to establish a new connection: [Errno 61] Connection refused',))
Tue Mar 29 10:52:25 2016
Traceback (most recent call last):
  File "/Users/linyuchen/Documents/code/Python/qq/qqsdk/qqclient.py", line 765, in run
    msg = self.getMsg()
  File "/Users/linyuchen/Documents/code/Python/qq/qqsdk/qqapi.py", line 90, in getMsg
    data = self.post_json(self.get_msgs_url)
  File "/Users/linyuchen/Documents/code/Python/qq/qqsdk/qqapi.py", line 37, in post_json
    res = requests.get(url, kwargs)
  File "/Library/Frameworks/Python.framework/Versions/2.7/lib/python2.7/site-packages/requests/api.py", line 67, in get
    return request('get', url, params=params, **kwargs)
  File "/Library/Frameworks/Python.framework/Versions/2.7/lib/python2.7/site-packages/requests/api.py", line 53, in request
    return session.request(method=method, url=url, **kwargs)
  File "/Library/Frameworks/Python.framework/Versions/2.7/lib/python2.7/site-packages/requests/sessions.py", line 468, in request
    resp = self.send(prep, **send_kwargs)
  File "/Library/Frameworks/Python.framework/Versions/2.7/lib/python2.7/site-packages/requests/sessions.py", line 576, in send
    r = adapter.send(request, **kwargs)
  File "/Library/Frameworks/Python.framework/Versions/2.7/lib/python2.7/site-packages/requests/adapters.py", line 437, in send
    raise ConnectionError(e, request=request)
ConnectionError: HTTPConnectionPool(host='localhost', port=3000): Max retries exceeded with url: /msgs (Caused by NewConnectionError('<requests.packages.urllib3.connection.HTTPConnection object at 0x1053c95d0>: Failed to establish a new connection: [Errno 61] Connection refused',))
Tue Mar 29 10:52:25 2016
Traceback (most recent call last):
  File "/Users/linyuchen/Documents/code/Python/qq/qqsdk/qqclient.py", line 765, in run
    msg = self.getMsg()
  File "/Users/linyuchen/Documents/code/Python/qq/qqsdk/qqapi.py", line 90, in getMsg
    data = self.post_json(self.get_msgs_url)
  File "/Users/linyuchen/Documents/code/Python/qq/qqsdk/qqapi.py", line 37, in post_json
    res = requests.get(url, kwargs)
  File "/Library/Frameworks/Python.framework/Versions/2.7/lib/python2.7/site-packages/requests/api.py", line 67, in get
    return request('get', url, params=params, **kwargs)
  File "/Library/Frameworks/Python.framework/Versions/2.7/lib/python2.7/site-packages/requests/api.py", line 53, in request
    return session.request(method=method, url=url, **kwargs)
  File "/Library/Frameworks/Python.framework/Versions/2.7/lib/python2.7/site-packages/requests/sessions.py", line 468, in request
    resp = self.send(prep, **send_kwargs)
  File "/Library/Frameworks/Python.framework/Versions/2.7/lib/python2.7/site-packages/requests/sessions.py", line 576, in send
    r = adapter.send(request, **kwargs)
  File "/Library/Frameworks/Python.framework/Versions/2.7/lib/python2.7/site-packages/requests/adapters.py", line 437, in send
    raise ConnectionError(e, request=request)
ConnectionError: HTTPConnectionPool(host='localhost', port=3000): Max retries exceeded with url: /msgs (Caused by NewConnectionError('<requests.packages.urllib3.connection.HTTPConnection object at 0x1053c96d0>: Failed to establish a new connection: [Errno 61] Connection refused',))
Tue Mar 29 10:52:25 2016
Traceback (most recent call last):
  File "/Users/linyuchen/Documents/code/Python/qq/qqsdk/qqclient.py", line 765, in run
    msg = self.getMsg()
  File "/Users/linyuchen/Documents/code/Python/qq/qqsdk/qqapi.py", line 90, in getMsg
    data = self.post_json(self.get_msgs_url)
  File "/Users/linyuchen/Documents/code/Python/qq/qqsdk/qqapi.py", line 37, in post_json
    res = requests.get(url, kwargs)
  File "/Library/Frameworks/Python.framework/Versions/2.7/lib/python2.7/site-packages/requests/api.py", line 67, in get
    return request('get', url, params=params, **kwargs)
  File "/Library/Frameworks/Python.framework/Versions/2.7/lib/python2.7/site-packages/requests/api.py", line 53, in request
    return session.request(method=method, url=url, **kwargs)
  File "/Library/Frameworks/Python.framework/Versions/2.7/lib/python2.7/site-packages/requests/sessions.py", line 468, in request
    resp = self.send(prep, **send_kwargs)
  File "/Library/Frameworks/Python.framework/Versions/2.7/lib/python2.7/site-packages/requests/sessions.py", line 576, in send
    r = adapter.send(request, **kwargs)
  File "/Library/Frameworks/Python.framework/Versions/2.7/lib/python2.7/site-packages/requests/adapters.py", line 437, in send
    raise ConnectionError(e, request=request)
ConnectionError: HTTPConnectionPool(host='localhost', port=3000): Max retries exceeded with url: /msgs (Caused by NewConnectionError('<requests.packages.urllib3.connection.HTTPConnection object at 0x1053c97d0>: Failed to establish a new connection: [Errno 61] Connection refused',))
Tue Mar 29 10:52:26 2016
Traceback (most recent call last):
  File "/Users/linyuchen/Documents/code/Python/qq/qqsdk/qqclient.py", line 765, in run
    msg = self.getMsg()
  File "/Users/linyuchen/Documents/code/Python/qq/qqsdk/qqapi.py", line 90, in getMsg
    data = self.post_json(self.get_msgs_url)
  File "/Users/linyuchen/Documents/code/Python/qq/qqsdk/qqapi.py", line 37, in post_json
    res = requests.get(url, kwargs)
  File "/Library/Frameworks/Python.framework/Versions/2.7/lib/python2.7/site-packages/requests/api.py", line 67, in get
    return request('get', url, params=params, **kwargs)
  File "/Library/Frameworks/Python.framework/Versions/2.7/lib/python2.7/site-packages/requests/api.py", line 53, in request
    return session.request(method=method, url=url, **kwargs)
  File "/Library/Frameworks/Python.framework/Versions/2.7/lib/python2.7/site-packages/requests/sessions.py", line 468, in request
    resp = self.send(prep, **send_kwargs)
  File "/Library/Frameworks/Python.framework/Versions/2.7/lib/python2.7/site-packages/requests/sessions.py", line 576, in send
    r = adapter.send(request, **kwargs)
  File "/Library/Frameworks/Python.framework/Versions/2.7/lib/python2.7/site-packages/requests/adapters.py", line 437, in send
    raise ConnectionError(e, request=request)
ConnectionError: HTTPConnectionPool(host='localhost', port=3000): Max retries exceeded with url: /msgs (Caused by NewConnectionError('<requests.packages.urllib3.connection.HTTPConnection object at 0x1053c90d0>: Failed to establish a new connection: [Errno 61] Connection refused',))
Tue Mar 29 10:52:26 2016
Traceback (most recent call last):
  File "/Users/linyuchen/Documents/code/Python/qq/qqsdk/qqclient.py", line 765, in run
    msg = self.getMsg()
  File "/Users/linyuchen/Documents/code/Python/qq/qqsdk/qqapi.py", line 90, in getMsg
    data = self.post_json(self.get_msgs_url)
  File "/Users/linyuchen/Documents/code/Python/qq/qqsdk/qqapi.py", line 37, in post_json
    res = requests.get(url, kwargs)
  File "/Library/Frameworks/Python.framework/Versions/2.7/lib/python2.7/site-packages/requests/api.py", line 67, in get
    return request('get', url, params=params, **kwargs)
  File "/Library/Frameworks/Python.framework/Versions/2.7/lib/python2.7/site-packages/requests/api.py", line 53, in request
    return session.request(method=method, url=url, **kwargs)
  File "/Library/Frameworks/Python.framework/Versions/2.7/lib/python2.7/site-packages/requests/sessions.py", line 468, in request
    resp = self.send(prep, **send_kwargs)
  File "/Library/Frameworks/Python.framework/Versions/2.7/lib/python2.7/site-packages/requests/sessions.py", line 576, in send
    r = adapter.send(request, **kwargs)
  File "/Library/Frameworks/Python.framework/Versions/2.7/lib/python2.7/site-packages/requests/adapters.py", line 437, in send
    raise ConnectionError(e, request=request)
ConnectionError: HTTPConnectionPool(host='localhost', port=3000): Max retries exceeded with url: /msgs (Caused by NewConnectionError('<requests.packages.urllib3.connection.HTTPConnection object at 0x1053c9d50>: Failed to establish a new connection: [Errno 61] Connection refused',))
Tue Mar 29 10:52:26 2016
Traceback (most recent call last):
  File "/Users/linyuchen/Documents/code/Python/qq/qqsdk/qqclient.py", line 765, in run
    msg = self.getMsg()
  File "/Users/linyuchen/Documents/code/Python/qq/qqsdk/qqapi.py", line 90, in getMsg
    data = self.post_json(self.get_msgs_url)
  File "/Users/linyuchen/Documents/code/Python/qq/qqsdk/qqapi.py", line 37, in post_json
    res = requests.get(url, kwargs)
  File "/Library/Frameworks/Python.framework/Versions/2.7/lib/python2.7/site-packages/requests/api.py", line 67, in get
    return request('get', url, params=params, **kwargs)
  File "/Library/Frameworks/Python.framework/Versions/2.7/lib/python2.7/site-packages/requests/api.py", line 53, in request
    return session.request(method=method, url=url, **kwargs)
  File "/Library/Frameworks/Python.framework/Versions/2.7/lib/python2.7/site-packages/requests/sessions.py", line 468, in request
    resp = self.send(prep, **send_kwargs)
  File "/Library/Frameworks/Python.framework/Versions/2.7/lib/python2.7/site-packages/requests/sessions.py", line 576, in send
    r = adapter.send(request, **kwargs)
  File "/Library/Frameworks/Python.framework/Versions/2.7/lib/python2.7/site-packages/requests/adapters.py", line 437, in send
    raise ConnectionError(e, request=request)
ConnectionError: HTTPConnectionPool(host='localhost', port=3000): Max retries exceeded with url: /msgs (Caused by NewConnectionError('<requests.packages.urllib3.connection.HTTPConnection object at 0x1053c99d0>: Failed to establish a new connection: [Errno 61] Connection refused',))
Tue Mar 29 10:52:26 2016
Traceback (most recent call last):
  File "/Users/linyuchen/Documents/code/Python/qq/qqsdk/qqclient.py", line 765, in run
    msg = self.getMsg()
  File "/Users/linyuchen/Documents/code/Python/qq/qqsdk/qqapi.py", line 90, in getMsg
    data = self.post_json(self.get_msgs_url)
  File "/Users/linyuchen/Documents/code/Python/qq/qqsdk/qqapi.py", line 37, in post_json
    res = requests.get(url, kwargs)
  File "/Library/Frameworks/Python.framework/Versions/2.7/lib/python2.7/site-packages/requests/api.py", line 67, in get
    return request('get', url, params=params, **kwargs)
  File "/Library/Frameworks/Python.framework/Versions/2.7/lib/python2.7/site-packages/requests/api.py", line 53, in request
    return session.request(method=method, url=url, **kwargs)
  File "/Library/Frameworks/Python.framework/Versions/2.7/lib/python2.7/site-packages/requests/sessions.py", line 468, in request
    resp = self.send(prep, **send_kwargs)
  File "/Library/Frameworks/Python.framework/Versions/2.7/lib/python2.7/site-packages/requests/sessions.py", line 576, in send
    r = adapter.send(request, **kwargs)
  File "/Library/Frameworks/Python.framework/Versions/2.7/lib/python2.7/site-packages/requests/adapters.py", line 437, in send
    raise ConnectionError(e, request=request)
ConnectionError: HTTPConnectionPool(host='localhost', port=3000): Max retries exceeded with url: /msgs (Caused by NewConnectionError('<requests.packages.urllib3.connection.HTTPConnection object at 0x1053c9b10>: Failed to establish a new connection: [Errno 61] Connection refused',))
Tue Mar 29 10:52:26 2016
Traceback (most recent call last):
  File "/Users/linyuchen/Documents/code/Python/qq/qqsdk/qqclient.py", line 765, in run
    msg = self.getMsg()
  File "/Users/linyuchen/Documents/code/Python/qq/qqsdk/qqapi.py", line 90, in getMsg
    data = self.post_json(self.get_msgs_url)
  File "/Users/linyuchen/Documents/code/Python/qq/qqsdk/qqapi.py", line 37, in post_json
    res = requests.get(url, kwargs)
  File "/Library/Frameworks/Python.framework/Versions/2.7/lib/python2.7/site-packages/requests/api.py", line 67, in get
    return request('get', url, params=params, **kwargs)
  File "/Library/Frameworks/Python.framework/Versions/2.7/lib/python2.7/site-packages/requests/api.py", line 53, in request
    return session.request(method=method, url=url, **kwargs)
  File "/Library/Frameworks/Python.framework/Versions/2.7/lib/python2.7/site-packages/requests/sessions.py", line 468, in request
    resp = self.send(prep, **send_kwargs)
  File "/Library/Frameworks/Python.framework/Versions/2.7/lib/python2.7/site-packages/requests/sessions.py", line 576, in send
    r = adapter.send(request, **kwargs)
  File "/Library/Frameworks/Python.framework/Versions/2.7/lib/python2.7/site-packages/requests/adapters.py", line 437, in send
    raise ConnectionError(e, request=request)
ConnectionError: HTTPConnectionPool(host='localhost', port=3000): Max retries exceeded with url: /msgs (Caused by NewConnectionError('<requests.packages.urllib3.connection.HTTPConnection object at 0x1053c9c10>: Failed to establish a new connection: [Errno 61] Connection refused',))
Tue Mar 29 10:52:26 2016
Traceback (most recent call last):
  File "/Users/linyuchen/Documents/code/Python/qq/qqsdk/qqclient.py", line 765, in run
    msg = self.getMsg()
  File "/Users/linyuchen/Documents/code/Python/qq/qqsdk/qqapi.py", line 90, in getMsg
    data = self.post_json(self.get_msgs_url)
  File "/Users/linyuchen/Documents/code/Python/qq/qqsdk/qqapi.py", line 37, in post_json
    res = requests.get(url, kwargs)
  File "/Library/Frameworks/Python.framework/Versions/2.7/lib/python2.7/site-packages/requests/api.py", line 67, in get
    return request('get', url, params=params, **kwargs)
  File "/Library/Frameworks/Python.framework/Versions/2.7/lib/python2.7/site-packages/requests/api.py", line 53, in request
    return session.request(method=method, url=url, **kwargs)
  File "/Library/Frameworks/Python.framework/Versions/2.7/lib/python2.7/site-packages/requests/sessions.py", line 468, in request
    resp = self.send(prep, **send_kwargs)
  File "/Library/Frameworks/Python.framework/Versions/2.7/lib/python2.7/site-packages/requests/sessions.py", line 576, in send
    r = adapter.send(request, **kwargs)
  File "/Library/Frameworks/Python.framework/Versions/2.7/lib/python2.7/site-packages/requests/adapters.py", line 437, in send
    raise ConnectionError(e, request=request)
ConnectionError: HTTPConnectionPool(host='localhost', port=3000): Max retries exceeded with url: /msgs (Caused by NewConnectionError('<requests.packages.urllib3.connection.HTTPConnection object at 0x1053c9e90>: Failed to establish a new connection: [Errno 61] Connection refused',))
Tue Mar 29 10:52:26 2016
Traceback (most recent call last):
  File "/Users/linyuchen/Documents/code/Python/qq/qqsdk/qqclient.py", line 765, in run
    msg = self.getMsg()
  File "/Users/linyuchen/Documents/code/Python/qq/qqsdk/qqapi.py", line 90, in getMsg
    data = self.post_json(self.get_msgs_url)
  File "/Users/linyuchen/Documents/code/Python/qq/qqsdk/qqapi.py", line 37, in post_json
    res = requests.get(url, kwargs)
  File "/Library/Frameworks/Python.framework/Versions/2.7/lib/python2.7/site-packages/requests/api.py", line 67, in get
    return request('get', url, params=params, **kwargs)
  File "/Library/Frameworks/Python.framework/Versions/2.7/lib/python2.7/site-packages/requests/api.py", line 53, in request
    return session.request(method=method, url=url, **kwargs)
  File "/Library/Frameworks/Python.framework/Versions/2.7/lib/python2.7/site-packages/requests/sessions.py", line 468, in request
    resp = self.send(prep, **send_kwargs)
  File "/Library/Frameworks/Python.framework/Versions/2.7/lib/python2.7/site-packages/requests/sessions.py", line 576, in send
    r = adapter.send(request, **kwargs)
  File "/Library/Frameworks/Python.framework/Versions/2.7/lib/python2.7/site-packages/requests/adapters.py", line 437, in send
    raise ConnectionError(e, request=request)
ConnectionError: HTTPConnectionPool(host='localhost', port=3000): Max retries exceeded with url: /msgs (Caused by NewConnectionError('<requests.packages.urllib3.connection.HTTPConnection object at 0x1053c98d0>: Failed to establish a new connection: [Errno 61] Connection refused',))
Tue Mar 29 10:52:26 2016
Traceback (most recent call last):
  File "/Users/linyuchen/Documents/code/Python/qq/qqsdk/qqclient.py", line 765, in run
    msg = self.getMsg()
  File "/Users/linyuchen/Documents/code/Python/qq/qqsdk/qqapi.py", line 90, in getMsg
    data = self.post_json(self.get_msgs_url)
  File "/Users/linyuchen/Documents/code/Python/qq/qqsdk/qqapi.py", line 37, in post_json
    res = requests.get(url, kwargs)
  File "/Library/Frameworks/Python.framework/Versions/2.7/lib/python2.7/site-packages/requests/api.py", line 67, in get
    return request('get', url, params=params, **kwargs)
  File "/Library/Frameworks/Python.framework/Versions/2.7/lib/python2.7/site-packages/requests/api.py", line 53, in request
    return session.request(method=method, url=url, **kwargs)
  File "/Library/Frameworks/Python.framework/Versions/2.7/lib/python2.7/site-packages/requests/sessions.py", line 468, in request
    resp = self.send(prep, **send_kwargs)
  File "/Library/Frameworks/Python.framework/Versions/2.7/lib/python2.7/site-packages/requests/sessions.py", line 576, in send
    r = adapter.send(request, **kwargs)
  File "/Library/Frameworks/Python.framework/Versions/2.7/lib/python2.7/site-packages/requests/adapters.py", line 437, in send
    raise ConnectionError(e, request=request)
ConnectionError: HTTPConnectionPool(host='localhost', port=3000): Max retries exceeded with url: /msgs (Caused by NewConnectionError('<requests.packages.urllib3.connection.HTTPConnection object at 0x10541e510>: Failed to establish a new connection: [Errno 61] Connection refused',))
Tue Mar 29 10:52:26 2016
Traceback (most recent call last):
  File "/Users/linyuchen/Documents/code/Python/qq/qqsdk/qqclient.py", line 765, in run
    msg = self.getMsg()
  File "/Users/linyuchen/Documents/code/Python/qq/qqsdk/qqapi.py", line 90, in getMsg
    data = self.post_json(self.get_msgs_url)
  File "/Users/linyuchen/Documents/code/Python/qq/qqsdk/qqapi.py", line 37, in post_json
    res = requests.get(url, kwargs)
  File "/Library/Frameworks/Python.framework/Versions/2.7/lib/python2.7/site-packages/requests/api.py", line 67, in get
    return request('get', url, params=params, **kwargs)
  File "/Library/Frameworks/Python.framework/Versions/2.7/lib/python2.7/site-packages/requests/api.py", line 53, in request
    return session.request(method=method, url=url, **kwargs)
  File "/Library/Frameworks/Python.framework/Versions/2.7/lib/python2.7/site-packages/requests/sessions.py", line 468, in request
    resp = self.send(prep, **send_kwargs)
  File "/Library/Frameworks/Python.framework/Versions/2.7/lib/python2.7/site-packages/requests/sessions.py", line 576, in send
    r = adapter.send(request, **kwargs)
  File "/Library/Frameworks/Python.framework/Versions/2.7/lib/python2.7/site-packages/requests/adapters.py", line 437, in send
    raise ConnectionError(e, request=request)
ConnectionError: HTTPConnectionPool(host='localhost', port=3000): Max retries exceeded with url: /msgs (Caused by NewConnectionError('<requests.packages.urllib3.connection.HTTPConnection object at 0x10541e690>: Failed to establish a new connection: [Errno 61] Connection refused',))
Tue Mar 29 10:52:27 2016
Traceback (most recent call last):
  File "/Users/linyuchen/Documents/code/Python/qq/qqsdk/qqclient.py", line 765, in run
    msg = self.getMsg()
  File "/Users/linyuchen/Documents/code/Python/qq/qqsdk/qqapi.py", line 90, in getMsg
    data = self.post_json(self.get_msgs_url)
  File "/Users/linyuchen/Documents/code/Python/qq/qqsdk/qqapi.py", line 37, in post_json
    res = requests.get(url, kwargs)
  File "/Library/Frameworks/Python.framework/Versions/2.7/lib/python2.7/site-packages/requests/api.py", line 67, in get
    return request('get', url, params=params, **kwargs)
  File "/Library/Frameworks/Python.framework/Versions/2.7/lib/python2.7/site-packages/requests/api.py", line 53, in request
    return session.request(method=method, url=url, **kwargs)
  File "/Library/Frameworks/Python.framework/Versions/2.7/lib/python2.7/site-packages/requests/sessions.py", line 468, in request
    resp = self.send(prep, **send_kwargs)
  File "/Library/Frameworks/Python.framework/Versions/2.7/lib/python2.7/site-packages/requests/sessions.py", line 576, in send
    r = adapter.send(request, **kwargs)
  File "/Library/Frameworks/Python.framework/Versions/2.7/lib/python2.7/site-packages/requests/adapters.py", line 437, in send
    raise ConnectionError(e, request=request)
ConnectionError: HTTPConnectionPool(host='localhost', port=3000): Max retries exceeded with url: /msgs (Caused by NewConnectionError('<requests.packages.urllib3.connection.HTTPConnection object at 0x10541e150>: Failed to establish a new connection: [Errno 61] Connection refused',))
Tue Mar 29 10:52:27 2016
Traceback (most recent call last):
  File "/Users/linyuchen/Documents/code/Python/qq/qqsdk/qqclient.py", line 765, in run
    msg = self.getMsg()
  File "/Users/linyuchen/Documents/code/Python/qq/qqsdk/qqapi.py", line 90, in getMsg
    data = self.post_json(self.get_msgs_url)
  File "/Users/linyuchen/Documents/code/Python/qq/qqsdk/qqapi.py", line 37, in post_json
    res = requests.get(url, kwargs)
  File "/Library/Frameworks/Python.framework/Versions/2.7/lib/python2.7/site-packages/requests/api.py", line 67, in get
    return request('get', url, params=params, **kwargs)
  File "/Library/Frameworks/Python.framework/Versions/2.7/lib/python2.7/site-packages/requests/api.py", line 53, in request
    return session.request(method=method, url=url, **kwargs)
  File "/Library/Frameworks/Python.framework/Versions/2.7/lib/python2.7/site-packages/requests/sessions.py", line 468, in request
    resp = self.send(prep, **send_kwargs)
  File "/Library/Frameworks/Python.framework/Versions/2.7/lib/python2.7/site-packages/requests/sessions.py", line 576, in send
    r = adapter.send(request, **kwargs)
  File "/Library/Frameworks/Python.framework/Versions/2.7/lib/python2.7/site-packages/requests/adapters.py", line 437, in send
    raise ConnectionError(e, request=request)
ConnectionError: HTTPConnectionPool(host='localhost', port=3000): Max retries exceeded with url: /msgs (Caused by NewConnectionError('<requests.packages.urllib3.connection.HTTPConnection object at 0x10541e4d0>: Failed to establish a new connection: [Errno 61] Connection refused',))
Tue Mar 29 10:52:27 2016
Traceback (most recent call last):
  File "/Users/linyuchen/Documents/code/Python/qq/qqsdk/qqclient.py", line 765, in run
    msg = self.getMsg()
  File "/Users/linyuchen/Documents/code/Python/qq/qqsdk/qqapi.py", line 90, in getMsg
    data = self.post_json(self.get_msgs_url)
  File "/Users/linyuchen/Documents/code/Python/qq/qqsdk/qqapi.py", line 37, in post_json
    res = requests.get(url, kwargs)
  File "/Library/Frameworks/Python.framework/Versions/2.7/lib/python2.7/site-packages/requests/api.py", line 67, in get
    return request('get', url, params=params, **kwargs)
  File "/Library/Frameworks/Python.framework/Versions/2.7/lib/python2.7/site-packages/requests/api.py", line 53, in request
    return session.request(method=method, url=url, **kwargs)
  File "/Library/Frameworks/Python.framework/Versions/2.7/lib/python2.7/site-packages/requests/sessions.py", line 468, in request
    resp = self.send(prep, **send_kwargs)
  File "/Library/Frameworks/Python.framework/Versions/2.7/lib/python2.7/site-packages/requests/sessions.py", line 576, in send
    r = adapter.send(request, **kwargs)
  File "/Library/Frameworks/Python.framework/Versions/2.7/lib/python2.7/site-packages/requests/adapters.py", line 437, in send
    raise ConnectionError(e, request=request)
ConnectionError: HTTPConnectionPool(host='localhost', port=3000): Max retries exceeded with url: /msgs (Caused by NewConnectionError('<requests.packages.urllib3.connection.HTTPConnection object at 0x10541e350>: Failed to establish a new connection: [Errno 61] Connection refused',))
Tue Mar 29 10:52:27 2016
Traceback (most recent call last):
  File "/Users/linyuchen/Documents/code/Python/qq/qqsdk/qqclient.py", line 765, in run
    msg = self.getMsg()
  File "/Users/linyuchen/Documents/code/Python/qq/qqsdk/qqapi.py", line 90, in getMsg
    data = self.post_json(self.get_msgs_url)
  File "/Users/linyuchen/Documents/code/Python/qq/qqsdk/qqapi.py", line 37, in post_json
    res = requests.get(url, kwargs)
  File "/Library/Frameworks/Python.framework/Versions/2.7/lib/python2.7/site-packages/requests/api.py", line 67, in get
    return request('get', url, params=params, **kwargs)
  File "/Library/Frameworks/Python.framework/Versions/2.7/lib/python2.7/site-packages/requests/api.py", line 53, in request
    return session.request(method=method, url=url, **kwargs)
  File "/Library/Frameworks/Python.framework/Versions/2.7/lib/python2.7/site-packages/requests/sessions.py", line 468, in request
    resp = self.send(prep, **send_kwargs)
  File "/Library/Frameworks/Python.framework/Versions/2.7/lib/python2.7/site-packages/requests/sessions.py", line 576, in send
    r = adapter.send(request, **kwargs)
  File "/Library/Frameworks/Python.framework/Versions/2.7/lib/python2.7/site-packages/requests/adapters.py", line 437, in send
    raise ConnectionError(e, request=request)
ConnectionError: HTTPConnectionPool(host='localhost', port=3000): Max retries exceeded with url: /msgs (Caused by NewConnectionError('<requests.packages.urllib3.connection.HTTPConnection object at 0x10541ec10>: Failed to establish a new connection: [Errno 61] Connection refused',))
Tue Mar 29 10:52:27 2016
Traceback (most recent call last):
  File "/Users/linyuchen/Documents/code/Python/qq/qqsdk/qqclient.py", line 765, in run
    msg = self.getMsg()
  File "/Users/linyuchen/Documents/code/Python/qq/qqsdk/qqapi.py", line 90, in getMsg
    data = self.post_json(self.get_msgs_url)
  File "/Users/linyuchen/Documents/code/Python/qq/qqsdk/qqapi.py", line 37, in post_json
    res = requests.get(url, kwargs)
  File "/Library/Frameworks/Python.framework/Versions/2.7/lib/python2.7/site-packages/requests/api.py", line 67, in get
    return request('get', url, params=params, **kwargs)
  File "/Library/Frameworks/Python.framework/Versions/2.7/lib/python2.7/site-packages/requests/api.py", line 53, in request
    return session.request(method=method, url=url, **kwargs)
  File "/Library/Frameworks/Python.framework/Versions/2.7/lib/python2.7/site-packages/requests/sessions.py", line 468, in request
    resp = self.send(prep, **send_kwargs)
  File "/Library/Frameworks/Python.framework/Versions/2.7/lib/python2.7/site-packages/requests/sessions.py", line 576, in send
    r = adapter.send(request, **kwargs)
  File "/Library/Frameworks/Python.framework/Versions/2.7/lib/python2.7/site-packages/requests/adapters.py", line 437, in send
    raise ConnectionError(e, request=request)
ConnectionError: HTTPConnectionPool(host='localhost', port=3000): Max retries exceeded with url: /msgs (Caused by NewConnectionError('<requests.packages.urllib3.connection.HTTPConnection object at 0x10541e410>: Failed to establish a new connection: [Errno 61] Connection refused',))
Tue Mar 29 10:52:27 2016
Traceback (most recent call last):
  File "/Users/linyuchen/Documents/code/Python/qq/qqsdk/qqclient.py", line 765, in run
    msg = self.getMsg()
  File "/Users/linyuchen/Documents/code/Python/qq/qqsdk/qqapi.py", line 90, in getMsg
    data = self.post_json(self.get_msgs_url)
  File "/Users/linyuchen/Documents/code/Python/qq/qqsdk/qqapi.py", line 37, in post_json
    res = requests.get(url, kwargs)
  File "/Library/Frameworks/Python.framework/Versions/2.7/lib/python2.7/site-packages/requests/api.py", line 67, in get
    return request('get', url, params=params, **kwargs)
  File "/Library/Frameworks/Python.framework/Versions/2.7/lib/python2.7/site-packages/requests/api.py", line 53, in request
    return session.request(method=method, url=url, **kwargs)
  File "/Library/Frameworks/Python.framework/Versions/2.7/lib/python2.7/site-packages/requests/sessions.py", line 468, in request
    resp = self.send(prep, **send_kwargs)
  File "/Library/Frameworks/Python.framework/Versions/2.7/lib/python2.7/site-packages/requests/sessions.py", line 576, in send
    r = adapter.send(request, **kwargs)
  File "/Library/Frameworks/Python.framework/Versions/2.7/lib/python2.7/site-packages/requests/adapters.py", line 437, in send
    raise ConnectionError(e, request=request)
ConnectionError: HTTPConnectionPool(host='localhost', port=3000): Max retries exceeded with url: /msgs (Caused by NewConnectionError('<requests.packages.urllib3.connection.HTTPConnection object at 0x10541e050>: Failed to establish a new connection: [Errno 61] Connection refused',))
Tue Mar 29 10:52:27 2016
Traceback (most recent call last):
  File "/Users/linyuchen/Documents/code/Python/qq/qqsdk/qqclient.py", line 765, in run
    msg = self.getMsg()
  File "/Users/linyuchen/Documents/code/Python/qq/qqsdk/qqapi.py", line 90, in getMsg
    data = self.post_json(self.get_msgs_url)
  File "/Users/linyuchen/Documents/code/Python/qq/qqsdk/qqapi.py", line 37, in post_json
    res = requests.get(url, kwargs)
  File "/Library/Frameworks/Python.framework/Versions/2.7/lib/python2.7/site-packages/requests/api.py", line 67, in get
    return request('get', url, params=params, **kwargs)
  File "/Library/Frameworks/Python.framework/Versions/2.7/lib/python2.7/site-packages/requests/api.py", line 53, in request
    return session.request(method=method, url=url, **kwargs)
  File "/Library/Frameworks/Python.framework/Versions/2.7/lib/python2.7/site-packages/requests/sessions.py", line 468, in request
    resp = self.send(prep, **send_kwargs)
  File "/Library/Frameworks/Python.framework/Versions/2.7/lib/python2.7/site-packages/requests/sessions.py", line 576, in send
    r = adapter.send(request, **kwargs)
  File "/Library/Frameworks/Python.framework/Versions/2.7/lib/python2.7/site-packages/requests/adapters.py", line 437, in send
    raise ConnectionError(e, request=request)
ConnectionError: HTTPConnectionPool(host='localhost', port=3000): Max retries exceeded with url: /msgs (Caused by NewConnectionError('<requests.packages.urllib3.connection.HTTPConnection object at 0x10541e490>: Failed to establish a new connection: [Errno 61] Connection refused',))
Tue Mar 29 10:52:27 2016
Traceback (most recent call last):
  File "/Users/linyuchen/Documents/code/Python/qq/qqsdk/qqclient.py", line 765, in run
    msg = self.getMsg()
  File "/Users/linyuchen/Documents/code/Python/qq/qqsdk/qqapi.py", line 90, in getMsg
    data = self.post_json(self.get_msgs_url)
  File "/Users/linyuchen/Documents/code/Python/qq/qqsdk/qqapi.py", line 37, in post_json
    res = requests.get(url, kwargs)
  File "/Library/Frameworks/Python.framework/Versions/2.7/lib/python2.7/site-packages/requests/api.py", line 67, in get
    return request('get', url, params=params, **kwargs)
  File "/Library/Frameworks/Python.framework/Versions/2.7/lib/python2.7/site-packages/requests/api.py", line 53, in request
    return session.request(method=method, url=url, **kwargs)
  File "/Library/Frameworks/Python.framework/Versions/2.7/lib/python2.7/site-packages/requests/sessions.py", line 468, in request
    resp = self.send(prep, **send_kwargs)
  File "/Library/Frameworks/Python.framework/Versions/2.7/lib/python2.7/site-packages/requests/sessions.py", line 576, in send
    r = adapter.send(request, **kwargs)
  File "/Library/Frameworks/Python.framework/Versions/2.7/lib/python2.7/site-packages/requests/adapters.py", line 437, in send
    raise ConnectionError(e, request=request)
ConnectionError: HTTPConnectionPool(host='localhost', port=3000): Max retries exceeded with url: /msgs (Caused by NewConnectionError('<requests.packages.urllib3.connection.HTTPConnection object at 0x10541e8d0>: Failed to establish a new connection: [Errno 61] Connection refused',))
Tue Mar 29 10:52:28 2016
Traceback (most recent call last):
  File "/Users/linyuchen/Documents/code/Python/qq/qqsdk/qqclient.py", line 765, in run
    msg = self.getMsg()
  File "/Users/linyuchen/Documents/code/Python/qq/qqsdk/qqapi.py", line 90, in getMsg
    data = self.post_json(self.get_msgs_url)
  File "/Users/linyuchen/Documents/code/Python/qq/qqsdk/qqapi.py", line 37, in post_json
    res = requests.get(url, kwargs)
  File "/Library/Frameworks/Python.framework/Versions/2.7/lib/python2.7/site-packages/requests/api.py", line 67, in get
    return request('get', url, params=params, **kwargs)
  File "/Library/Frameworks/Python.framework/Versions/2.7/lib/python2.7/site-packages/requests/api.py", line 53, in request
    return session.request(method=method, url=url, **kwargs)
  File "/Library/Frameworks/Python.framework/Versions/2.7/lib/python2.7/site-packages/requests/sessions.py", line 468, in request
    resp = self.send(prep, **send_kwargs)
  File "/Library/Frameworks/Python.framework/Versions/2.7/lib/python2.7/site-packages/requests/sessions.py", line 576, in send
    r = adapter.send(request, **kwargs)
  File "/Library/Frameworks/Python.framework/Versions/2.7/lib/python2.7/site-packages/requests/adapters.py", line 437, in send
    raise ConnectionError(e, request=request)
ConnectionError: HTTPConnectionPool(host='localhost', port=3000): Max retries exceeded with url: /msgs (Caused by NewConnectionError('<requests.packages.urllib3.connection.HTTPConnection object at 0x10541e110>: Failed to establish a new connection: [Errno 61] Connection refused',))
Tue Mar 29 10:52:28 2016
Traceback (most recent call last):
  File "/Users/linyuchen/Documents/code/Python/qq/qqsdk/qqclient.py", line 765, in run
    msg = self.getMsg()
  File "/Users/linyuchen/Documents/code/Python/qq/qqsdk/qqapi.py", line 90, in getMsg
    data = self.post_json(self.get_msgs_url)
  File "/Users/linyuchen/Documents/code/Python/qq/qqsdk/qqapi.py", line 37, in post_json
    res = requests.get(url, kwargs)
  File "/Library/Frameworks/Python.framework/Versions/2.7/lib/python2.7/site-packages/requests/api.py", line 67, in get
    return request('get', url, params=params, **kwargs)
  File "/Library/Frameworks/Python.framework/Versions/2.7/lib/python2.7/site-packages/requests/api.py", line 53, in request
    return session.request(method=method, url=url, **kwargs)
  File "/Library/Frameworks/Python.framework/Versions/2.7/lib/python2.7/site-packages/requests/sessions.py", line 468, in request
    resp = self.send(prep, **send_kwargs)
  File "/Library/Frameworks/Python.framework/Versions/2.7/lib/python2.7/site-packages/requests/sessions.py", line 576, in send
    r = adapter.send(request, **kwargs)
  File "/Library/Frameworks/Python.framework/Versions/2.7/lib/python2.7/site-packages/requests/adapters.py", line 437, in send
    raise ConnectionError(e, request=request)
ConnectionError: HTTPConnectionPool(host='localhost', port=3000): Max retries exceeded with url: /msgs (Caused by NewConnectionError('<requests.packages.urllib3.connection.HTTPConnection object at 0x10541ee10>: Failed to establish a new connection: [Errno 61] Connection refused',))
Tue Mar 29 10:52:28 2016
Traceback (most recent call last):
  File "/Users/linyuchen/Documents/code/Python/qq/qqsdk/qqclient.py", line 765, in run
    msg = self.getMsg()
  File "/Users/linyuchen/Documents/code/Python/qq/qqsdk/qqapi.py", line 90, in getMsg
    data = self.post_json(self.get_msgs_url)
  File "/Users/linyuchen/Documents/code/Python/qq/qqsdk/qqapi.py", line 37, in post_json
    res = requests.get(url, kwargs)
  File "/Library/Frameworks/Python.framework/Versions/2.7/lib/python2.7/site-packages/requests/api.py", line 67, in get
    return request('get', url, params=params, **kwargs)
  File "/Library/Frameworks/Python.framework/Versions/2.7/lib/python2.7/site-packages/requests/api.py", line 53, in request
    return session.request(method=method, url=url, **kwargs)
  File "/Library/Frameworks/Python.framework/Versions/2.7/lib/python2.7/site-packages/requests/sessions.py", line 468, in request
    resp = self.send(prep, **send_kwargs)
  File "/Library/Frameworks/Python.framework/Versions/2.7/lib/python2.7/site-packages/requests/sessions.py", line 576, in send
    r = adapter.send(request, **kwargs)
  File "/Library/Frameworks/Python.framework/Versions/2.7/lib/python2.7/site-packages/requests/adapters.py", line 437, in send
    raise ConnectionError(e, request=request)
ConnectionError: HTTPConnectionPool(host='localhost', port=3000): Max retries exceeded with url: /msgs (Caused by NewConnectionError('<requests.packages.urllib3.connection.HTTPConnection object at 0x10541ee90>: Failed to establish a new connection: [Errno 61] Connection refused',))
Tue Mar 29 10:52:28 2016
Traceback (most recent call last):
  File "/Users/linyuchen/Documents/code/Python/qq/qqsdk/qqclient.py", line 765, in run
    msg = self.getMsg()
  File "/Users/linyuchen/Documents/code/Python/qq/qqsdk/qqapi.py", line 90, in getMsg
    data = self.post_json(self.get_msgs_url)
  File "/Users/linyuchen/Documents/code/Python/qq/qqsdk/qqapi.py", line 37, in post_json
    res = requests.get(url, kwargs)
  File "/Library/Frameworks/Python.framework/Versions/2.7/lib/python2.7/site-packages/requests/api.py", line 67, in get
    return request('get', url, params=params, **kwargs)
  File "/Library/Frameworks/Python.framework/Versions/2.7/lib/python2.7/site-packages/requests/api.py", line 53, in request
    return session.request(method=method, url=url, **kwargs)
  File "/Library/Frameworks/Python.framework/Versions/2.7/lib/python2.7/site-packages/requests/sessions.py", line 468, in request
    resp = self.send(prep, **send_kwargs)
  File "/Library/Frameworks/Python.framework/Versions/2.7/lib/python2.7/site-packages/requests/sessions.py", line 576, in send
    r = adapter.send(request, **kwargs)
  File "/Library/Frameworks/Python.framework/Versions/2.7/lib/python2.7/site-packages/requests/adapters.py", line 437, in send
    raise ConnectionError(e, request=request)
ConnectionError: HTTPConnectionPool(host='localhost', port=3000): Max retries exceeded with url: /msgs (Caused by NewConnectionError('<requests.packages.urllib3.connection.HTTPConnection object at 0x10541e710>: Failed to establish a new connection: [Errno 61] Connection refused',))
Tue Mar 29 10:52:28 2016
Traceback (most recent call last):
  File "/Users/linyuchen/Documents/code/Python/qq/qqsdk/qqclient.py", line 765, in run
    msg = self.getMsg()
  File "/Users/linyuchen/Documents/code/Python/qq/qqsdk/qqapi.py", line 90, in getMsg
    data = self.post_json(self.get_msgs_url)
  File "/Users/linyuchen/Documents/code/Python/qq/qqsdk/qqapi.py", line 37, in post_json
    res = requests.get(url, kwargs)
  File "/Library/Frameworks/Python.framework/Versions/2.7/lib/python2.7/site-packages/requests/api.py", line 67, in get
    return request('get', url, params=params, **kwargs)
  File "/Library/Frameworks/Python.framework/Versions/2.7/lib/python2.7/site-packages/requests/api.py", line 53, in request
    return session.request(method=method, url=url, **kwargs)
  File "/Library/Frameworks/Python.framework/Versions/2.7/lib/python2.7/site-packages/requests/sessions.py", line 468, in request
    resp = self.send(prep, **send_kwargs)
  File "/Library/Frameworks/Python.framework/Versions/2.7/lib/python2.7/site-packages/requests/sessions.py", line 576, in send
    r = adapter.send(request, **kwargs)
  File "/Library/Frameworks/Python.framework/Versions/2.7/lib/python2.7/site-packages/requests/adapters.py", line 437, in send
    raise ConnectionError(e, request=request)
ConnectionError: HTTPConnectionPool(host='localhost', port=3000): Max retries exceeded with url: /msgs (Caused by NewConnectionError('<requests.packages.urllib3.connection.HTTPConnection object at 0x10541e190>: Failed to establish a new connection: [Errno 61] Connection refused',))
Tue Mar 29 10:52:28 2016
Traceback (most recent call last):
  File "/Users/linyuchen/Documents/code/Python/qq/qqsdk/qqclient.py", line 765, in run
    msg = self.getMsg()
  File "/Users/linyuchen/Documents/code/Python/qq/qqsdk/qqapi.py", line 90, in getMsg
    data = self.post_json(self.get_msgs_url)
  File "/Users/linyuchen/Documents/code/Python/qq/qqsdk/qqapi.py", line 37, in post_json
    res = requests.get(url, kwargs)
  File "/Library/Frameworks/Python.framework/Versions/2.7/lib/python2.7/site-packages/requests/api.py", line 67, in get
    return request('get', url, params=params, **kwargs)
  File "/Library/Frameworks/Python.framework/Versions/2.7/lib/python2.7/site-packages/requests/api.py", line 53, in request
    return session.request(method=method, url=url, **kwargs)
  File "/Library/Frameworks/Python.framework/Versions/2.7/lib/python2.7/site-packages/requests/sessions.py", line 468, in request
    resp = self.send(prep, **send_kwargs)
  File "/Library/Frameworks/Python.framework/Versions/2.7/lib/python2.7/site-packages/requests/sessions.py", line 576, in send
    r = adapter.send(request, **kwargs)
  File "/Library/Frameworks/Python.framework/Versions/2.7/lib/python2.7/site-packages/requests/adapters.py", line 437, in send
    raise ConnectionError(e, request=request)
ConnectionError: HTTPConnectionPool(host='localhost', port=3000): Max retries exceeded with url: /msgs (Caused by NewConnectionError('<requests.packages.urllib3.connection.HTTPConnection object at 0x10543e4d0>: Failed to establish a new connection: [Errno 61] Connection refused',))
Tue Mar 29 10:52:28 2016
Traceback (most recent call last):
  File "/Users/linyuchen/Documents/code/Python/qq/qqsdk/qqclient.py", line 765, in run
    msg = self.getMsg()
  File "/Users/linyuchen/Documents/code/Python/qq/qqsdk/qqapi.py", line 90, in getMsg
    data = self.post_json(self.get_msgs_url)
  File "/Users/linyuchen/Documents/code/Python/qq/qqsdk/qqapi.py", line 37, in post_json
    res = requests.get(url, kwargs)
  File "/Library/Frameworks/Python.framework/Versions/2.7/lib/python2.7/site-packages/requests/api.py", line 67, in get
    return request('get', url, params=params, **kwargs)
  File "/Library/Frameworks/Python.framework/Versions/2.7/lib/python2.7/site-packages/requests/api.py", line 53, in request
    return session.request(method=method, url=url, **kwargs)
  File "/Library/Frameworks/Python.framework/Versions/2.7/lib/python2.7/site-packages/requests/sessions.py", line 468, in request
    resp = self.send(prep, **send_kwargs)
  File "/Library/Frameworks/Python.framework/Versions/2.7/lib/python2.7/site-packages/requests/sessions.py", line 576, in send
    r = adapter.send(request, **kwargs)
  File "/Library/Frameworks/Python.framework/Versions/2.7/lib/python2.7/site-packages/requests/adapters.py", line 437, in send
    raise ConnectionError(e, request=request)
ConnectionError: HTTPConnectionPool(host='localhost', port=3000): Max retries exceeded with url: /msgs (Caused by NewConnectionError('<requests.packages.urllib3.connection.HTTPConnection object at 0x10543e510>: Failed to establish a new connection: [Errno 61] Connection refused',))
Tue Mar 29 10:52:28 2016
Traceback (most recent call last):
  File "/Users/linyuchen/Documents/code/Python/qq/qqsdk/qqclient.py", line 765, in run
    msg = self.getMsg()
  File "/Users/linyuchen/Documents/code/Python/qq/qqsdk/qqapi.py", line 90, in getMsg
    data = self.post_json(self.get_msgs_url)
  File "/Users/linyuchen/Documents/code/Python/qq/qqsdk/qqapi.py", line 37, in post_json
    res = requests.get(url, kwargs)
  File "/Library/Frameworks/Python.framework/Versions/2.7/lib/python2.7/site-packages/requests/api.py", line 67, in get
    return request('get', url, params=params, **kwargs)
  File "/Library/Frameworks/Python.framework/Versions/2.7/lib/python2.7/site-packages/requests/api.py", line 53, in request
    return session.request(method=method, url=url, **kwargs)
  File "/Library/Frameworks/Python.framework/Versions/2.7/lib/python2.7/site-packages/requests/sessions.py", line 468, in request
    resp = self.send(prep, **send_kwargs)
  File "/Library/Frameworks/Python.framework/Versions/2.7/lib/python2.7/site-packages/requests/sessions.py", line 576, in send
    r = adapter.send(request, **kwargs)
  File "/Library/Frameworks/Python.framework/Versions/2.7/lib/python2.7/site-packages/requests/adapters.py", line 437, in send
    raise ConnectionError(e, request=request)
ConnectionError: HTTPConnectionPool(host='localhost', port=3000): Max retries exceeded with url: /msgs (Caused by NewConnectionError('<requests.packages.urllib3.connection.HTTPConnection object at 0x10543e590>: Failed to establish a new connection: [Errno 61] Connection refused',))
Tue Mar 29 10:52:28 2016
Traceback (most recent call last):
  File "/Users/linyuchen/Documents/code/Python/qq/qqsdk/qqclient.py", line 765, in run
    msg = self.getMsg()
  File "/Users/linyuchen/Documents/code/Python/qq/qqsdk/qqapi.py", line 90, in getMsg
    data = self.post_json(self.get_msgs_url)
  File "/Users/linyuchen/Documents/code/Python/qq/qqsdk/qqapi.py", line 37, in post_json
    res = requests.get(url, kwargs)
  File "/Library/Frameworks/Python.framework/Versions/2.7/lib/python2.7/site-packages/requests/api.py", line 67, in get
    return request('get', url, params=params, **kwargs)
  File "/Library/Frameworks/Python.framework/Versions/2.7/lib/python2.7/site-packages/requests/api.py", line 53, in request
    return session.request(method=method, url=url, **kwargs)
  File "/Library/Frameworks/Python.framework/Versions/2.7/lib/python2.7/site-packages/requests/sessions.py", line 468, in request
    resp = self.send(prep, **send_kwargs)
  File "/Library/Frameworks/Python.framework/Versions/2.7/lib/python2.7/site-packages/requests/sessions.py", line 576, in send
    r = adapter.send(request, **kwargs)
  File "/Library/Frameworks/Python.framework/Versions/2.7/lib/python2.7/site-packages/requests/adapters.py", line 437, in send
    raise ConnectionError(e, request=request)
ConnectionError: HTTPConnectionPool(host='localhost', port=3000): Max retries exceeded with url: /msgs (Caused by NewConnectionError('<requests.packages.urllib3.connection.HTTPConnection object at 0x10543e690>: Failed to establish a new connection: [Errno 61] Connection refused',))
Tue Mar 29 10:52:29 2016
Traceback (most recent call last):
  File "/Users/linyuchen/Documents/code/Python/qq/qqsdk/qqclient.py", line 765, in run
    msg = self.getMsg()
  File "/Users/linyuchen/Documents/code/Python/qq/qqsdk/qqapi.py", line 90, in getMsg
    data = self.post_json(self.get_msgs_url)
  File "/Users/linyuchen/Documents/code/Python/qq/qqsdk/qqapi.py", line 37, in post_json
    res = requests.get(url, kwargs)
  File "/Library/Frameworks/Python.framework/Versions/2.7/lib/python2.7/site-packages/requests/api.py", line 67, in get
    return request('get', url, params=params, **kwargs)
  File "/Library/Frameworks/Python.framework/Versions/2.7/lib/python2.7/site-packages/requests/api.py", line 53, in request
    return session.request(method=method, url=url, **kwargs)
  File "/Library/Frameworks/Python.framework/Versions/2.7/lib/python2.7/site-packages/requests/sessions.py", line 468, in request
    resp = self.send(prep, **send_kwargs)
  File "/Library/Frameworks/Python.framework/Versions/2.7/lib/python2.7/site-packages/requests/sessions.py", line 576, in send
    r = adapter.send(request, **kwargs)
  File "/Library/Frameworks/Python.framework/Versions/2.7/lib/python2.7/site-packages/requests/adapters.py", line 437, in send
    raise ConnectionError(e, request=request)
ConnectionError: HTTPConnectionPool(host='localhost', port=3000): Max retries exceeded with url: /msgs (Caused by NewConnectionError('<requests.packages.urllib3.connection.HTTPConnection object at 0x10543e710>: Failed to establish a new connection: [Errno 61] Connection refused',))
Tue Mar 29 10:52:29 2016
Traceback (most recent call last):
  File "/Users/linyuchen/Documents/code/Python/qq/qqsdk/qqclient.py", line 765, in run
    msg = self.getMsg()
  File "/Users/linyuchen/Documents/code/Python/qq/qqsdk/qqapi.py", line 90, in getMsg
    data = self.post_json(self.get_msgs_url)
  File "/Users/linyuchen/Documents/code/Python/qq/qqsdk/qqapi.py", line 37, in post_json
    res = requests.get(url, kwargs)
  File "/Library/Frameworks/Python.framework/Versions/2.7/lib/python2.7/site-packages/requests/api.py", line 67, in get
    return request('get', url, params=params, **kwargs)
  File "/Library/Frameworks/Python.framework/Versions/2.7/lib/python2.7/site-packages/requests/api.py", line 53, in request
    return session.request(method=method, url=url, **kwargs)
  File "/Library/Frameworks/Python.framework/Versions/2.7/lib/python2.7/site-packages/requests/sessions.py", line 468, in request
    resp = self.send(prep, **send_kwargs)
  File "/Library/Frameworks/Python.framework/Versions/2.7/lib/python2.7/site-packages/requests/sessions.py", line 576, in send
    r = adapter.send(request, **kwargs)
  File "/Library/Frameworks/Python.framework/Versions/2.7/lib/python2.7/site-packages/requests/adapters.py", line 437, in send
    raise ConnectionError(e, request=request)
ConnectionError: HTTPConnectionPool(host='localhost', port=3000): Max retries exceeded with url: /msgs (Caused by NewConnectionError('<requests.packages.urllib3.connection.HTTPConnection object at 0x10543e790>: Failed to establish a new connection: [Errno 61] Connection refused',))
Tue Mar 29 10:52:29 2016
Traceback (most recent call last):
  File "/Users/linyuchen/Documents/code/Python/qq/qqsdk/qqclient.py", line 765, in run
    msg = self.getMsg()
  File "/Users/linyuchen/Documents/code/Python/qq/qqsdk/qqapi.py", line 90, in getMsg
    data = self.post_json(self.get_msgs_url)
  File "/Users/linyuchen/Documents/code/Python/qq/qqsdk/qqapi.py", line 37, in post_json
    res = requests.get(url, kwargs)
  File "/Library/Frameworks/Python.framework/Versions/2.7/lib/python2.7/site-packages/requests/api.py", line 67, in get
    return request('get', url, params=params, **kwargs)
  File "/Library/Frameworks/Python.framework/Versions/2.7/lib/python2.7/site-packages/requests/api.py", line 53, in request
    return session.request(method=method, url=url, **kwargs)
  File "/Library/Frameworks/Python.framework/Versions/2.7/lib/python2.7/site-packages/requests/sessions.py", line 468, in request
    resp = self.send(prep, **send_kwargs)
  File "/Library/Frameworks/Python.framework/Versions/2.7/lib/python2.7/site-packages/requests/sessions.py", line 576, in send
    r = adapter.send(request, **kwargs)
  File "/Library/Frameworks/Python.framework/Versions/2.7/lib/python2.7/site-packages/requests/adapters.py", line 437, in send
    raise ConnectionError(e, request=request)
ConnectionError: HTTPConnectionPool(host='localhost', port=3000): Max retries exceeded with url: /msgs (Caused by NewConnectionError('<requests.packages.urllib3.connection.HTTPConnection object at 0x10543e810>: Failed to establish a new connection: [Errno 61] Connection refused',))
Tue Mar 29 10:52:29 2016
Traceback (most recent call last):
  File "/Users/linyuchen/Documents/code/Python/qq/qqsdk/qqclient.py", line 765, in run
    msg = self.getMsg()
  File "/Users/linyuchen/Documents/code/Python/qq/qqsdk/qqapi.py", line 90, in getMsg
    data = self.post_json(self.get_msgs_url)
  File "/Users/linyuchen/Documents/code/Python/qq/qqsdk/qqapi.py", line 37, in post_json
    res = requests.get(url, kwargs)
  File "/Library/Frameworks/Python.framework/Versions/2.7/lib/python2.7/site-packages/requests/api.py", line 67, in get
    return request('get', url, params=params, **kwargs)
  File "/Library/Frameworks/Python.framework/Versions/2.7/lib/python2.7/site-packages/requests/api.py", line 53, in request
    return session.request(method=method, url=url, **kwargs)
  File "/Library/Frameworks/Python.framework/Versions/2.7/lib/python2.7/site-packages/requests/sessions.py", line 468, in request
    resp = self.send(prep, **send_kwargs)
  File "/Library/Frameworks/Python.framework/Versions/2.7/lib/python2.7/site-packages/requests/sessions.py", line 576, in send
    r = adapter.send(request, **kwargs)
  File "/Library/Frameworks/Python.framework/Versions/2.7/lib/python2.7/site-packages/requests/adapters.py", line 437, in send
    raise ConnectionError(e, request=request)
ConnectionError: HTTPConnectionPool(host='localhost', port=3000): Max retries exceeded with url: /msgs (Caused by NewConnectionError('<requests.packages.urllib3.connection.HTTPConnection object at 0x10543e890>: Failed to establish a new connection: [Errno 61] Connection refused',))
Tue Mar 29 10:52:29 2016
Traceback (most recent call last):
  File "/Users/linyuchen/Documents/code/Python/qq/qqsdk/qqclient.py", line 765, in run
    msg = self.getMsg()
  File "/Users/linyuchen/Documents/code/Python/qq/qqsdk/qqapi.py", line 90, in getMsg
    data = self.post_json(self.get_msgs_url)
  File "/Users/linyuchen/Documents/code/Python/qq/qqsdk/qqapi.py", line 37, in post_json
    res = requests.get(url, kwargs)
  File "/Library/Frameworks/Python.framework/Versions/2.7/lib/python2.7/site-packages/requests/api.py", line 67, in get
    return request('get', url, params=params, **kwargs)
  File "/Library/Frameworks/Python.framework/Versions/2.7/lib/python2.7/site-packages/requests/api.py", line 53, in request
    return session.request(method=method, url=url, **kwargs)
  File "/Library/Frameworks/Python.framework/Versions/2.7/lib/python2.7/site-packages/requests/sessions.py", line 468, in request
    resp = self.send(prep, **send_kwargs)
  File "/Library/Frameworks/Python.framework/Versions/2.7/lib/python2.7/site-packages/requests/sessions.py", line 576, in send
    r = adapter.send(request, **kwargs)
  File "/Library/Frameworks/Python.framework/Versions/2.7/lib/python2.7/site-packages/requests/adapters.py", line 437, in send
    raise ConnectionError(e, request=request)
ConnectionError: HTTPConnectionPool(host='localhost', port=3000): Max retries exceeded with url: /msgs (Caused by NewConnectionError('<requests.packages.urllib3.connection.HTTPConnection object at 0x10543e590>: Failed to establish a new connection: [Errno 61] Connection refused',))
Tue Mar 29 10:52:29 2016
Traceback (most recent call last):
  File "/Users/linyuchen/Documents/code/Python/qq/qqsdk/qqclient.py", line 765, in run
    msg = self.getMsg()
  File "/Users/linyuchen/Documents/code/Python/qq/qqsdk/qqapi.py", line 90, in getMsg
    data = self.post_json(self.get_msgs_url)
  File "/Users/linyuchen/Documents/code/Python/qq/qqsdk/qqapi.py", line 37, in post_json
    res = requests.get(url, kwargs)
  File "/Library/Frameworks/Python.framework/Versions/2.7/lib/python2.7/site-packages/requests/api.py", line 67, in get
    return request('get', url, params=params, **kwargs)
  File "/Library/Frameworks/Python.framework/Versions/2.7/lib/python2.7/site-packages/requests/api.py", line 53, in request
    return session.request(method=method, url=url, **kwargs)
  File "/Library/Frameworks/Python.framework/Versions/2.7/lib/python2.7/site-packages/requests/sessions.py", line 468, in request
    resp = self.send(prep, **send_kwargs)
  File "/Library/Frameworks/Python.framework/Versions/2.7/lib/python2.7/site-packages/requests/sessions.py", line 576, in send
    r = adapter.send(request, **kwargs)
  File "/Library/Frameworks/Python.framework/Versions/2.7/lib/python2.7/site-packages/requests/adapters.py", line 437, in send
    raise ConnectionError(e, request=request)
ConnectionError: HTTPConnectionPool(host='localhost', port=3000): Max retries exceeded with url: /msgs (Caused by NewConnectionError('<requests.packages.urllib3.connection.HTTPConnection object at 0x10543e9d0>: Failed to establish a new connection: [Errno 61] Connection refused',))
Tue Mar 29 10:52:29 2016
Traceback (most recent call last):
  File "/Users/linyuchen/Documents/code/Python/qq/qqsdk/qqclient.py", line 765, in run
    msg = self.getMsg()
  File "/Users/linyuchen/Documents/code/Python/qq/qqsdk/qqapi.py", line 90, in getMsg
    data = self.post_json(self.get_msgs_url)
  File "/Users/linyuchen/Documents/code/Python/qq/qqsdk/qqapi.py", line 37, in post_json
    res = requests.get(url, kwargs)
  File "/Library/Frameworks/Python.framework/Versions/2.7/lib/python2.7/site-packages/requests/api.py", line 67, in get
    return request('get', url, params=params, **kwargs)
  File "/Library/Frameworks/Python.framework/Versions/2.7/lib/python2.7/site-packages/requests/api.py", line 53, in request
    return session.request(method=method, url=url, **kwargs)
  File "/Library/Frameworks/Python.framework/Versions/2.7/lib/python2.7/site-packages/requests/sessions.py", line 468, in request
    resp = self.send(prep, **send_kwargs)
  File "/Library/Frameworks/Python.framework/Versions/2.7/lib/python2.7/site-packages/requests/sessions.py", line 576, in send
    r = adapter.send(request, **kwargs)
  File "/Library/Frameworks/Python.framework/Versions/2.7/lib/python2.7/site-packages/requests/adapters.py", line 437, in send
    raise ConnectionError(e, request=request)
ConnectionError: HTTPConnectionPool(host='localhost', port=3000): Max retries exceeded with url: /msgs (Caused by NewConnectionError('<requests.packages.urllib3.connection.HTTPConnection object at 0x10543e990>: Failed to establish a new connection: [Errno 61] Connection refused',))
Tue Mar 29 10:52:29 2016
Traceback (most recent call last):
  File "/Users/linyuchen/Documents/code/Python/qq/qqsdk/qqclient.py", line 765, in run
    msg = self.getMsg()
  File "/Users/linyuchen/Documents/code/Python/qq/qqsdk/qqapi.py", line 90, in getMsg
    data = self.post_json(self.get_msgs_url)
  File "/Users/linyuchen/Documents/code/Python/qq/qqsdk/qqapi.py", line 37, in post_json
    res = requests.get(url, kwargs)
  File "/Library/Frameworks/Python.framework/Versions/2.7/lib/python2.7/site-packages/requests/api.py", line 67, in get
    return request('get', url, params=params, **kwargs)
  File "/Library/Frameworks/Python.framework/Versions/2.7/lib/python2.7/site-packages/requests/api.py", line 53, in request
    return session.request(method=method, url=url, **kwargs)
  File "/Library/Frameworks/Python.framework/Versions/2.7/lib/python2.7/site-packages/requests/sessions.py", line 468, in request
    resp = self.send(prep, **send_kwargs)
  File "/Library/Frameworks/Python.framework/Versions/2.7/lib/python2.7/site-packages/requests/sessions.py", line 576, in send
    r = adapter.send(request, **kwargs)
  File "/Library/Frameworks/Python.framework/Versions/2.7/lib/python2.7/site-packages/requests/adapters.py", line 437, in send
    raise ConnectionError(e, request=request)
ConnectionError: HTTPConnectionPool(host='localhost', port=3000): Max retries exceeded with url: /msgs (Caused by NewConnectionError('<requests.packages.urllib3.connection.HTTPConnection object at 0x10543ea50>: Failed to establish a new connection: [Errno 61] Connection refused',))
Tue Mar 29 10:52:29 2016
Traceback (most recent call last):
  File "/Users/linyuchen/Documents/code/Python/qq/qqsdk/qqclient.py", line 765, in run
    msg = self.getMsg()
  File "/Users/linyuchen/Documents/code/Python/qq/qqsdk/qqapi.py", line 90, in getMsg
    data = self.post_json(self.get_msgs_url)
  File "/Users/linyuchen/Documents/code/Python/qq/qqsdk/qqapi.py", line 37, in post_json
    res = requests.get(url, kwargs)
  File "/Library/Frameworks/Python.framework/Versions/2.7/lib/python2.7/site-packages/requests/api.py", line 67, in get
    return request('get', url, params=params, **kwargs)
  File "/Library/Frameworks/Python.framework/Versions/2.7/lib/python2.7/site-packages/requests/api.py", line 53, in request
    return session.request(method=method, url=url, **kwargs)
  File "/Library/Frameworks/Python.framework/Versions/2.7/lib/python2.7/site-packages/requests/sessions.py", line 468, in request
    resp = self.send(prep, **send_kwargs)
  File "/Library/Frameworks/Python.framework/Versions/2.7/lib/python2.7/site-packages/requests/sessions.py", line 576, in send
    r = adapter.send(request, **kwargs)
  File "/Library/Frameworks/Python.framework/Versions/2.7/lib/python2.7/site-packages/requests/adapters.py", line 437, in send
    raise ConnectionError(e, request=request)
ConnectionError: HTTPConnectionPool(host='localhost', port=3000): Max retries exceeded with url: /msgs (Caused by NewConnectionError('<requests.packages.urllib3.connection.HTTPConnection object at 0x10543ead0>: Failed to establish a new connection: [Errno 61] Connection refused',))
Tue Mar 29 10:52:29 2016
Traceback (most recent call last):
  File "/Users/linyuchen/Documents/code/Python/qq/qqsdk/qqclient.py", line 765, in run
    msg = self.getMsg()
  File "/Users/linyuchen/Documents/code/Python/qq/qqsdk/qqapi.py", line 90, in getMsg
    data = self.post_json(self.get_msgs_url)
  File "/Users/linyuchen/Documents/code/Python/qq/qqsdk/qqapi.py", line 37, in post_json
    res = requests.get(url, kwargs)
  File "/Library/Frameworks/Python.framework/Versions/2.7/lib/python2.7/site-packages/requests/api.py", line 67, in get
    return request('get', url, params=params, **kwargs)
  File "/Library/Frameworks/Python.framework/Versions/2.7/lib/python2.7/site-packages/requests/api.py", line 53, in request
    return session.request(method=method, url=url, **kwargs)
  File "/Library/Frameworks/Python.framework/Versions/2.7/lib/python2.7/site-packages/requests/sessions.py", line 468, in request
    resp = self.send(prep, **send_kwargs)
  File "/Library/Frameworks/Python.framework/Versions/2.7/lib/python2.7/site-packages/requests/sessions.py", line 576, in send
    r = adapter.send(request, **kwargs)
  File "/Library/Frameworks/Python.framework/Versions/2.7/lib/python2.7/site-packages/requests/adapters.py", line 437, in send
    raise ConnectionError(e, request=request)
ConnectionError: HTTPConnectionPool(host='localhost', port=3000): Max retries exceeded with url: /msgs (Caused by NewConnectionError('<requests.packages.urllib3.connection.HTTPConnection object at 0x10543eb50>: Failed to establish a new connection: [Errno 61] Connection refused',))
Tue Mar 29 10:52:30 2016
Traceback (most recent call last):
  File "/Users/linyuchen/Documents/code/Python/qq/qqsdk/qqclient.py", line 765, in run
    msg = self.getMsg()
  File "/Users/linyuchen/Documents/code/Python/qq/qqsdk/qqapi.py", line 90, in getMsg
    data = self.post_json(self.get_msgs_url)
  File "/Users/linyuchen/Documents/code/Python/qq/qqsdk/qqapi.py", line 37, in post_json
    res = requests.get(url, kwargs)
  File "/Library/Frameworks/Python.framework/Versions/2.7/lib/python2.7/site-packages/requests/api.py", line 67, in get
    return request('get', url, params=params, **kwargs)
  File "/Library/Frameworks/Python.framework/Versions/2.7/lib/python2.7/site-packages/requests/api.py", line 53, in request
    return session.request(method=method, url=url, **kwargs)
  File "/Library/Frameworks/Python.framework/Versions/2.7/lib/python2.7/site-packages/requests/sessions.py", line 468, in request
    resp = self.send(prep, **send_kwargs)
  File "/Library/Frameworks/Python.framework/Versions/2.7/lib/python2.7/site-packages/requests/sessions.py", line 576, in send
    r = adapter.send(request, **kwargs)
  File "/Library/Frameworks/Python.framework/Versions/2.7/lib/python2.7/site-packages/requests/adapters.py", line 437, in send
    raise ConnectionError(e, request=request)
ConnectionError: HTTPConnectionPool(host='localhost', port=3000): Max retries exceeded with url: /msgs (Caused by NewConnectionError('<requests.packages.urllib3.connection.HTTPConnection object at 0x10543ebd0>: Failed to establish a new connection: [Errno 61] Connection refused',))
Tue Mar 29 10:52:30 2016
Traceback (most recent call last):
  File "/Users/linyuchen/Documents/code/Python/qq/qqsdk/qqclient.py", line 765, in run
    msg = self.getMsg()
  File "/Users/linyuchen/Documents/code/Python/qq/qqsdk/qqapi.py", line 90, in getMsg
    data = self.post_json(self.get_msgs_url)
  File "/Users/linyuchen/Documents/code/Python/qq/qqsdk/qqapi.py", line 37, in post_json
    res = requests.get(url, kwargs)
  File "/Library/Frameworks/Python.framework/Versions/2.7/lib/python2.7/site-packages/requests/api.py", line 67, in get
    return request('get', url, params=params, **kwargs)
  File "/Library/Frameworks/Python.framework/Versions/2.7/lib/python2.7/site-packages/requests/api.py", line 53, in request
    return session.request(method=method, url=url, **kwargs)
  File "/Library/Frameworks/Python.framework/Versions/2.7/lib/python2.7/site-packages/requests/sessions.py", line 468, in request
    resp = self.send(prep, **send_kwargs)
  File "/Library/Frameworks/Python.framework/Versions/2.7/lib/python2.7/site-packages/requests/sessions.py", line 576, in send
    r = adapter.send(request, **kwargs)
  File "/Library/Frameworks/Python.framework/Versions/2.7/lib/python2.7/site-packages/requests/adapters.py", line 437, in send
    raise ConnectionError(e, request=request)
ConnectionError: HTTPConnectionPool(host='localhost', port=3000): Max retries exceeded with url: /msgs (Caused by NewConnectionError('<requests.packages.urllib3.connection.HTTPConnection object at 0x10543ec50>: Failed to establish a new connection: [Errno 61] Connection refused',))
Tue Mar 29 10:52:30 2016
Traceback (most recent call last):
  File "/Users/linyuchen/Documents/code/Python/qq/qqsdk/qqclient.py", line 765, in run
    msg = self.getMsg()
  File "/Users/linyuchen/Documents/code/Python/qq/qqsdk/qqapi.py", line 90, in getMsg
    data = self.post_json(self.get_msgs_url)
  File "/Users/linyuchen/Documents/code/Python/qq/qqsdk/qqapi.py", line 37, in post_json
    res = requests.get(url, kwargs)
  File "/Library/Frameworks/Python.framework/Versions/2.7/lib/python2.7/site-packages/requests/api.py", line 67, in get
    return request('get', url, params=params, **kwargs)
  File "/Library/Frameworks/Python.framework/Versions/2.7/lib/python2.7/site-packages/requests/api.py", line 53, in request
    return session.request(method=method, url=url, **kwargs)
  File "/Library/Frameworks/Python.framework/Versions/2.7/lib/python2.7/site-packages/requests/sessions.py", line 468, in request
    resp = self.send(prep, **send_kwargs)
  File "/Library/Frameworks/Python.framework/Versions/2.7/lib/python2.7/site-packages/requests/sessions.py", line 576, in send
    r = adapter.send(request, **kwargs)
  File "/Library/Frameworks/Python.framework/Versions/2.7/lib/python2.7/site-packages/requests/adapters.py", line 437, in send
    raise ConnectionError(e, request=request)
ConnectionError: HTTPConnectionPool(host='localhost', port=3000): Max retries exceeded with url: /msgs (Caused by NewConnectionError('<requests.packages.urllib3.connection.HTTPConnection object at 0x10543ecd0>: Failed to establish a new connection: [Errno 61] Connection refused',))
Tue Mar 29 10:52:30 2016
Traceback (most recent call last):
  File "/Users/linyuchen/Documents/code/Python/qq/qqsdk/qqclient.py", line 765, in run
    msg = self.getMsg()
  File "/Users/linyuchen/Documents/code/Python/qq/qqsdk/qqapi.py", line 90, in getMsg
    data = self.post_json(self.get_msgs_url)
  File "/Users/linyuchen/Documents/code/Python/qq/qqsdk/qqapi.py", line 37, in post_json
    res = requests.get(url, kwargs)
  File "/Library/Frameworks/Python.framework/Versions/2.7/lib/python2.7/site-packages/requests/api.py", line 67, in get
    return request('get', url, params=params, **kwargs)
  File "/Library/Frameworks/Python.framework/Versions/2.7/lib/python2.7/site-packages/requests/api.py", line 53, in request
    return session.request(method=method, url=url, **kwargs)
  File "/Library/Frameworks/Python.framework/Versions/2.7/lib/python2.7/site-packages/requests/sessions.py", line 468, in request
    resp = self.send(prep, **send_kwargs)
  File "/Library/Frameworks/Python.framework/Versions/2.7/lib/python2.7/site-packages/requests/sessions.py", line 576, in send
    r = adapter.send(request, **kwargs)
  File "/Library/Frameworks/Python.framework/Versions/2.7/lib/python2.7/site-packages/requests/adapters.py", line 437, in send
    raise ConnectionError(e, request=request)
ConnectionError: HTTPConnectionPool(host='localhost', port=3000): Max retries exceeded with url: /msgs (Caused by NewConnectionError('<requests.packages.urllib3.connection.HTTPConnection object at 0x10543ed50>: Failed to establish a new connection: [Errno 61] Connection refused',))
Tue Mar 29 10:52:30 2016
Traceback (most recent call last):
  File "/Users/linyuchen/Documents/code/Python/qq/qqsdk/qqclient.py", line 765, in run
    msg = self.getMsg()
  File "/Users/linyuchen/Documents/code/Python/qq/qqsdk/qqapi.py", line 90, in getMsg
    data = self.post_json(self.get_msgs_url)
  File "/Users/linyuchen/Documents/code/Python/qq/qqsdk/qqapi.py", line 37, in post_json
    res = requests.get(url, kwargs)
  File "/Library/Frameworks/Python.framework/Versions/2.7/lib/python2.7/site-packages/requests/api.py", line 67, in get
    return request('get', url, params=params, **kwargs)
  File "/Library/Frameworks/Python.framework/Versions/2.7/lib/python2.7/site-packages/requests/api.py", line 53, in request
    return session.request(method=method, url=url, **kwargs)
  File "/Library/Frameworks/Python.framework/Versions/2.7/lib/python2.7/site-packages/requests/sessions.py", line 468, in request
    resp = self.send(prep, **send_kwargs)
  File "/Library/Frameworks/Python.framework/Versions/2.7/lib/python2.7/site-packages/requests/sessions.py", line 576, in send
    r = adapter.send(request, **kwargs)
  File "/Library/Frameworks/Python.framework/Versions/2.7/lib/python2.7/site-packages/requests/adapters.py", line 437, in send
    raise ConnectionError(e, request=request)
ConnectionError: HTTPConnectionPool(host='localhost', port=3000): Max retries exceeded with url: /msgs (Caused by NewConnectionError('<requests.packages.urllib3.connection.HTTPConnection object at 0x10543edd0>: Failed to establish a new connection: [Errno 61] Connection refused',))
Tue Mar 29 10:52:30 2016
Traceback (most recent call last):
  File "/Users/linyuchen/Documents/code/Python/qq/qqsdk/qqclient.py", line 765, in run
    msg = self.getMsg()
  File "/Users/linyuchen/Documents/code/Python/qq/qqsdk/qqapi.py", line 90, in getMsg
    data = self.post_json(self.get_msgs_url)
  File "/Users/linyuchen/Documents/code/Python/qq/qqsdk/qqapi.py", line 37, in post_json
    res = requests.get(url, kwargs)
  File "/Library/Frameworks/Python.framework/Versions/2.7/lib/python2.7/site-packages/requests/api.py", line 67, in get
    return request('get', url, params=params, **kwargs)
  File "/Library/Frameworks/Python.framework/Versions/2.7/lib/python2.7/site-packages/requests/api.py", line 53, in request
    return session.request(method=method, url=url, **kwargs)
  File "/Library/Frameworks/Python.framework/Versions/2.7/lib/python2.7/site-packages/requests/sessions.py", line 468, in request
    resp = self.send(prep, **send_kwargs)
  File "/Library/Frameworks/Python.framework/Versions/2.7/lib/python2.7/site-packages/requests/sessions.py", line 576, in send
    r = adapter.send(request, **kwargs)
  File "/Library/Frameworks/Python.framework/Versions/2.7/lib/python2.7/site-packages/requests/adapters.py", line 437, in send
    raise ConnectionError(e, request=request)
ConnectionError: HTTPConnectionPool(host='localhost', port=3000): Max retries exceeded with url: /msgs (Caused by NewConnectionError('<requests.packages.urllib3.connection.HTTPConnection object at 0x10543ee50>: Failed to establish a new connection: [Errno 61] Connection refused',))
Tue Mar 29 10:52:30 2016
Traceback (most recent call last):
  File "/Users/linyuchen/Documents/code/Python/qq/qqsdk/qqclient.py", line 765, in run
    msg = self.getMsg()
  File "/Users/linyuchen/Documents/code/Python/qq/qqsdk/qqapi.py", line 90, in getMsg
    data = self.post_json(self.get_msgs_url)
  File "/Users/linyuchen/Documents/code/Python/qq/qqsdk/qqapi.py", line 37, in post_json
    res = requests.get(url, kwargs)
  File "/Library/Frameworks/Python.framework/Versions/2.7/lib/python2.7/site-packages/requests/api.py", line 67, in get
    return request('get', url, params=params, **kwargs)
  File "/Library/Frameworks/Python.framework/Versions/2.7/lib/python2.7/site-packages/requests/api.py", line 53, in request
    return session.request(method=method, url=url, **kwargs)
  File "/Library/Frameworks/Python.framework/Versions/2.7/lib/python2.7/site-packages/requests/sessions.py", line 468, in request
    resp = self.send(prep, **send_kwargs)
  File "/Library/Frameworks/Python.framework/Versions/2.7/lib/python2.7/site-packages/requests/sessions.py", line 576, in send
    r = adapter.send(request, **kwargs)
  File "/Library/Frameworks/Python.framework/Versions/2.7/lib/python2.7/site-packages/requests/adapters.py", line 437, in send
    raise ConnectionError(e, request=request)
ConnectionError: HTTPConnectionPool(host='localhost', port=3000): Max retries exceeded with url: /msgs (Caused by NewConnectionError('<requests.packages.urllib3.connection.HTTPConnection object at 0x10543eed0>: Failed to establish a new connection: [Errno 61] Connection refused',))
Tue Mar 29 10:52:30 2016
Traceback (most recent call last):
  File "/Users/linyuchen/Documents/code/Python/qq/qqsdk/qqclient.py", line 765, in run
    msg = self.getMsg()
  File "/Users/linyuchen/Documents/code/Python/qq/qqsdk/qqapi.py", line 90, in getMsg
    data = self.post_json(self.get_msgs_url)
  File "/Users/linyuchen/Documents/code/Python/qq/qqsdk/qqapi.py", line 37, in post_json
    res = requests.get(url, kwargs)
  File "/Library/Frameworks/Python.framework/Versions/2.7/lib/python2.7/site-packages/requests/api.py", line 67, in get
    return request('get', url, params=params, **kwargs)
  File "/Library/Frameworks/Python.framework/Versions/2.7/lib/python2.7/site-packages/requests/api.py", line 53, in request
    return session.request(method=method, url=url, **kwargs)
  File "/Library/Frameworks/Python.framework/Versions/2.7/lib/python2.7/site-packages/requests/sessions.py", line 468, in request
    resp = self.send(prep, **send_kwargs)
  File "/Library/Frameworks/Python.framework/Versions/2.7/lib/python2.7/site-packages/requests/sessions.py", line 576, in send
    r = adapter.send(request, **kwargs)
  File "/Library/Frameworks/Python.framework/Versions/2.7/lib/python2.7/site-packages/requests/adapters.py", line 437, in send
    raise ConnectionError(e, request=request)
ConnectionError: HTTPConnectionPool(host='localhost', port=3000): Max retries exceeded with url: /msgs (Caused by NewConnectionError('<requests.packages.urllib3.connection.HTTPConnection object at 0x10543ef50>: Failed to establish a new connection: [Errno 61] Connection refused',))
Tue Mar 29 10:52:30 2016
Traceback (most recent call last):
  File "/Users/linyuchen/Documents/code/Python/qq/qqsdk/qqclient.py", line 765, in run
    msg = self.getMsg()
  File "/Users/linyuchen/Documents/code/Python/qq/qqsdk/qqapi.py", line 90, in getMsg
    data = self.post_json(self.get_msgs_url)
  File "/Users/linyuchen/Documents/code/Python/qq/qqsdk/qqapi.py", line 37, in post_json
    res = requests.get(url, kwargs)
  File "/Library/Frameworks/Python.framework/Versions/2.7/lib/python2.7/site-packages/requests/api.py", line 67, in get
    return request('get', url, params=params, **kwargs)
  File "/Library/Frameworks/Python.framework/Versions/2.7/lib/python2.7/site-packages/requests/api.py", line 53, in request
    return session.request(method=method, url=url, **kwargs)
  File "/Library/Frameworks/Python.framework/Versions/2.7/lib/python2.7/site-packages/requests/sessions.py", line 468, in request
    resp = self.send(prep, **send_kwargs)
  File "/Library/Frameworks/Python.framework/Versions/2.7/lib/python2.7/site-packages/requests/sessions.py", line 576, in send
    r = adapter.send(request, **kwargs)
  File "/Library/Frameworks/Python.framework/Versions/2.7/lib/python2.7/site-packages/requests/adapters.py", line 437, in send
    raise ConnectionError(e, request=request)
ConnectionError: HTTPConnectionPool(host='localhost', port=3000): Max retries exceeded with url: /msgs (Caused by NewConnectionError('<requests.packages.urllib3.connection.HTTPConnection object at 0x10543e550>: Failed to establish a new connection: [Errno 61] Connection refused',))
Tue Mar 29 10:52:30 2016
Traceback (most recent call last):
  File "/Users/linyuchen/Documents/code/Python/qq/qqsdk/qqclient.py", line 765, in run
    msg = self.getMsg()
  File "/Users/linyuchen/Documents/code/Python/qq/qqsdk/qqapi.py", line 90, in getMsg
    data = self.post_json(self.get_msgs_url)
  File "/Users/linyuchen/Documents/code/Python/qq/qqsdk/qqapi.py", line 37, in post_json
    res = requests.get(url, kwargs)
  File "/Library/Frameworks/Python.framework/Versions/2.7/lib/python2.7/site-packages/requests/api.py", line 67, in get
    return request('get', url, params=params, **kwargs)
  File "/Library/Frameworks/Python.framework/Versions/2.7/lib/python2.7/site-packages/requests/api.py", line 53, in request
    return session.request(method=method, url=url, **kwargs)
  File "/Library/Frameworks/Python.framework/Versions/2.7/lib/python2.7/site-packages/requests/sessions.py", line 468, in request
    resp = self.send(prep, **send_kwargs)
  File "/Library/Frameworks/Python.framework/Versions/2.7/lib/python2.7/site-packages/requests/sessions.py", line 576, in send
    r = adapter.send(request, **kwargs)
  File "/Library/Frameworks/Python.framework/Versions/2.7/lib/python2.7/site-packages/requests/adapters.py", line 437, in send
    raise ConnectionError(e, request=request)
ConnectionError: HTTPConnectionPool(host='localhost', port=3000): Max retries exceeded with url: /msgs (Caused by NewConnectionError('<requests.packages.urllib3.connection.HTTPConnection object at 0x1053cc090>: Failed to establish a new connection: [Errno 61] Connection refused',))
Tue Mar 29 10:52:31 2016
Traceback (most recent call last):
  File "/Users/linyuchen/Documents/code/Python/qq/qqsdk/qqclient.py", line 765, in run
    msg = self.getMsg()
  File "/Users/linyuchen/Documents/code/Python/qq/qqsdk/qqapi.py", line 90, in getMsg
    data = self.post_json(self.get_msgs_url)
  File "/Users/linyuchen/Documents/code/Python/qq/qqsdk/qqapi.py", line 37, in post_json
    res = requests.get(url, kwargs)
  File "/Library/Frameworks/Python.framework/Versions/2.7/lib/python2.7/site-packages/requests/api.py", line 67, in get
    return request('get', url, params=params, **kwargs)
  File "/Library/Frameworks/Python.framework/Versions/2.7/lib/python2.7/site-packages/requests/api.py", line 53, in request
    return session.request(method=method, url=url, **kwargs)
  File "/Library/Frameworks/Python.framework/Versions/2.7/lib/python2.7/site-packages/requests/sessions.py", line 468, in request
    resp = self.send(prep, **send_kwargs)
  File "/Library/Frameworks/Python.framework/Versions/2.7/lib/python2.7/site-packages/requests/sessions.py", line 576, in send
    r = adapter.send(request, **kwargs)
  File "/Library/Frameworks/Python.framework/Versions/2.7/lib/python2.7/site-packages/requests/adapters.py", line 437, in send
    raise ConnectionError(e, request=request)
ConnectionError: HTTPConnectionPool(host='localhost', port=3000): Max retries exceeded with url: /msgs (Caused by NewConnectionError('<requests.packages.urllib3.connection.HTTPConnection object at 0x1053cc110>: Failed to establish a new connection: [Errno 61] Connection refused',))
Tue Mar 29 10:52:31 2016
Traceback (most recent call last):
  File "/Users/linyuchen/Documents/code/Python/qq/qqsdk/qqclient.py", line 765, in run
    msg = self.getMsg()
  File "/Users/linyuchen/Documents/code/Python/qq/qqsdk/qqapi.py", line 90, in getMsg
    data = self.post_json(self.get_msgs_url)
  File "/Users/linyuchen/Documents/code/Python/qq/qqsdk/qqapi.py", line 37, in post_json
    res = requests.get(url, kwargs)
  File "/Library/Frameworks/Python.framework/Versions/2.7/lib/python2.7/site-packages/requests/api.py", line 67, in get
    return request('get', url, params=params, **kwargs)
  File "/Library/Frameworks/Python.framework/Versions/2.7/lib/python2.7/site-packages/requests/api.py", line 53, in request
    return session.request(method=method, url=url, **kwargs)
  File "/Library/Frameworks/Python.framework/Versions/2.7/lib/python2.7/site-packages/requests/sessions.py", line 468, in request
    resp = self.send(prep, **send_kwargs)
  File "/Library/Frameworks/Python.framework/Versions/2.7/lib/python2.7/site-packages/requests/sessions.py", line 576, in send
    r = adapter.send(request, **kwargs)
  File "/Library/Frameworks/Python.framework/Versions/2.7/lib/python2.7/site-packages/requests/adapters.py", line 437, in send
    raise ConnectionError(e, request=request)
ConnectionError: HTTPConnectionPool(host='localhost', port=3000): Max retries exceeded with url: /msgs (Caused by NewConnectionError('<requests.packages.urllib3.connection.HTTPConnection object at 0x1053cc190>: Failed to establish a new connection: [Errno 61] Connection refused',))
Tue Mar 29 10:52:31 2016
Traceback (most recent call last):
  File "/Users/linyuchen/Documents/code/Python/qq/qqsdk/qqclient.py", line 765, in run
    msg = self.getMsg()
  File "/Users/linyuchen/Documents/code/Python/qq/qqsdk/qqapi.py", line 90, in getMsg
    data = self.post_json(self.get_msgs_url)
  File "/Users/linyuchen/Documents/code/Python/qq/qqsdk/qqapi.py", line 37, in post_json
    res = requests.get(url, kwargs)
  File "/Library/Frameworks/Python.framework/Versions/2.7/lib/python2.7/site-packages/requests/api.py", line 67, in get
    return request('get', url, params=params, **kwargs)
  File "/Library/Frameworks/Python.framework/Versions/2.7/lib/python2.7/site-packages/requests/api.py", line 53, in request
    return session.request(method=method, url=url, **kwargs)
  File "/Library/Frameworks/Python.framework/Versions/2.7/lib/python2.7/site-packages/requests/sessions.py", line 468, in request
    resp = self.send(prep, **send_kwargs)
  File "/Library/Frameworks/Python.framework/Versions/2.7/lib/python2.7/site-packages/requests/sessions.py", line 576, in send
    r = adapter.send(request, **kwargs)
  File "/Library/Frameworks/Python.framework/Versions/2.7/lib/python2.7/site-packages/requests/adapters.py", line 437, in send
    raise ConnectionError(e, request=request)
ConnectionError: HTTPConnectionPool(host='localhost', port=3000): Max retries exceeded with url: /msgs (Caused by NewConnectionError('<requests.packages.urllib3.connection.HTTPConnection object at 0x1053cc210>: Failed to establish a new connection: [Errno 61] Connection refused',))
Tue Mar 29 10:52:31 2016
Traceback (most recent call last):
  File "/Users/linyuchen/Documents/code/Python/qq/qqsdk/qqclient.py", line 765, in run
    msg = self.getMsg()
  File "/Users/linyuchen/Documents/code/Python/qq/qqsdk/qqapi.py", line 90, in getMsg
    data = self.post_json(self.get_msgs_url)
  File "/Users/linyuchen/Documents/code/Python/qq/qqsdk/qqapi.py", line 37, in post_json
    res = requests.get(url, kwargs)
  File "/Library/Frameworks/Python.framework/Versions/2.7/lib/python2.7/site-packages/requests/api.py", line 67, in get
    return request('get', url, params=params, **kwargs)
  File "/Library/Frameworks/Python.framework/Versions/2.7/lib/python2.7/site-packages/requests/api.py", line 53, in request
    return session.request(method=method, url=url, **kwargs)
  File "/Library/Frameworks/Python.framework/Versions/2.7/lib/python2.7/site-packages/requests/sessions.py", line 468, in request
    resp = self.send(prep, **send_kwargs)
  File "/Library/Frameworks/Python.framework/Versions/2.7/lib/python2.7/site-packages/requests/sessions.py", line 576, in send
    r = adapter.send(request, **kwargs)
  File "/Library/Frameworks/Python.framework/Versions/2.7/lib/python2.7/site-packages/requests/adapters.py", line 437, in send
    raise ConnectionError(e, request=request)
ConnectionError: HTTPConnectionPool(host='localhost', port=3000): Max retries exceeded with url: /msgs (Caused by NewConnectionError('<requests.packages.urllib3.connection.HTTPConnection object at 0x1053cc290>: Failed to establish a new connection: [Errno 61] Connection refused',))
Tue Mar 29 10:52:31 2016
Traceback (most recent call last):
  File "/Users/linyuchen/Documents/code/Python/qq/qqsdk/qqclient.py", line 765, in run
    msg = self.getMsg()
  File "/Users/linyuchen/Documents/code/Python/qq/qqsdk/qqapi.py", line 90, in getMsg
    data = self.post_json(self.get_msgs_url)
  File "/Users/linyuchen/Documents/code/Python/qq/qqsdk/qqapi.py", line 37, in post_json
    res = requests.get(url, kwargs)
  File "/Library/Frameworks/Python.framework/Versions/2.7/lib/python2.7/site-packages/requests/api.py", line 67, in get
    return request('get', url, params=params, **kwargs)
  File "/Library/Frameworks/Python.framework/Versions/2.7/lib/python2.7/site-packages/requests/api.py", line 53, in request
    return session.request(method=method, url=url, **kwargs)
  File "/Library/Frameworks/Python.framework/Versions/2.7/lib/python2.7/site-packages/requests/sessions.py", line 468, in request
    resp = self.send(prep, **send_kwargs)
  File "/Library/Frameworks/Python.framework/Versions/2.7/lib/python2.7/site-packages/requests/sessions.py", line 576, in send
    r = adapter.send(request, **kwargs)
  File "/Library/Frameworks/Python.framework/Versions/2.7/lib/python2.7/site-packages/requests/adapters.py", line 437, in send
    raise ConnectionError(e, request=request)
ConnectionError: HTTPConnectionPool(host='localhost', port=3000): Max retries exceeded with url: /msgs (Caused by NewConnectionError('<requests.packages.urllib3.connection.HTTPConnection object at 0x1053cc310>: Failed to establish a new connection: [Errno 61] Connection refused',))
Tue Mar 29 10:52:31 2016
Traceback (most recent call last):
  File "/Users/linyuchen/Documents/code/Python/qq/qqsdk/qqclient.py", line 765, in run
    msg = self.getMsg()
  File "/Users/linyuchen/Documents/code/Python/qq/qqsdk/qqapi.py", line 90, in getMsg
    data = self.post_json(self.get_msgs_url)
  File "/Users/linyuchen/Documents/code/Python/qq/qqsdk/qqapi.py", line 37, in post_json
    res = requests.get(url, kwargs)
  File "/Library/Frameworks/Python.framework/Versions/2.7/lib/python2.7/site-packages/requests/api.py", line 67, in get
    return request('get', url, params=params, **kwargs)
  File "/Library/Frameworks/Python.framework/Versions/2.7/lib/python2.7/site-packages/requests/api.py", line 53, in request
    return session.request(method=method, url=url, **kwargs)
  File "/Library/Frameworks/Python.framework/Versions/2.7/lib/python2.7/site-packages/requests/sessions.py", line 468, in request
    resp = self.send(prep, **send_kwargs)
  File "/Library/Frameworks/Python.framework/Versions/2.7/lib/python2.7/site-packages/requests/sessions.py", line 576, in send
    r = adapter.send(request, **kwargs)
  File "/Library/Frameworks/Python.framework/Versions/2.7/lib/python2.7/site-packages/requests/adapters.py", line 437, in send
    raise ConnectionError(e, request=request)
ConnectionError: HTTPConnectionPool(host='localhost', port=3000): Max retries exceeded with url: /msgs (Caused by NewConnectionError('<requests.packages.urllib3.connection.HTTPConnection object at 0x1053cc390>: Failed to establish a new connection: [Errno 61] Connection refused',))
Tue Mar 29 10:52:31 2016
Traceback (most recent call last):
  File "/Users/linyuchen/Documents/code/Python/qq/qqsdk/qqclient.py", line 765, in run
    msg = self.getMsg()
  File "/Users/linyuchen/Documents/code/Python/qq/qqsdk/qqapi.py", line 90, in getMsg
    data = self.post_json(self.get_msgs_url)
  File "/Users/linyuchen/Documents/code/Python/qq/qqsdk/qqapi.py", line 37, in post_json
    res = requests.get(url, kwargs)
  File "/Library/Frameworks/Python.framework/Versions/2.7/lib/python2.7/site-packages/requests/api.py", line 67, in get
    return request('get', url, params=params, **kwargs)
  File "/Library/Frameworks/Python.framework/Versions/2.7/lib/python2.7/site-packages/requests/api.py", line 53, in request
    return session.request(method=method, url=url, **kwargs)
  File "/Library/Frameworks/Python.framework/Versions/2.7/lib/python2.7/site-packages/requests/sessions.py", line 468, in request
    resp = self.send(prep, **send_kwargs)
  File "/Library/Frameworks/Python.framework/Versions/2.7/lib/python2.7/site-packages/requests/sessions.py", line 576, in send
    r = adapter.send(request, **kwargs)
  File "/Library/Frameworks/Python.framework/Versions/2.7/lib/python2.7/site-packages/requests/adapters.py", line 437, in send
    raise ConnectionError(e, request=request)
ConnectionError: HTTPConnectionPool(host='localhost', port=3000): Max retries exceeded with url: /msgs (Caused by NewConnectionError('<requests.packages.urllib3.connection.HTTPConnection object at 0x1053cc410>: Failed to establish a new connection: [Errno 61] Connection refused',))
Tue Mar 29 10:52:31 2016
Traceback (most recent call last):
  File "/Users/linyuchen/Documents/code/Python/qq/qqsdk/qqclient.py", line 765, in run
    msg = self.getMsg()
  File "/Users/linyuchen/Documents/code/Python/qq/qqsdk/qqapi.py", line 90, in getMsg
    data = self.post_json(self.get_msgs_url)
  File "/Users/linyuchen/Documents/code/Python/qq/qqsdk/qqapi.py", line 37, in post_json
    res = requests.get(url, kwargs)
  File "/Library/Frameworks/Python.framework/Versions/2.7/lib/python2.7/site-packages/requests/api.py", line 67, in get
    return request('get', url, params=params, **kwargs)
  File "/Library/Frameworks/Python.framework/Versions/2.7/lib/python2.7/site-packages/requests/api.py", line 53, in request
    return session.request(method=method, url=url, **kwargs)
  File "/Library/Frameworks/Python.framework/Versions/2.7/lib/python2.7/site-packages/requests/sessions.py", line 468, in request
    resp = self.send(prep, **send_kwargs)
  File "/Library/Frameworks/Python.framework/Versions/2.7/lib/python2.7/site-packages/requests/sessions.py", line 576, in send
    r = adapter.send(request, **kwargs)
  File "/Library/Frameworks/Python.framework/Versions/2.7/lib/python2.7/site-packages/requests/adapters.py", line 437, in send
    raise ConnectionError(e, request=request)
ConnectionError: HTTPConnectionPool(host='localhost', port=3000): Max retries exceeded with url: /msgs (Caused by NewConnectionError('<requests.packages.urllib3.connection.HTTPConnection object at 0x1053cc490>: Failed to establish a new connection: [Errno 61] Connection refused',))
Tue Mar 29 10:52:31 2016
Traceback (most recent call last):
  File "/Users/linyuchen/Documents/code/Python/qq/qqsdk/qqclient.py", line 765, in run
    msg = self.getMsg()
  File "/Users/linyuchen/Documents/code/Python/qq/qqsdk/qqapi.py", line 90, in getMsg
    data = self.post_json(self.get_msgs_url)
  File "/Users/linyuchen/Documents/code/Python/qq/qqsdk/qqapi.py", line 37, in post_json
    res = requests.get(url, kwargs)
  File "/Library/Frameworks/Python.framework/Versions/2.7/lib/python2.7/site-packages/requests/api.py", line 67, in get
    return request('get', url, params=params, **kwargs)
  File "/Library/Frameworks/Python.framework/Versions/2.7/lib/python2.7/site-packages/requests/api.py", line 53, in request
    return session.request(method=method, url=url, **kwargs)
  File "/Library/Frameworks/Python.framework/Versions/2.7/lib/python2.7/site-packages/requests/sessions.py", line 468, in request
    resp = self.send(prep, **send_kwargs)
  File "/Library/Frameworks/Python.framework/Versions/2.7/lib/python2.7/site-packages/requests/sessions.py", line 576, in send
    r = adapter.send(request, **kwargs)
  File "/Library/Frameworks/Python.framework/Versions/2.7/lib/python2.7/site-packages/requests/adapters.py", line 437, in send
    raise ConnectionError(e, request=request)
ConnectionError: HTTPConnectionPool(host='localhost', port=3000): Max retries exceeded with url: /msgs (Caused by NewConnectionError('<requests.packages.urllib3.connection.HTTPConnection object at 0x1053cc110>: Failed to establish a new connection: [Errno 61] Connection refused',))
Tue Mar 29 10:52:32 2016
Traceback (most recent call last):
  File "/Users/linyuchen/Documents/code/Python/qq/qqsdk/qqclient.py", line 765, in run
    msg = self.getMsg()
  File "/Users/linyuchen/Documents/code/Python/qq/qqsdk/qqapi.py", line 90, in getMsg
    data = self.post_json(self.get_msgs_url)
  File "/Users/linyuchen/Documents/code/Python/qq/qqsdk/qqapi.py", line 37, in post_json
    res = requests.get(url, kwargs)
  File "/Library/Frameworks/Python.framework/Versions/2.7/lib/python2.7/site-packages/requests/api.py", line 67, in get
    return request('get', url, params=params, **kwargs)
  File "/Library/Frameworks/Python.framework/Versions/2.7/lib/python2.7/site-packages/requests/api.py", line 53, in request
    return session.request(method=method, url=url, **kwargs)
  File "/Library/Frameworks/Python.framework/Versions/2.7/lib/python2.7/site-packages/requests/sessions.py", line 468, in request
    resp = self.send(prep, **send_kwargs)
  File "/Library/Frameworks/Python.framework/Versions/2.7/lib/python2.7/site-packages/requests/sessions.py", line 576, in send
    r = adapter.send(request, **kwargs)
  File "/Library/Frameworks/Python.framework/Versions/2.7/lib/python2.7/site-packages/requests/adapters.py", line 437, in send
    raise ConnectionError(e, request=request)
ConnectionError: HTTPConnectionPool(host='localhost', port=3000): Max retries exceeded with url: /msgs (Caused by NewConnectionError('<requests.packages.urllib3.connection.HTTPConnection object at 0x1053cc5d0>: Failed to establish a new connection: [Errno 61] Connection refused',))
Tue Mar 29 10:52:32 2016
Traceback (most recent call last):
  File "/Users/linyuchen/Documents/code/Python/qq/qqsdk/qqclient.py", line 765, in run
    msg = self.getMsg()
  File "/Users/linyuchen/Documents/code/Python/qq/qqsdk/qqapi.py", line 90, in getMsg
    data = self.post_json(self.get_msgs_url)
  File "/Users/linyuchen/Documents/code/Python/qq/qqsdk/qqapi.py", line 37, in post_json
    res = requests.get(url, kwargs)
  File "/Library/Frameworks/Python.framework/Versions/2.7/lib/python2.7/site-packages/requests/api.py", line 67, in get
    return request('get', url, params=params, **kwargs)
  File "/Library/Frameworks/Python.framework/Versions/2.7/lib/python2.7/site-packages/requests/api.py", line 53, in request
    return session.request(method=method, url=url, **kwargs)
  File "/Library/Frameworks/Python.framework/Versions/2.7/lib/python2.7/site-packages/requests/sessions.py", line 468, in request
    resp = self.send(prep, **send_kwargs)
  File "/Library/Frameworks/Python.framework/Versions/2.7/lib/python2.7/site-packages/requests/sessions.py", line 576, in send
    r = adapter.send(request, **kwargs)
  File "/Library/Frameworks/Python.framework/Versions/2.7/lib/python2.7/site-packages/requests/adapters.py", line 437, in send
    raise ConnectionError(e, request=request)
ConnectionError: HTTPConnectionPool(host='localhost', port=3000): Max retries exceeded with url: /msgs (Caused by NewConnectionError('<requests.packages.urllib3.connection.HTTPConnection object at 0x1053cc590>: Failed to establish a new connection: [Errno 61] Connection refused',))
Tue Mar 29 10:52:32 2016
Traceback (most recent call last):
  File "/Users/linyuchen/Documents/code/Python/qq/qqsdk/qqclient.py", line 765, in run
    msg = self.getMsg()
  File "/Users/linyuchen/Documents/code/Python/qq/qqsdk/qqapi.py", line 90, in getMsg
    data = self.post_json(self.get_msgs_url)
  File "/Users/linyuchen/Documents/code/Python/qq/qqsdk/qqapi.py", line 37, in post_json
    res = requests.get(url, kwargs)
  File "/Library/Frameworks/Python.framework/Versions/2.7/lib/python2.7/site-packages/requests/api.py", line 67, in get
    return request('get', url, params=params, **kwargs)
  File "/Library/Frameworks/Python.framework/Versions/2.7/lib/python2.7/site-packages/requests/api.py", line 53, in request
    return session.request(method=method, url=url, **kwargs)
  File "/Library/Frameworks/Python.framework/Versions/2.7/lib/python2.7/site-packages/requests/sessions.py", line 468, in request
    resp = self.send(prep, **send_kwargs)
  File "/Library/Frameworks/Python.framework/Versions/2.7/lib/python2.7/site-packages/requests/sessions.py", line 576, in send
    r = adapter.send(request, **kwargs)
  File "/Library/Frameworks/Python.framework/Versions/2.7/lib/python2.7/site-packages/requests/adapters.py", line 437, in send
    raise ConnectionError(e, request=request)
ConnectionError: HTTPConnectionPool(host='localhost', port=3000): Max retries exceeded with url: /msgs (Caused by NewConnectionError('<requests.packages.urllib3.connection.HTTPConnection object at 0x1053cc650>: Failed to establish a new connection: [Errno 61] Connection refused',))
Tue Mar 29 10:52:32 2016
Traceback (most recent call last):
  File "/Users/linyuchen/Documents/code/Python/qq/qqsdk/qqclient.py", line 765, in run
    msg = self.getMsg()
  File "/Users/linyuchen/Documents/code/Python/qq/qqsdk/qqapi.py", line 90, in getMsg
    data = self.post_json(self.get_msgs_url)
  File "/Users/linyuchen/Documents/code/Python/qq/qqsdk/qqapi.py", line 37, in post_json
    res = requests.get(url, kwargs)
  File "/Library/Frameworks/Python.framework/Versions/2.7/lib/python2.7/site-packages/requests/api.py", line 67, in get
    return request('get', url, params=params, **kwargs)
  File "/Library/Frameworks/Python.framework/Versions/2.7/lib/python2.7/site-packages/requests/api.py", line 53, in request
    return session.request(method=method, url=url, **kwargs)
  File "/Library/Frameworks/Python.framework/Versions/2.7/lib/python2.7/site-packages/requests/sessions.py", line 468, in request
    resp = self.send(prep, **send_kwargs)
  File "/Library/Frameworks/Python.framework/Versions/2.7/lib/python2.7/site-packages/requests/sessions.py", line 576, in send
    r = adapter.send(request, **kwargs)
  File "/Library/Frameworks/Python.framework/Versions/2.7/lib/python2.7/site-packages/requests/adapters.py", line 437, in send
    raise ConnectionError(e, request=request)
ConnectionError: HTTPConnectionPool(host='localhost', port=3000): Max retries exceeded with url: /msgs (Caused by NewConnectionError('<requests.packages.urllib3.connection.HTTPConnection object at 0x1053cc6d0>: Failed to establish a new connection: [Errno 61] Connection refused',))
Tue Mar 29 10:52:32 2016
Traceback (most recent call last):
  File "/Users/linyuchen/Documents/code/Python/qq/qqsdk/qqclient.py", line 765, in run
    msg = self.getMsg()
  File "/Users/linyuchen/Documents/code/Python/qq/qqsdk/qqapi.py", line 90, in getMsg
    data = self.post_json(self.get_msgs_url)
  File "/Users/linyuchen/Documents/code/Python/qq/qqsdk/qqapi.py", line 37, in post_json
    res = requests.get(url, kwargs)
  File "/Library/Frameworks/Python.framework/Versions/2.7/lib/python2.7/site-packages/requests/api.py", line 67, in get
    return request('get', url, params=params, **kwargs)
  File "/Library/Frameworks/Python.framework/Versions/2.7/lib/python2.7/site-packages/requests/api.py", line 53, in request
    return session.request(method=method, url=url, **kwargs)
  File "/Library/Frameworks/Python.framework/Versions/2.7/lib/python2.7/site-packages/requests/sessions.py", line 468, in request
    resp = self.send(prep, **send_kwargs)
  File "/Library/Frameworks/Python.framework/Versions/2.7/lib/python2.7/site-packages/requests/sessions.py", line 576, in send
    r = adapter.send(request, **kwargs)
  File "/Library/Frameworks/Python.framework/Versions/2.7/lib/python2.7/site-packages/requests/adapters.py", line 437, in send
    raise ConnectionError(e, request=request)
ConnectionError: HTTPConnectionPool(host='localhost', port=3000): Max retries exceeded with url: /msgs (Caused by NewConnectionError('<requests.packages.urllib3.connection.HTTPConnection object at 0x1053cc750>: Failed to establish a new connection: [Errno 61] Connection refused',))
Tue Mar 29 10:52:32 2016
Traceback (most recent call last):
  File "/Users/linyuchen/Documents/code/Python/qq/qqsdk/qqclient.py", line 765, in run
    msg = self.getMsg()
  File "/Users/linyuchen/Documents/code/Python/qq/qqsdk/qqapi.py", line 90, in getMsg
    data = self.post_json(self.get_msgs_url)
  File "/Users/linyuchen/Documents/code/Python/qq/qqsdk/qqapi.py", line 37, in post_json
    res = requests.get(url, kwargs)
  File "/Library/Frameworks/Python.framework/Versions/2.7/lib/python2.7/site-packages/requests/api.py", line 67, in get
    return request('get', url, params=params, **kwargs)
  File "/Library/Frameworks/Python.framework/Versions/2.7/lib/python2.7/site-packages/requests/api.py", line 53, in request
    return session.request(method=method, url=url, **kwargs)
  File "/Library/Frameworks/Python.framework/Versions/2.7/lib/python2.7/site-packages/requests/sessions.py", line 468, in request
    resp = self.send(prep, **send_kwargs)
  File "/Library/Frameworks/Python.framework/Versions/2.7/lib/python2.7/site-packages/requests/sessions.py", line 576, in send
    r = adapter.send(request, **kwargs)
  File "/Library/Frameworks/Python.framework/Versions/2.7/lib/python2.7/site-packages/requests/adapters.py", line 437, in send
    raise ConnectionError(e, request=request)
ConnectionError: HTTPConnectionPool(host='localhost', port=3000): Max retries exceeded with url: /msgs (Caused by NewConnectionError('<requests.packages.urllib3.connection.HTTPConnection object at 0x1053cc7d0>: Failed to establish a new connection: [Errno 61] Connection refused',))
Tue Mar 29 10:52:32 2016
Traceback (most recent call last):
  File "/Users/linyuchen/Documents/code/Python/qq/qqsdk/qqclient.py", line 765, in run
    msg = self.getMsg()
  File "/Users/linyuchen/Documents/code/Python/qq/qqsdk/qqapi.py", line 90, in getMsg
    data = self.post_json(self.get_msgs_url)
  File "/Users/linyuchen/Documents/code/Python/qq/qqsdk/qqapi.py", line 37, in post_json
    res = requests.get(url, kwargs)
  File "/Library/Frameworks/Python.framework/Versions/2.7/lib/python2.7/site-packages/requests/api.py", line 67, in get
    return request('get', url, params=params, **kwargs)
  File "/Library/Frameworks/Python.framework/Versions/2.7/lib/python2.7/site-packages/requests/api.py", line 53, in request
    return session.request(method=method, url=url, **kwargs)
  File "/Library/Frameworks/Python.framework/Versions/2.7/lib/python2.7/site-packages/requests/sessions.py", line 468, in request
    resp = self.send(prep, **send_kwargs)
  File "/Library/Frameworks/Python.framework/Versions/2.7/lib/python2.7/site-packages/requests/sessions.py", line 576, in send
    r = adapter.send(request, **kwargs)
  File "/Library/Frameworks/Python.framework/Versions/2.7/lib/python2.7/site-packages/requests/adapters.py", line 437, in send
    raise ConnectionError(e, request=request)
ConnectionError: HTTPConnectionPool(host='localhost', port=3000): Max retries exceeded with url: /msgs (Caused by NewConnectionError('<requests.packages.urllib3.connection.HTTPConnection object at 0x1053cc850>: Failed to establish a new connection: [Errno 61] Connection refused',))
Tue Mar 29 10:52:32 2016
Traceback (most recent call last):
  File "/Users/linyuchen/Documents/code/Python/qq/qqsdk/qqclient.py", line 765, in run
    msg = self.getMsg()
  File "/Users/linyuchen/Documents/code/Python/qq/qqsdk/qqapi.py", line 90, in getMsg
    data = self.post_json(self.get_msgs_url)
  File "/Users/linyuchen/Documents/code/Python/qq/qqsdk/qqapi.py", line 37, in post_json
    res = requests.get(url, kwargs)
  File "/Library/Frameworks/Python.framework/Versions/2.7/lib/python2.7/site-packages/requests/api.py", line 67, in get
    return request('get', url, params=params, **kwargs)
  File "/Library/Frameworks/Python.framework/Versions/2.7/lib/python2.7/site-packages/requests/api.py", line 53, in request
    return session.request(method=method, url=url, **kwargs)
  File "/Library/Frameworks/Python.framework/Versions/2.7/lib/python2.7/site-packages/requests/sessions.py", line 468, in request
    resp = self.send(prep, **send_kwargs)
  File "/Library/Frameworks/Python.framework/Versions/2.7/lib/python2.7/site-packages/requests/sessions.py", line 576, in send
    r = adapter.send(request, **kwargs)
  File "/Library/Frameworks/Python.framework/Versions/2.7/lib/python2.7/site-packages/requests/adapters.py", line 437, in send
    raise ConnectionError(e, request=request)
ConnectionError: HTTPConnectionPool(host='localhost', port=3000): Max retries exceeded with url: /msgs (Caused by NewConnectionError('<requests.packages.urllib3.connection.HTTPConnection object at 0x1053cc8d0>: Failed to establish a new connection: [Errno 61] Connection refused',))
Tue Mar 29 10:52:32 2016
Traceback (most recent call last):
  File "/Users/linyuchen/Documents/code/Python/qq/qqsdk/qqclient.py", line 765, in run
    msg = self.getMsg()
  File "/Users/linyuchen/Documents/code/Python/qq/qqsdk/qqapi.py", line 90, in getMsg
    data = self.post_json(self.get_msgs_url)
  File "/Users/linyuchen/Documents/code/Python/qq/qqsdk/qqapi.py", line 37, in post_json
    res = requests.get(url, kwargs)
  File "/Library/Frameworks/Python.framework/Versions/2.7/lib/python2.7/site-packages/requests/api.py", line 67, in get
    return request('get', url, params=params, **kwargs)
  File "/Library/Frameworks/Python.framework/Versions/2.7/lib/python2.7/site-packages/requests/api.py", line 53, in request
    return session.request(method=method, url=url, **kwargs)
  File "/Library/Frameworks/Python.framework/Versions/2.7/lib/python2.7/site-packages/requests/sessions.py", line 468, in request
    resp = self.send(prep, **send_kwargs)
  File "/Library/Frameworks/Python.framework/Versions/2.7/lib/python2.7/site-packages/requests/sessions.py", line 576, in send
    r = adapter.send(request, **kwargs)
  File "/Library/Frameworks/Python.framework/Versions/2.7/lib/python2.7/site-packages/requests/adapters.py", line 437, in send
    raise ConnectionError(e, request=request)
ConnectionError: HTTPConnectionPool(host='localhost', port=3000): Max retries exceeded with url: /msgs (Caused by NewConnectionError('<requests.packages.urllib3.connection.HTTPConnection object at 0x1053cc950>: Failed to establish a new connection: [Errno 61] Connection refused',))
Tue Mar 29 10:52:32 2016
Traceback (most recent call last):
  File "/Users/linyuchen/Documents/code/Python/qq/qqsdk/qqclient.py", line 765, in run
    msg = self.getMsg()
  File "/Users/linyuchen/Documents/code/Python/qq/qqsdk/qqapi.py", line 90, in getMsg
    data = self.post_json(self.get_msgs_url)
  File "/Users/linyuchen/Documents/code/Python/qq/qqsdk/qqapi.py", line 37, in post_json
    res = requests.get(url, kwargs)
  File "/Library/Frameworks/Python.framework/Versions/2.7/lib/python2.7/site-packages/requests/api.py", line 67, in get
    return request('get', url, params=params, **kwargs)
  File "/Library/Frameworks/Python.framework/Versions/2.7/lib/python2.7/site-packages/requests/api.py", line 53, in request
    return session.request(method=method, url=url, **kwargs)
  File "/Library/Frameworks/Python.framework/Versions/2.7/lib/python2.7/site-packages/requests/sessions.py", line 468, in request
    resp = self.send(prep, **send_kwargs)
  File "/Library/Frameworks/Python.framework/Versions/2.7/lib/python2.7/site-packages/requests/sessions.py", line 576, in send
    r = adapter.send(request, **kwargs)
  File "/Library/Frameworks/Python.framework/Versions/2.7/lib/python2.7/site-packages/requests/adapters.py", line 437, in send
    raise ConnectionError(e, request=request)
ConnectionError: HTTPConnectionPool(host='localhost', port=3000): Max retries exceeded with url: /msgs (Caused by NewConnectionError('<requests.packages.urllib3.connection.HTTPConnection object at 0x1053cc9d0>: Failed to establish a new connection: [Errno 61] Connection refused',))
Tue Mar 29 10:52:33 2016
Traceback (most recent call last):
  File "/Users/linyuchen/Documents/code/Python/qq/qqsdk/qqclient.py", line 765, in run
    msg = self.getMsg()
  File "/Users/linyuchen/Documents/code/Python/qq/qqsdk/qqapi.py", line 90, in getMsg
    data = self.post_json(self.get_msgs_url)
  File "/Users/linyuchen/Documents/code/Python/qq/qqsdk/qqapi.py", line 37, in post_json
    res = requests.get(url, kwargs)
  File "/Library/Frameworks/Python.framework/Versions/2.7/lib/python2.7/site-packages/requests/api.py", line 67, in get
    return request('get', url, params=params, **kwargs)
  File "/Library/Frameworks/Python.framework/Versions/2.7/lib/python2.7/site-packages/requests/api.py", line 53, in request
    return session.request(method=method, url=url, **kwargs)
  File "/Library/Frameworks/Python.framework/Versions/2.7/lib/python2.7/site-packages/requests/sessions.py", line 468, in request
    resp = self.send(prep, **send_kwargs)
  File "/Library/Frameworks/Python.framework/Versions/2.7/lib/python2.7/site-packages/requests/sessions.py", line 576, in send
    r = adapter.send(request, **kwargs)
  File "/Library/Frameworks/Python.framework/Versions/2.7/lib/python2.7/site-packages/requests/adapters.py", line 437, in send
    raise ConnectionError(e, request=request)
ConnectionError: HTTPConnectionPool(host='localhost', port=3000): Max retries exceeded with url: /msgs (Caused by NewConnectionError('<requests.packages.urllib3.connection.HTTPConnection object at 0x1053cca50>: Failed to establish a new connection: [Errno 61] Connection refused',))
Tue Mar 29 10:52:33 2016
Traceback (most recent call last):
  File "/Users/linyuchen/Documents/code/Python/qq/qqsdk/qqclient.py", line 765, in run
    msg = self.getMsg()
  File "/Users/linyuchen/Documents/code/Python/qq/qqsdk/qqapi.py", line 90, in getMsg
    data = self.post_json(self.get_msgs_url)
  File "/Users/linyuchen/Documents/code/Python/qq/qqsdk/qqapi.py", line 37, in post_json
    res = requests.get(url, kwargs)
  File "/Library/Frameworks/Python.framework/Versions/2.7/lib/python2.7/site-packages/requests/api.py", line 67, in get
    return request('get', url, params=params, **kwargs)
  File "/Library/Frameworks/Python.framework/Versions/2.7/lib/python2.7/site-packages/requests/api.py", line 53, in request
    return session.request(method=method, url=url, **kwargs)
  File "/Library/Frameworks/Python.framework/Versions/2.7/lib/python2.7/site-packages/requests/sessions.py", line 468, in request
    resp = self.send(prep, **send_kwargs)
  File "/Library/Frameworks/Python.framework/Versions/2.7/lib/python2.7/site-packages/requests/sessions.py", line 576, in send
    r = adapter.send(request, **kwargs)
  File "/Library/Frameworks/Python.framework/Versions/2.7/lib/python2.7/site-packages/requests/adapters.py", line 437, in send
    raise ConnectionError(e, request=request)
ConnectionError: HTTPConnectionPool(host='localhost', port=3000): Max retries exceeded with url: /msgs (Caused by NewConnectionError('<requests.packages.urllib3.connection.HTTPConnection object at 0x1053ccad0>: Failed to establish a new connection: [Errno 61] Connection refused',))
Tue Mar 29 10:52:33 2016
Traceback (most recent call last):
  File "/Users/linyuchen/Documents/code/Python/qq/qqsdk/qqclient.py", line 765, in run
    msg = self.getMsg()
  File "/Users/linyuchen/Documents/code/Python/qq/qqsdk/qqapi.py", line 90, in getMsg
    data = self.post_json(self.get_msgs_url)
  File "/Users/linyuchen/Documents/code/Python/qq/qqsdk/qqapi.py", line 37, in post_json
    res = requests.get(url, kwargs)
  File "/Library/Frameworks/Python.framework/Versions/2.7/lib/python2.7/site-packages/requests/api.py", line 67, in get
    return request('get', url, params=params, **kwargs)
  File "/Library/Frameworks/Python.framework/Versions/2.7/lib/python2.7/site-packages/requests/api.py", line 53, in request
    return session.request(method=method, url=url, **kwargs)
  File "/Library/Frameworks/Python.framework/Versions/2.7/lib/python2.7/site-packages/requests/sessions.py", line 468, in request
    resp = self.send(prep, **send_kwargs)
  File "/Library/Frameworks/Python.framework/Versions/2.7/lib/python2.7/site-packages/requests/sessions.py", line 576, in send
    r = adapter.send(request, **kwargs)
  File "/Library/Frameworks/Python.framework/Versions/2.7/lib/python2.7/site-packages/requests/adapters.py", line 437, in send
    raise ConnectionError(e, request=request)
ConnectionError: HTTPConnectionPool(host='localhost', port=3000): Max retries exceeded with url: /msgs (Caused by NewConnectionError('<requests.packages.urllib3.connection.HTTPConnection object at 0x1053ccb50>: Failed to establish a new connection: [Errno 61] Connection refused',))
Tue Mar 29 10:52:33 2016
Traceback (most recent call last):
  File "/Users/linyuchen/Documents/code/Python/qq/qqsdk/qqclient.py", line 765, in run
    msg = self.getMsg()
  File "/Users/linyuchen/Documents/code/Python/qq/qqsdk/qqapi.py", line 90, in getMsg
    data = self.post_json(self.get_msgs_url)
  File "/Users/linyuchen/Documents/code/Python/qq/qqsdk/qqapi.py", line 37, in post_json
    res = requests.get(url, kwargs)
  File "/Library/Frameworks/Python.framework/Versions/2.7/lib/python2.7/site-packages/requests/api.py", line 67, in get
    return request('get', url, params=params, **kwargs)
  File "/Library/Frameworks/Python.framework/Versions/2.7/lib/python2.7/site-packages/requests/api.py", line 53, in request
    return session.request(method=method, url=url, **kwargs)
  File "/Library/Frameworks/Python.framework/Versions/2.7/lib/python2.7/site-packages/requests/sessions.py", line 468, in request
    resp = self.send(prep, **send_kwargs)
  File "/Library/Frameworks/Python.framework/Versions/2.7/lib/python2.7/site-packages/requests/sessions.py", line 576, in send
    r = adapter.send(request, **kwargs)
  File "/Library/Frameworks/Python.framework/Versions/2.7/lib/python2.7/site-packages/requests/adapters.py", line 437, in send
    raise ConnectionError(e, request=request)
ConnectionError: HTTPConnectionPool(host='localhost', port=3000): Max retries exceeded with url: /msgs (Caused by NewConnectionError('<requests.packages.urllib3.connection.HTTPConnection object at 0x1053ccbd0>: Failed to establish a new connection: [Errno 61] Connection refused',))
Tue Mar 29 10:52:33 2016
Traceback (most recent call last):
  File "/Users/linyuchen/Documents/code/Python/qq/qqsdk/qqclient.py", line 765, in run
    msg = self.getMsg()
  File "/Users/linyuchen/Documents/code/Python/qq/qqsdk/qqapi.py", line 90, in getMsg
    data = self.post_json(self.get_msgs_url)
  File "/Users/linyuchen/Documents/code/Python/qq/qqsdk/qqapi.py", line 37, in post_json
    res = requests.get(url, kwargs)
  File "/Library/Frameworks/Python.framework/Versions/2.7/lib/python2.7/site-packages/requests/api.py", line 67, in get
    return request('get', url, params=params, **kwargs)
  File "/Library/Frameworks/Python.framework/Versions/2.7/lib/python2.7/site-packages/requests/api.py", line 53, in request
    return session.request(method=method, url=url, **kwargs)
  File "/Library/Frameworks/Python.framework/Versions/2.7/lib/python2.7/site-packages/requests/sessions.py", line 468, in request
    resp = self.send(prep, **send_kwargs)
  File "/Library/Frameworks/Python.framework/Versions/2.7/lib/python2.7/site-packages/requests/sessions.py", line 576, in send
    r = adapter.send(request, **kwargs)
  File "/Library/Frameworks/Python.framework/Versions/2.7/lib/python2.7/site-packages/requests/adapters.py", line 437, in send
    raise ConnectionError(e, request=request)
ConnectionError: HTTPConnectionPool(host='localhost', port=3000): Max retries exceeded with url: /msgs (Caused by NewConnectionError('<requests.packages.urllib3.connection.HTTPConnection object at 0x1053ccc50>: Failed to establish a new connection: [Errno 61] Connection refused',))
Tue Mar 29 10:52:33 2016
Traceback (most recent call last):
  File "/Users/linyuchen/Documents/code/Python/qq/qqsdk/qqclient.py", line 765, in run
    msg = self.getMsg()
  File "/Users/linyuchen/Documents/code/Python/qq/qqsdk/qqapi.py", line 90, in getMsg
    data = self.post_json(self.get_msgs_url)
  File "/Users/linyuchen/Documents/code/Python/qq/qqsdk/qqapi.py", line 37, in post_json
    res = requests.get(url, kwargs)
  File "/Library/Frameworks/Python.framework/Versions/2.7/lib/python2.7/site-packages/requests/api.py", line 67, in get
    return request('get', url, params=params, **kwargs)
  File "/Library/Frameworks/Python.framework/Versions/2.7/lib/python2.7/site-packages/requests/api.py", line 53, in request
    return session.request(method=method, url=url, **kwargs)
  File "/Library/Frameworks/Python.framework/Versions/2.7/lib/python2.7/site-packages/requests/sessions.py", line 468, in request
    resp = self.send(prep, **send_kwargs)
  File "/Library/Frameworks/Python.framework/Versions/2.7/lib/python2.7/site-packages/requests/sessions.py", line 576, in send
    r = adapter.send(request, **kwargs)
  File "/Library/Frameworks/Python.framework/Versions/2.7/lib/python2.7/site-packages/requests/adapters.py", line 437, in send
    raise ConnectionError(e, request=request)
ConnectionError: HTTPConnectionPool(host='localhost', port=3000): Max retries exceeded with url: /msgs (Caused by NewConnectionError('<requests.packages.urllib3.connection.HTTPConnection object at 0x1053cc8d0>: Failed to establish a new connection: [Errno 61] Connection refused',))
Tue Mar 29 10:52:33 2016
Traceback (most recent call last):
  File "/Users/linyuchen/Documents/code/Python/qq/qqsdk/qqclient.py", line 765, in run
    msg = self.getMsg()
  File "/Users/linyuchen/Documents/code/Python/qq/qqsdk/qqapi.py", line 90, in getMsg
    data = self.post_json(self.get_msgs_url)
  File "/Users/linyuchen/Documents/code/Python/qq/qqsdk/qqapi.py", line 37, in post_json
    res = requests.get(url, kwargs)
  File "/Library/Frameworks/Python.framework/Versions/2.7/lib/python2.7/site-packages/requests/api.py", line 67, in get
    return request('get', url, params=params, **kwargs)
  File "/Library/Frameworks/Python.framework/Versions/2.7/lib/python2.7/site-packages/requests/api.py", line 53, in request
    return session.request(method=method, url=url, **kwargs)
  File "/Library/Frameworks/Python.framework/Versions/2.7/lib/python2.7/site-packages/requests/sessions.py", line 468, in request
    resp = self.send(prep, **send_kwargs)
  File "/Library/Frameworks/Python.framework/Versions/2.7/lib/python2.7/site-packages/requests/sessions.py", line 576, in send
    r = adapter.send(request, **kwargs)
  File "/Library/Frameworks/Python.framework/Versions/2.7/lib/python2.7/site-packages/requests/adapters.py", line 437, in send
    raise ConnectionError(e, request=request)
ConnectionError: HTTPConnectionPool(host='localhost', port=3000): Max retries exceeded with url: /msgs (Caused by NewConnectionError('<requests.packages.urllib3.connection.HTTPConnection object at 0x1053cc050>: Failed to establish a new connection: [Errno 61] Connection refused',))
Tue Mar 29 10:52:33 2016
Traceback (most recent call last):
  File "/Users/linyuchen/Documents/code/Python/qq/qqsdk/qqclient.py", line 765, in run
    msg = self.getMsg()
  File "/Users/linyuchen/Documents/code/Python/qq/qqsdk/qqapi.py", line 90, in getMsg
    data = self.post_json(self.get_msgs_url)
  File "/Users/linyuchen/Documents/code/Python/qq/qqsdk/qqapi.py", line 37, in post_json
    res = requests.get(url, kwargs)
  File "/Library/Frameworks/Python.framework/Versions/2.7/lib/python2.7/site-packages/requests/api.py", line 67, in get
    return request('get', url, params=params, **kwargs)
  File "/Library/Frameworks/Python.framework/Versions/2.7/lib/python2.7/site-packages/requests/api.py", line 53, in request
    return session.request(method=method, url=url, **kwargs)
  File "/Library/Frameworks/Python.framework/Versions/2.7/lib/python2.7/site-packages/requests/sessions.py", line 468, in request
    resp = self.send(prep, **send_kwargs)
  File "/Library/Frameworks/Python.framework/Versions/2.7/lib/python2.7/site-packages/requests/sessions.py", line 576, in send
    r = adapter.send(request, **kwargs)
  File "/Library/Frameworks/Python.framework/Versions/2.7/lib/python2.7/site-packages/requests/adapters.py", line 437, in send
    raise ConnectionError(e, request=request)
ConnectionError: HTTPConnectionPool(host='localhost', port=3000): Max retries exceeded with url: /msgs (Caused by NewConnectionError('<requests.packages.urllib3.connection.HTTPConnection object at 0x1053ccd50>: Failed to establish a new connection: [Errno 61] Connection refused',))
Tue Mar 29 10:52:33 2016
Traceback (most recent call last):
  File "/Users/linyuchen/Documents/code/Python/qq/qqsdk/qqclient.py", line 765, in run
    msg = self.getMsg()
  File "/Users/linyuchen/Documents/code/Python/qq/qqsdk/qqapi.py", line 90, in getMsg
    data = self.post_json(self.get_msgs_url)
  File "/Users/linyuchen/Documents/code/Python/qq/qqsdk/qqapi.py", line 37, in post_json
    res = requests.get(url, kwargs)
  File "/Library/Frameworks/Python.framework/Versions/2.7/lib/python2.7/site-packages/requests/api.py", line 67, in get
    return request('get', url, params=params, **kwargs)
  File "/Library/Frameworks/Python.framework/Versions/2.7/lib/python2.7/site-packages/requests/api.py", line 53, in request
    return session.request(method=method, url=url, **kwargs)
  File "/Library/Frameworks/Python.framework/Versions/2.7/lib/python2.7/site-packages/requests/sessions.py", line 468, in request
    resp = self.send(prep, **send_kwargs)
  File "/Library/Frameworks/Python.framework/Versions/2.7/lib/python2.7/site-packages/requests/sessions.py", line 576, in send
    r = adapter.send(request, **kwargs)
  File "/Library/Frameworks/Python.framework/Versions/2.7/lib/python2.7/site-packages/requests/adapters.py", line 437, in send
    raise ConnectionError(e, request=request)
ConnectionError: HTTPConnectionPool(host='localhost', port=3000): Max retries exceeded with url: /msgs (Caused by NewConnectionError('<requests.packages.urllib3.connection.HTTPConnection object at 0x1053cce10>: Failed to establish a new connection: [Errno 61] Connection refused',))
Tue Mar 29 10:52:34 2016
Traceback (most recent call last):
  File "/Users/linyuchen/Documents/code/Python/qq/qqsdk/qqclient.py", line 765, in run
    msg = self.getMsg()
  File "/Users/linyuchen/Documents/code/Python/qq/qqsdk/qqapi.py", line 90, in getMsg
    data = self.post_json(self.get_msgs_url)
  File "/Users/linyuchen/Documents/code/Python/qq/qqsdk/qqapi.py", line 37, in post_json
    res = requests.get(url, kwargs)
  File "/Library/Frameworks/Python.framework/Versions/2.7/lib/python2.7/site-packages/requests/api.py", line 67, in get
    return request('get', url, params=params, **kwargs)
  File "/Library/Frameworks/Python.framework/Versions/2.7/lib/python2.7/site-packages/requests/api.py", line 53, in request
    return session.request(method=method, url=url, **kwargs)
  File "/Library/Frameworks/Python.framework/Versions/2.7/lib/python2.7/site-packages/requests/sessions.py", line 468, in request
    resp = self.send(prep, **send_kwargs)
  File "/Library/Frameworks/Python.framework/Versions/2.7/lib/python2.7/site-packages/requests/sessions.py", line 576, in send
    r = adapter.send(request, **kwargs)
  File "/Library/Frameworks/Python.framework/Versions/2.7/lib/python2.7/site-packages/requests/adapters.py", line 437, in send
    raise ConnectionError(e, request=request)
ConnectionError: HTTPConnectionPool(host='localhost', port=3000): Max retries exceeded with url: /msgs (Caused by NewConnectionError('<requests.packages.urllib3.connection.HTTPConnection object at 0x1053cce90>: Failed to establish a new connection: [Errno 61] Connection refused',))
Tue Mar 29 10:52:34 2016
Traceback (most recent call last):
  File "/Users/linyuchen/Documents/code/Python/qq/qqsdk/qqclient.py", line 765, in run
    msg = self.getMsg()
  File "/Users/linyuchen/Documents/code/Python/qq/qqsdk/qqapi.py", line 90, in getMsg
    data = self.post_json(self.get_msgs_url)
  File "/Users/linyuchen/Documents/code/Python/qq/qqsdk/qqapi.py", line 37, in post_json
    res = requests.get(url, kwargs)
  File "/Library/Frameworks/Python.framework/Versions/2.7/lib/python2.7/site-packages/requests/api.py", line 67, in get
    return request('get', url, params=params, **kwargs)
  File "/Library/Frameworks/Python.framework/Versions/2.7/lib/python2.7/site-packages/requests/api.py", line 53, in request
    return session.request(method=method, url=url, **kwargs)
  File "/Library/Frameworks/Python.framework/Versions/2.7/lib/python2.7/site-packages/requests/sessions.py", line 468, in request
    resp = self.send(prep, **send_kwargs)
  File "/Library/Frameworks/Python.framework/Versions/2.7/lib/python2.7/site-packages/requests/sessions.py", line 576, in send
    r = adapter.send(request, **kwargs)
  File "/Library/Frameworks/Python.framework/Versions/2.7/lib/python2.7/site-packages/requests/adapters.py", line 437, in send
    raise ConnectionError(e, request=request)
ConnectionError: HTTPConnectionPool(host='localhost', port=3000): Max retries exceeded with url: /msgs (Caused by NewConnectionError('<requests.packages.urllib3.connection.HTTPConnection object at 0x1053ccf10>: Failed to establish a new connection: [Errno 61] Connection refused',))
Tue Mar 29 10:52:34 2016
Traceback (most recent call last):
  File "/Users/linyuchen/Documents/code/Python/qq/qqsdk/qqclient.py", line 765, in run
    msg = self.getMsg()
  File "/Users/linyuchen/Documents/code/Python/qq/qqsdk/qqapi.py", line 90, in getMsg
    data = self.post_json(self.get_msgs_url)
  File "/Users/linyuchen/Documents/code/Python/qq/qqsdk/qqapi.py", line 37, in post_json
    res = requests.get(url, kwargs)
  File "/Library/Frameworks/Python.framework/Versions/2.7/lib/python2.7/site-packages/requests/api.py", line 67, in get
    return request('get', url, params=params, **kwargs)
  File "/Library/Frameworks/Python.framework/Versions/2.7/lib/python2.7/site-packages/requests/api.py", line 53, in request
    return session.request(method=method, url=url, **kwargs)
  File "/Library/Frameworks/Python.framework/Versions/2.7/lib/python2.7/site-packages/requests/sessions.py", line 468, in request
    resp = self.send(prep, **send_kwargs)
  File "/Library/Frameworks/Python.framework/Versions/2.7/lib/python2.7/site-packages/requests/sessions.py", line 576, in send
    r = adapter.send(request, **kwargs)
  File "/Library/Frameworks/Python.framework/Versions/2.7/lib/python2.7/site-packages/requests/adapters.py", line 437, in send
    raise ConnectionError(e, request=request)
ConnectionError: HTTPConnectionPool(host='localhost', port=3000): Max retries exceeded with url: /msgs (Caused by NewConnectionError('<requests.packages.urllib3.connection.HTTPConnection object at 0x1053ccf90>: Failed to establish a new connection: [Errno 61] Connection refused',))
Tue Mar 29 10:52:34 2016
Traceback (most recent call last):
  File "/Users/linyuchen/Documents/code/Python/qq/qqsdk/qqclient.py", line 765, in run
    msg = self.getMsg()
  File "/Users/linyuchen/Documents/code/Python/qq/qqsdk/qqapi.py", line 90, in getMsg
    data = self.post_json(self.get_msgs_url)
  File "/Users/linyuchen/Documents/code/Python/qq/qqsdk/qqapi.py", line 37, in post_json
    res = requests.get(url, kwargs)
  File "/Library/Frameworks/Python.framework/Versions/2.7/lib/python2.7/site-packages/requests/api.py", line 67, in get
    return request('get', url, params=params, **kwargs)
  File "/Library/Frameworks/Python.framework/Versions/2.7/lib/python2.7/site-packages/requests/api.py", line 53, in request
    return session.request(method=method, url=url, **kwargs)
  File "/Library/Frameworks/Python.framework/Versions/2.7/lib/python2.7/site-packages/requests/sessions.py", line 468, in request
    resp = self.send(prep, **send_kwargs)
  File "/Library/Frameworks/Python.framework/Versions/2.7/lib/python2.7/site-packages/requests/sessions.py", line 576, in send
    r = adapter.send(request, **kwargs)
  File "/Library/Frameworks/Python.framework/Versions/2.7/lib/python2.7/site-packages/requests/adapters.py", line 437, in send
    raise ConnectionError(e, request=request)
ConnectionError: HTTPConnectionPool(host='localhost', port=3000): Max retries exceeded with url: /msgs (Caused by NewConnectionError('<requests.packages.urllib3.connection.HTTPConnection object at 0x1053cccd0>: Failed to establish a new connection: [Errno 61] Connection refused',))
Tue Mar 29 10:52:34 2016
Traceback (most recent call last):
  File "/Users/linyuchen/Documents/code/Python/qq/qqsdk/qqclient.py", line 765, in run
    msg = self.getMsg()
  File "/Users/linyuchen/Documents/code/Python/qq/qqsdk/qqapi.py", line 90, in getMsg
    data = self.post_json(self.get_msgs_url)
  File "/Users/linyuchen/Documents/code/Python/qq/qqsdk/qqapi.py", line 37, in post_json
    res = requests.get(url, kwargs)
  File "/Library/Frameworks/Python.framework/Versions/2.7/lib/python2.7/site-packages/requests/api.py", line 67, in get
    return request('get', url, params=params, **kwargs)
  File "/Library/Frameworks/Python.framework/Versions/2.7/lib/python2.7/site-packages/requests/api.py", line 53, in request
    return session.request(method=method, url=url, **kwargs)
  File "/Library/Frameworks/Python.framework/Versions/2.7/lib/python2.7/site-packages/requests/sessions.py", line 468, in request
    resp = self.send(prep, **send_kwargs)
  File "/Library/Frameworks/Python.framework/Versions/2.7/lib/python2.7/site-packages/requests/sessions.py", line 576, in send
    r = adapter.send(request, **kwargs)
  File "/Library/Frameworks/Python.framework/Versions/2.7/lib/python2.7/site-packages/requests/adapters.py", line 437, in send
    raise ConnectionError(e, request=request)
ConnectionError: HTTPConnectionPool(host='localhost', port=3000): Max retries exceeded with url: /msgs (Caused by NewConnectionError('<requests.packages.urllib3.connection.HTTPConnection object at 0x10541d0d0>: Failed to establish a new connection: [Errno 61] Connection refused',))
Tue Mar 29 10:52:34 2016
Traceback (most recent call last):
  File "/Users/linyuchen/Documents/code/Python/qq/qqsdk/qqclient.py", line 765, in run
    msg = self.getMsg()
  File "/Users/linyuchen/Documents/code/Python/qq/qqsdk/qqapi.py", line 90, in getMsg
    data = self.post_json(self.get_msgs_url)
  File "/Users/linyuchen/Documents/code/Python/qq/qqsdk/qqapi.py", line 37, in post_json
    res = requests.get(url, kwargs)
  File "/Library/Frameworks/Python.framework/Versions/2.7/lib/python2.7/site-packages/requests/api.py", line 67, in get
    return request('get', url, params=params, **kwargs)
  File "/Library/Frameworks/Python.framework/Versions/2.7/lib/python2.7/site-packages/requests/api.py", line 53, in request
    return session.request(method=method, url=url, **kwargs)
  File "/Library/Frameworks/Python.framework/Versions/2.7/lib/python2.7/site-packages/requests/sessions.py", line 468, in request
    resp = self.send(prep, **send_kwargs)
  File "/Library/Frameworks/Python.framework/Versions/2.7/lib/python2.7/site-packages/requests/sessions.py", line 576, in send
    r = adapter.send(request, **kwargs)
  File "/Library/Frameworks/Python.framework/Versions/2.7/lib/python2.7/site-packages/requests/adapters.py", line 437, in send
    raise ConnectionError(e, request=request)
ConnectionError: HTTPConnectionPool(host='localhost', port=3000): Max retries exceeded with url: /msgs (Caused by NewConnectionError('<requests.packages.urllib3.connection.HTTPConnection object at 0x10541d150>: Failed to establish a new connection: [Errno 61] Connection refused',))
Tue Mar 29 10:52:34 2016
Traceback (most recent call last):
  File "/Users/linyuchen/Documents/code/Python/qq/qqsdk/qqclient.py", line 765, in run
    msg = self.getMsg()
  File "/Users/linyuchen/Documents/code/Python/qq/qqsdk/qqapi.py", line 90, in getMsg
    data = self.post_json(self.get_msgs_url)
  File "/Users/linyuchen/Documents/code/Python/qq/qqsdk/qqapi.py", line 37, in post_json
    res = requests.get(url, kwargs)
  File "/Library/Frameworks/Python.framework/Versions/2.7/lib/python2.7/site-packages/requests/api.py", line 67, in get
    return request('get', url, params=params, **kwargs)
  File "/Library/Frameworks/Python.framework/Versions/2.7/lib/python2.7/site-packages/requests/api.py", line 53, in request
    return session.request(method=method, url=url, **kwargs)
  File "/Library/Frameworks/Python.framework/Versions/2.7/lib/python2.7/site-packages/requests/sessions.py", line 468, in request
    resp = self.send(prep, **send_kwargs)
  File "/Library/Frameworks/Python.framework/Versions/2.7/lib/python2.7/site-packages/requests/sessions.py", line 576, in send
    r = adapter.send(request, **kwargs)
  File "/Library/Frameworks/Python.framework/Versions/2.7/lib/python2.7/site-packages/requests/adapters.py", line 437, in send
    raise ConnectionError(e, request=request)
ConnectionError: HTTPConnectionPool(host='localhost', port=3000): Max retries exceeded with url: /msgs (Caused by NewConnectionError('<requests.packages.urllib3.connection.HTTPConnection object at 0x10541d1d0>: Failed to establish a new connection: [Errno 61] Connection refused',))
Tue Mar 29 10:52:34 2016
Traceback (most recent call last):
  File "/Users/linyuchen/Documents/code/Python/qq/qqsdk/qqclient.py", line 765, in run
    msg = self.getMsg()
  File "/Users/linyuchen/Documents/code/Python/qq/qqsdk/qqapi.py", line 90, in getMsg
    data = self.post_json(self.get_msgs_url)
  File "/Users/linyuchen/Documents/code/Python/qq/qqsdk/qqapi.py", line 37, in post_json
    res = requests.get(url, kwargs)
  File "/Library/Frameworks/Python.framework/Versions/2.7/lib/python2.7/site-packages/requests/api.py", line 67, in get
    return request('get', url, params=params, **kwargs)
  File "/Library/Frameworks/Python.framework/Versions/2.7/lib/python2.7/site-packages/requests/api.py", line 53, in request
    return session.request(method=method, url=url, **kwargs)
  File "/Library/Frameworks/Python.framework/Versions/2.7/lib/python2.7/site-packages/requests/sessions.py", line 468, in request
    resp = self.send(prep, **send_kwargs)
  File "/Library/Frameworks/Python.framework/Versions/2.7/lib/python2.7/site-packages/requests/sessions.py", line 576, in send
    r = adapter.send(request, **kwargs)
  File "/Library/Frameworks/Python.framework/Versions/2.7/lib/python2.7/site-packages/requests/adapters.py", line 437, in send
    raise ConnectionError(e, request=request)
ConnectionError: HTTPConnectionPool(host='localhost', port=3000): Max retries exceeded with url: /msgs (Caused by NewConnectionError('<requests.packages.urllib3.connection.HTTPConnection object at 0x10541d250>: Failed to establish a new connection: [Errno 61] Connection refused',))
Tue Mar 29 10:52:34 2016
Traceback (most recent call last):
  File "/Users/linyuchen/Documents/code/Python/qq/qqsdk/qqclient.py", line 765, in run
    msg = self.getMsg()
  File "/Users/linyuchen/Documents/code/Python/qq/qqsdk/qqapi.py", line 90, in getMsg
    data = self.post_json(self.get_msgs_url)
  File "/Users/linyuchen/Documents/code/Python/qq/qqsdk/qqapi.py", line 37, in post_json
    res = requests.get(url, kwargs)
  File "/Library/Frameworks/Python.framework/Versions/2.7/lib/python2.7/site-packages/requests/api.py", line 67, in get
    return request('get', url, params=params, **kwargs)
  File "/Library/Frameworks/Python.framework/Versions/2.7/lib/python2.7/site-packages/requests/api.py", line 53, in request
    return session.request(method=method, url=url, **kwargs)
  File "/Library/Frameworks/Python.framework/Versions/2.7/lib/python2.7/site-packages/requests/sessions.py", line 468, in request
    resp = self.send(prep, **send_kwargs)
  File "/Library/Frameworks/Python.framework/Versions/2.7/lib/python2.7/site-packages/requests/sessions.py", line 576, in send
    r = adapter.send(request, **kwargs)
  File "/Library/Frameworks/Python.framework/Versions/2.7/lib/python2.7/site-packages/requests/adapters.py", line 437, in send
    raise ConnectionError(e, request=request)
ConnectionError: HTTPConnectionPool(host='localhost', port=3000): Max retries exceeded with url: /msgs (Caused by NewConnectionError('<requests.packages.urllib3.connection.HTTPConnection object at 0x10541d2d0>: Failed to establish a new connection: [Errno 61] Connection refused',))
Tue Mar 29 10:52:34 2016
